Workbook

Sheet 00_사용안내
B2: ESG 핵심지표 채점 기준표
B3: K-ESG 가이드라인 v2.0 기반 통합 채점 도구
B5: 1. 목적
B6: 기업의 ESG 현황을 공식 가이드라인 기준으로 정량 진단·채점하고, KSSB 공시기준 대비 GAP을 분석하는 컨설팅용 도구입니다.
B8: 2. 적용 기준 (공식 출처)
B9: · 기본 69 + 추가 16개(85개) 배점: K-ESG 가이드라인 v2.0 (산업통상자원부·한국생산성본부, 2024.12)
B10: · 반도체 특화 6개: 업종별 K-ESG 가이드라인(반도체, 2023.12) — v2.0 기본체계에 보완지표로 적용
B11: · 지배구조 세부지표(129개, 03번 시트): 한국거래소 기업지배구조보고서 가이드라인(2025.2 개정본)
B12: · 공시 GAP 분석(04번 시트): KSSB(한국회계기준원 산하) 지속가능성 공시기준서 제1호·제2호(2026.2.26 최종 제정)
B14: 3. 점수 체계
B15: · 채점 유형 구성: 단계형·선택형 74개 / 복합가중형 11개 / 감점형 6개 (총 91개)
B16: · 단계형/선택형: 단계 수에 따라 0~100점 균등 배분 (원문 그대로)
... B33: 문서 구성: 00_사용안내 · 01_ESG통합진단마스터 · 02_점수산정참고표 · 03_지배구조세부점검(KRX) · 04_KSSB갭분석 · 05_요약대시보드

Sheet 01_ESG통합진단마스터
A1: f | B1: 분류코드 | C1: 적용구분 | D1: 영역 | E1: 범주 | F1: 진단항목명 | G1: 항목설명 | H1: 데이터원천(수집처) | I1: 데이터기간 | J1: 데이터범위 | K1: 데이터산식(정량화공식) | L1: 채점유형 | M1: 최대단계수 | N1: 배점구조 요약 | O1: 점검기준 상세(K-ESG v2.0 원문) | P1: KSSB 대응현황 | Q1: KSSB 참고근거 | R1: 기타 참고기준(GRI/SASB/TCFD/KCGS 등) | S1: 원본 출처파일 | T1: [입력]충족단계/요건수 | U1: [입력]위반유형1 | V1: [입력]위반유형2 | W1: [입력]위반유형3 | X1: 자사취득점수(0~100) | Y1: 개선 가이드 | Z1: 비고-채점모델-25년 | AA1: 비고 - 손채점 + AI채점 - 26년 | AB1: 시급성 29년 의무공시 대비 개선 착수해야 하는 시점 순 점수가 낮은 순서 X | AC1: 해결방안 | AD1: 실사 진단 질문 | AE1: 답변형식
A2: 1 | B2: P-1-1 | C2: 기본진단항목(v2.0) | D2: 정보공시 | E2: 정보공시 형식 | F2: ESG 정보공시 방식 | G2: 조직이 ESG 정보공시 동향에 맞추어 정보 수요자의 접근성을 고려한 ESG 정보공시 방식을 정립하고 있는지 점검 | ESG 정보를 종합한 온/오프라인 채널 운영 및 ESG 정보공시 외부 확산/전파 등 정보 접근성 향상 측면의 노력을 확인 | H2: 홈페이지, 지속가능경영보고서, 사업보고서, 기타간행물, 전자공시시스템 上 ‘자율공시’ | I2: 직전 회계연도 | J2: N/A | K2: N/A | L2: 단계형 | M2: 5 | N2: 단계형: 1단계=0점 / 2단계=25점 / 3단계=50점 / 4단계=75점 / 5단계=100점 | O2: 1단계 | 조직이 어떠한 방식으로든 ESG 정보를 공시하지 않는 경우 | 2단계 | 조직의 홈페이지, 지속가능경영보고서, 사업보고서, 기타 간행물 등에 ESG 정보를 분산하여 공시하고 있는 경우 | 3단계 | 조직의 홈페이지, 지속가능경영보고서, 사업보고서, 기타 간행물 등에 ESG 정보를 통합하여 공시하고 있는 경우 | 4단계 | ESG 정보를 통합한 조직의 홈페이지, 지속가능경영보고서, 사업보고서, 기타 간행물 등을 지정된 장소에 비치하거나, | 특정 URL에 담고 있는 경우 | 5단계 | ESG 정보를 통합한 조직의 홈페이지, 지속가능경영보고서, 사업보고서, 기타 간행물 등의 발행여부를 ‘전자공시시스템-자율공시’ | 사항으로 알리는 경우 | P2: 부분대응 | Q2: KSSB 제1호 문단 64~70(보고시기·장소), 21~24(연계된 정보) | R2: GRI 2-3 | S2: 1_2_0_업종별 K-ESG 가이드라인(v2.0) 진단항목 | T2: 4 | X2: =IF(T2="","",SUMPRODUCT(('02_점수산정참고표'!$A$2:$A$314=$B2)*('02_점수산정참고표'!$C$2:$C$314=T2)*'02_점수산정참고표'!$E$2:$E$314)) -> 75 | Y2: ESG 정보공시란 투자자를 비롯한 다양한 이해관계자의 의사결정 및 가치판단에 영향을 미칠 수 있는 환경, 사회, 지배구조와 관련된 정보를 공개적으로 널리 알리는 행위를 의미한다. 조직은 정기적으로 특정한 정보공시 창구(홈페이지, 사업보고서, 지속가능경영보고서, 기타 간행물 등)에 ESG 관련 정보를 종합적으로 수록하고 있으며, 해당 정보공시 창구를 통해 이해관계자 누구나 ESG 정보를 접근/열람할 수 있고, 정보공시 여부를 대내외에 알리는 행위를 한 경우 ESG 정보공시를 하였다고 정의한다. ESG 정보란 중대성 평가(Materiality Test) 결과에 따른 핵심이슈, 또는 조직의 사업운영 과정에서 지속적 관리가 필요한 ESG 이슈별로 ‘전략’, ‘조직’,… | Z2: [자동채점] | 근거충분성: 부분적 | 근거: [지배구조보고서] 12p. 당사는 정관 규정에 따라 금전, 주식 및 기타의 재산으로 이익의 배당을 할 수 있습니다. 당사는 주주와 이해관계인의 중장기적 이익 극대화를 전제로 회사의 이익을 주주에게 배당하고 있으며 사업확장을 위한 투자수요, 경기변동에 따른 적정수준의 운영자금확보, 과거 배당 실적, 영업실적을 포함한 요소를 감안하여 배당 규모를 결정하고 있습니다.(17번째 줄) → 기업지배구조보고서 및 사업보고서 등을 통해 ESG 관련 정보를 분산하여 공시하고 있으나, 이를 통합하여 관리하거나 전자공시시스템에 자율공시로 알리는 체계에 대한 구체적인 근거가 부족하여 2단계로 판단함. | 근거페이지: 사업보고서 261p / 지배구조보고서 3~4p, 8p, 10~12p, 17p, 19p, 21p, 27p, 37p, 44p | AA2: 지속가능경영 충분 / 4단계 / 75점 [판단근거] 기준상 통합 ESG 정보와 지정 장소·특정 URL이 있으면 4단계, 이를 DART 자율공시로 발행 사실까지 알리면 5단계다. DN은 ESG 경영·정책·정량데이터·검증 링크 등을 하나의 지속가능경영 웹페이지에 통합해 제공하고 특정 URL이 확인된다. [확인근거] DN오토모티브_통합 PDF p.1~3은 원본 ESG 페이지 URL과 ESG 정책·정량데이터를 함께 제시한다. [감점사유] 첨부 문서에서 ESG 정보 발행 자체를 DART 자율공시로 별도 알렸다는 직접 증빙은 확인되지 않아 5단계는 인정하지 않는다. [보완 필요 증빙] DART 자율공시 접수증·공시문, ESG 데이터/보고서 발행 공지. | AB2: 중기 | AC2: [현재 문제점] 통합 웹공시는 확보됐으나 DART를 이용한 외부 확산 증빙이 부족하다. [개선방향] 매년 ESG 데이터 또는 지속가능경영 자료 업데이트 시 DART 자율공시를 표준 절차에 포함한다. [필요 근거] DART 공시문·접수번호, 홈페이지 게시일 로그. | AD2: 홈페이지, 지속가능경영보고서, 사업보고서 등을 통해 ESG 정보를 통합하여 공시하고, 전자공시시스템(DART) 자율공시 등을 통해 정보 접근성을 확보하고 있습니까? | AE2: 단계(1~5)
A3: 2 | B3: P-1-2 | C3: 기본진단항목(v2.0) | D3: 정보공시 | E3: 정보공시 형식 | F3: ESG 정보공시 주기 | G3: 투자자, 고객 등 정보 수요자의 의사결정 및 가치판단에 필요한 최신 ESG 정보를 적시에 제공하고 있는지 점검 | 조직의 ESG 데이터 취합/분석/마감 기간을 고려하여 1년 단위로 ESG 정보공시 주기를 설정하고 있는지 확인 | H3: ESG 정보공시 일자, 지속가능경영보고서 발간 주기 | I3: 최근 4개년 회계연도 * 3개년 이하 데이터 보유 시 해당 데이터로 추세 산정 | J3: N/A | K3: N/A | L3: 단계형 | M3: 3 | N3: 단계형: 1단계=0점 / 2단계=50점 / 3단계=100점 | O3: 1단계 | ESG 정보공시 주기를 특정할 수 없거나, 명시하고 있지 않는 경우 | 2단계 | 2년 단위로 보고서 발간 및 ESG 정보를 공시하는 경우 | 3단계 | 1년 단위로 보고서 발간 및 ESG 정보를 공시하는 경우 | P3: 부분대응 | Q3: KSSB 제1호 문단 60~63(보고빈도) | R3: GRI 2-3 | S3: 1_2_0_업종별 K-ESG 가이드라인(v2.0) 진단항목 | T3: 1 | X3: =IF(T3="","",SUMPRODUCT(('02_점수산정참고표'!$A$2:$A$314=$B3)*('02_점수산정참고표'!$C$2:$C$314=T3)*'02_점수산정참고표'!$E$2:$E$314)) -> 0 | Y3: ESG 정보 수요자가 조직의 ESG 정보를 효과적으로 활용하기 위해서는, 조직이 ESG 정보를 주기적으로 공시하는 것이 중요하다. ESG 정보가 적시성을 확보하기 위해서는 ESG 정보공시 주기를 재무정보 공시주기와 동일하게 하거나, 재무정보 공시 이후 최대한 빠른 시기에 ESG 정보를 공시할 필요가 있다. 또한, ESG 정보 수요자에 상당한 영향력을 미칠 수 있는 정보는 이를 확인한 즉시 대외공시할 것을 권장한다. 조직은 ESG 정보공시 주기를 자율적으로 정할 수 있다. 일부 조직은 주요한 ESG 성과가 창출되는 시점마다 공시하기도 하며, 어떠한 조직은 ESG 정보공시에 따른 업무/비용 부담을 고려하여 격년 주기로 공시하기도 한다. 반면 ESG 정보공시 규제 및… | Z3: [자동채점] | 근거충분성: 불충분 | 근거: [지배구조보고서] 12p. 당사는 자산 2조원 미만인 코스피 상장사로 영문공시 의무화(2단계 '26~) 대상이 아니며, 이에 모든 공시는 국문으로 공시되고 외국인주주 및 외국인투자자를 위한 영문공시는 현재 제공하지 않고 있습니다.(17번째 줄) → 제공된 근거 자료 내에서 ESG 정보공시 주기를 1년 또는 2년 단위로 설정하여 정기적으로 공시한다는 명시적인 정책이나 보고서 발간 주기에 대한 언급이 확인되지 않아 1단계로 판단함. | 근거페이지: 사업보고서 189p, 261p, 272p / 지배구조보고서 3p, 5p, 8p, 12p, 17p, 19p, 30p, 32p, 43~44p | AA3: 부족 / 1단계 / 0점 [판단근거] 3단계는 1년 단위 공시, 2단계는 2년 단위이며 주기를 특정할 수 없으면 1단계다. [확인근거] 통합 ESG 자료에는 2023·2024·2025년 수치가 나란히 제공되지만, 이것만으로 “매년 공시한다”는 발간정책 또는 과거 연도별 실제 게시일을 입증하지는 못한다. [감점사유] 연속 3개년 데이터와 연 1회 공시 주기는 서로 다른 증빙이므로 보수적으로 주기 미특정 처리한다. [보완 필요 증빙] ESG 정보공시 정책, 연간 공시캘린더, 2024·2025·2026 게시일/발간이력 | AB3: 즉시 | AC3: [현재 문제점] 데이터는 연도별로 있으나 공시 주기가 제도화돼 있음을 보여주는 문서가 없다. [개선방향] ‘매 회계연도 종료 후 ○개월 내 연 1회 업데이트’ 원칙을 문서화하고 매년 동일 시기에 이행한다. [필요 근거] ESG 공시규정, 연간 캘린더, 연도별 게시 로그 | AD3: 지속가능경영보고서 발간 등을 포함한 ESG 정보공시 주기를 1년 단위로 설정하여 정기적으로 공시하고 있습니까? | AE3: 단계(1~3)
A4: 3 | B4: P-1-3 | C4: 기본진단항목(v2.0) | D4: 정보공시 | E4: 정보공시 형식 | F4: ESG 정보공시 범위 | G4: ESG 정보공시 제도화 움직임에 따라, 조직의 ESG 활동 및 성과를 충분히 대표하고 나타낼 수 있는 정보가 공시되고 있는지 점검 | 조직의 영향력과 통제력이 미치는 사업장(자회사 포함)의 ESG 정보가 최대한 공시되고 있는지 확인 | H4: 홈페이지, 지속가능경영보고서, 사업보고서, 전자공시시스템 上 ‘자율공시’ | I4: 직전 회계연도 | J4: 사업적 영향력 및 통제력을 행사하는 사업장 및 기타 연결실체 | K4: ESG 정보공시 범위 = ESG 정보공시에 포함된 사업장 등의 (매출액 등) / 전체 조직의 (매출액 등) | L4: 단계형 | M4: 5 | N4: 단계형: 1단계=0점 / 2단계=25점 / 3단계=50점 / 4단계=75점 / 5단계=100점 | O4: 1단계 | ESG 정보공시 범위를 특정할 수 없거나, 명시하고 있지 않는 경우 | 2단계 | 조직이 법적으로 직접 소유하고 있는 사업장(ex. 별도재무제표 기준)의 일부 또는 모든 ESG 정보를 공시하고 있는 경우 | 3단계 | 조직의 영향력과 통제력 범위에 있는 곳(자회사, 종속법인, 연결실체 등)의 일부 ESG 정보를 공시하고 있는 경우 | 4단계 | 조직의 영향력과 통제력 범위에 있는 곳(자회사, 종속법인, 연결실체 등)의 일부 ESG 정보를 공시하고 있는 경우. | 단, 조직의 영향력과 통제력 범위로 ESG 정보공시 범위를 확대한다는 계획을 제시하고 있는 경우 | 5단계 | 조직의 영향력과 통제력 범위에 있는 곳(자회사, 종속법인, 연결실체 등)의 모든 ESG 정보를 공시하고 있는 경우 | P4: 부분대응 | Q4: KSSB 제1호 문단 21~24(연계된 정보) | R4: GRI 2-2 | S4: 1_2_0_업종별 K-ESG 가이드라인(v2.0) 진단항목 | T4: 2 | X4: =IF(T4="","",SUMPRODUCT(('02_점수산정참고표'!$A$2:$A$314=$B4)*('02_점수산정참고표'!$C$2:$C$314=T4)*'02_점수산정참고표'!$E$2:$E$314)) -> 25 | Y4: 조직은 ESG 정보공시 전 어떠한 범위까지 성과관리를 할 것인지, 또는 성과관리가 가능한지 등 최대 범위를 설정해야 한다. ESG 개념을 조직의 재무적 정보를 기반으로 투자의사결정을 하는 자본시장에서 등장하였기 때문에, 장기적으로 ESG 성과관리 및 정보공시 최대범위는 ‘(연결)재무제표’에 포함되는 ‘재무정보’ 범위와 동일시하려는 논의가 진행될 것으로 예상된다. 따라서 조직은 아래의 ‘영향력’과 ‘통제력’이 행사되는 범위에서 발생하는 환경, 사회, 지배구조 관련 정보를 공시할 필요가 있다. (예를 들어, US GAAP, IFRS 회계지침에는 20% 이상 지분을 보유한 조직을 상당한 영향력이 행사되는 조직으로 간주한다.) 1) ESG 정보를 공시하는 조직이 직접적으로… | Z4: [자동채점] | 근거충분성: 불충분 | 근거: [지배구조보고서] 12p. 당사는 공시대상기간중 자회사의 감사보고서 제출(자회사의 주요경영사항)을 지연공시하여 불성실 공시 법인에 지정되었습니다.(13번째 줄) → 제공된 근거 자료 내에서 ESG 정보공시의 범위(연결실체 전체 포함 여부 등)를 명시하거나 관련 정책을 설명하는 내용이 확인되지 않아 1단계로 판단함. | 근거페이지: 사업보고서 16p, 46~47p, 49p, 54p, 72p, 90p, 146p, 249p, 261p, 286p / 지배구조보고서 12p, 19p | AA4: 충분 / 2단계 / 25점 [판단근거] 직접 소유 사업장의 일부·전부 ESG 정보는 2단계, 자회사·종속법인 등 통제범위의 일부 정보를 포함해야 3단계 이상이다. [확인근거] 통합자료 p.3은 공시 데이터가 VMS 양산 1공장·진주공장·BTS 울산 1공장을 기준으로 하며 일부 인원지표만 한국사업장 전체를 별도 각주 처리한다고 명시한다. 반면 사업보고서는 연결대상 종속회사가 24개라고 밝힌다. [감점사유] 환경·안전·인권 정책의 적용범위가 자회사까지 넓다는 사실은 확인되지만, 정책 적용범위와 실제 ESG 성과 데이터 공시범위는 동일하지 않으므로 3단계 이상으로 올리지 않는다. [보완 필요 증빙] 법인별 ESG Reporting Boundary Matrix, 연결 자회사 ESG 데이터, 범위확대 계획 - 연결 기준 23개 자회사 포함 - ESG정량데이터 공시 중 - ESG정보공시 범위 명시적 정의 X - 자회사 23개 중 몇 개의 ESG데이터가 공시되는지 명시 부재 - 해외 자회사 ESG정보 포함 여부 불명확X | AB4: 즉시 | AC4: [현재 문제점] 정책범위는 글로벌하지만 정량공시는 일부 국내사업장 중심이다. [개선방향] 연결재무제표 법인목록과 ESG 데이터 법인목록을 연결하고 우선 주요 종속회사부터 범위를 확대한다. [필요 근거] 연결법인-ESG 지표 매핑표, 자회사 데이터 제출서, 범위확대 로드맵. | AD4: 자회사 및 연결실체 등 조직의 영향력과 통제력이 미치는 사업장을 대상으로 ESG 정보공시 범위를 설정하고 이를 반영하여 공시하고 있습니까? | AE4: 단계(1~5)
A5: 4 | B5: P-2-1 | C5: 기본진단항목(v2.0) | D5: 정보공시 | E5: 정보공시 내용 | F5: ESG 핵심이슈 및 KPI | G5: 조직의 사업성과 및 환경/사회에 상당한 영향력을 미치는 핵심이슈를 명확히 정의하고, 이를 관리하기 위한 시스템 및 절차를 갖추고 있는지 확인 | 조직이 인식하고 관리하고 있는 핵심 ESG 이슈에 대한 조직의 정보공시 수준을 점검 | H5: 홈페이지, 지속가능경영보고서, 사업보고서, 전자공시시스템 上 ‘자율공시’ | I5: 직전 회계연도 | J5: N/A | K5: N/A | L5: 단계형 | M5: 5 | N5: 단계형: 1단계=0점 / 2단계=25점 / 3단계=50점 / 4단계=75점 / 5단계=100점 | O5: 1단계 | 중대성 평가 결과 또는 ESG 핵심이슈를 공시하고 있지 않은 경우 | 2단계 | 중대성 평가 결과와 핵심이슈를 명확히 정의하고 있는 경우 | 3단계 | 2단계 + 핵심이슈에 대해 조직이 관리하고 있는 성과지표를 설명하고 있는 경우 (예를 들어, 기후변화가 핵심이슈일 경우, 온실가스 배출량 데이터 제시) | 4단계 | 3단계 + 핵심이슈가 사업적/사회적 관점에서 중요한 사유를 설명하고 있는 경우 (예를 들어, 사업적/사회적 관점의 기회 요인과 리스크 요인 등) | 5단계 | 4단계 + 핵심이슈를 관리하기 위한 시스템 및 절차를 설명하고 있는 경우 (조직, 전략 및 계획, 고충처리체계, 활동 및 교육 등) | P5: 부분대응 | Q5: KSSB 제1호 문단 17~19(중요성 판단, 이중중대성 개념 미흡) | R5: GRI 3(중대성평가) | S5: 1_2_0_업종별 K-ESG 가이드라인(v2.0) 진단항목 | T5: 1 | X5: =IF(T5="","",SUMPRODUCT(('02_점수산정참고표'!$A$2:$A$314=$B5)*('02_점수산정참고표'!$C$2:$C$314=T5)*'02_점수산정참고표'!$E$2:$E$314)) -> 0 | Y5: 조직의 중요한 경제적, 환경적, 사회적 영향을 반영하는 측면 또는 이해관계자들의 평가와 의사결정에 실질적으로 영향을 미치는 측면을 모두 고려하여 보고서에서 다룰 가치가 있다고 판단되는 주제를 선정하는 과정을 거쳐야 한다. 이러한 이슈의 중대성을 판별하기 위한 방법으로는 일반적으로 ‘중대성 평가(Materiality Assessment)’ 또는 ‘이중 중대성 평가(Double Materiality Assessment)’가 있으며, 중대 측면을 정의하는 데 있어 조직이 참작해야 할 요인들은 다음과 같다. - 지속가능성에 영향, 위험, 기회 요소가 될 수 있는 항목(ex. 지구 온난화, 에이즈, 빈곤 등) 중 합리적 평가가 가능하고, 전문가나 해당 분야에 자격을 갖춘 전문… | Z5: [자동채점] | 근거충분성: 충분 | 근거: [지배구조보고서] 18p. 당사는 감사규정에 따라 리스크 관리체계를 마련하고 있지만, 모범규준에서 요구하는 수준의 명문화된 리스크 관리 정책 마련되어 있지는 않습니다.(5번째 줄) → 중대성 평가 결과나 ESG 핵심이슈를 정의하고 공시했다는 내용이 확인되지 않으므로 1단계에 해당합니다. | 근거페이지: 사업보고서 135p, 229p, 267~268p / 지배구조보고서 3p, 17~19p, 32p, 43~44p | AA5: 부족 / 1단계 / 0점 [판단근거] 2단계부터 중대성 평가 결과와 핵심이슈의 명확한 정의가 선행돼야 하며, 이후 KPI→중요성/위험·기회→관리 시스템 순으로 상향된다. [확인근거] DN 자료에는 온실가스, 안전, 인권, 공급망, 윤리 등 다수 정책·정량 KPI가 있으나 이를 중대성 평가를 통해 선별된 핵심 ESG 이슈라고 정의한 결과표는 확인되지 않는다. [감점사유] KPI가 많다는 것만으로 핵심이슈 선정 요건을 대체할 수 없고, 2단계 선행요건이 미충족이므로 후속 단계도 인정하지 않는다. [보완 필요 증빙] 중대성평가 방법론, Issue Universe, 이해관계자 평가결과, 핵심이슈 Matrix, 이슈별 KPI·리스크·기회·관리체계. - KPI 데이터(온실가스, 대기오염물질, 안전보건, 협력사 평가 등) 보유 - ESG 정책 수립 - 중대성 평가 실시 미명시 - 위험, 기회 요소 체계적 분석 미흡 - 이슈별 관리 시스템, 절차 설명 미흡 | AB5: 즉시 | AC5: [현재 문제점] ESG 활동은 많지만 “무엇이 DN의 핵심 이슈인지”를 선정한 연결논리가 없다. [개선방향] 연 1회 중대성평가를 시행하고 핵심이슈별 KPI·위험/기회·담당조직·목표를 묶어 공시한다. [필요 근거] 중대성평가 보고서, 경영진/이사회 승인자료, KPI 관리대장 | AD5: 중대성 평가를 통해 ESG 핵심이슈를 정의하고, 해당 이슈에 대한 성과지표(KPI), 중요 사유(위험·기회), 관리 시스템 및 절차를 공시하고 있습니까? | AE5: 단계(1~5)
A6: 5 | B6: P-3-1 | C6: 기본진단항목(v2.0) | D6: 정보공시 | E6: 정보공시 검증 | F6: ESG 정보공시 검증 | G6: 조직의 ESG 정보를 직접적으로 또는 가공하여 활용하는 이해관계자가 증가함에 따라, 조직이 대외공시하는 ESG 정보가 타당성/신뢰성/투명성을 확보하고 있는지 확인 | 조직이 대외공시하는 정보에 관해 제3자 기관으로부터 검증을 받는 경우, 해당 검증의견이 갖추어야 할 형식적 요건을 점검 | H6: ESG 정보 검증의견서, 지속가능경영보고서 검증의견서 | I6: 직전 회계연도 | J6: N/A | K6: N/A | L6: 선택형 | M6: 5 | N6: 선택형 (5가지 형식적 요건의 충족 개수에 따른 점수 부여) | 세부 배점 기준: 1개 이하 충족=0점 / 2개 충족 = 25점 / 3개 충족= 50점 / 4개 충족= 75점 / 5개 충족= 100점 | O6: 요건1 | 검증의견서에 검증기관(또는 검증인)이 명시되어 있는 경우 (또는, 검증기관이 License Number를 보유하고 있는 경우) | 요건2 | 검증의견서에 검증기관과의 독립성 성명이 포함되어 있는 경우 (즉, 검증기관과 검증받는 조직간 이해관계 상충이 없음을 선언한 경우) | 요건3 | 검증의견서에 검증표준(방법론)이 제시되어 있는 경우 (AA1000AS, ISAE3000, 또는 제3자 검증기관이 개발한 자체 검증표준 등) | 요건4 | 검증의견서에 ESG 정보 검증수준을 공개하고 있는 경우 (Type1/Type2, Moderate/High, 제한적/합리적 등) | 요건5 | 검증의견서에 제3자 검증기관이 검증한 정보공시 지표가 적시되어 있는 경우 (즉, 조직의 모든 ESG 정보 중 어떠한 정보를 검증하였는지 명시하는 경우) | P6: 완전대응 | Q6: KSSB 제1호 문단 50(3)(외부검증) | R6: GRI 2-5, AA1000AS, ISAE3000 | S6: 1_2_0_업종별 K-ESG 가이드라인(v2.0) 진단항목 | T6: 1 | X6: =IF(T6="","",SUMPRODUCT(('02_점수산정참고표'!$A$2:$A$314=$B6)*('02_점수산정참고표'!$C$2:$C$314=T6)*'02_점수산정참고표'!$E$2:$E$314)) -> 0 | Y6: 조직은 지속가능경영보고서 발간 등 ESG 정보공시 지표 및 기준을 자율적으로 선택할 수 있으며, ESG 정보가 갖추어야 할 신뢰성을 강제할 수 있는 법적/제도적 장치도 마련되어 있지 않은 상황이다. 따라서 ESG 정보 검증은 이러한 문제점을 개선하기 위한 조직의 의지이자 자율적 활동으로 조직이 공시하는 ESG 정보의 신뢰성을 확보하는 수단으로 인정받고 있다. ESG 정보 검증의 타당성과 신뢰성을 확인하기 위한 기준은 ‘검증기관의 적격성’, ‘검증기관과의 독립성’, ‘검증방법론의 합리성’, ‘검증수준의 명확성’, ‘검증지표의 구체성’으로 구분할 수 있다. 글로벌 시장에서 통용되는 ESG 검증표준에는 1) 지속가능경영 관련 국제표준 제정기관인… | Z6: [자동채점] | 근거충분성: 불충분 | 근거: ⚠️[출처 미확정, 검색 1위 후보로 대체] [지배구조보고서] 41p. 근거부족(줄 위치 특정 실패) → 제공된 근거 자료에는 ESG 정보공시에 대한 제3자 검증의견서나 관련 검증 요건(검증기관, 독립성, 표준, 수준, 지표 등)에 대한 언급이 전혀 없어 근거가 불충분합니다. | 근거페이지: 사업보고서 255p, 266p, 269p, 271p / 지배구조보고서 3p, 16~17p, 19p, 21p, 26p, 37~38p, 41~42p | AA6: 부족 / 0단계 / 0점 [판단근거] 검증의견서 자체에 ① 검증기관 ② 독립성 ③ 검증표준 ④ 검증수준 ⑤ 검증대상 지표가 있어야 하며 2개부터 25점이다. [확인근거] 통합자료 p.3은 ESG 데이터가 DN과 이해관계가 없는 제3자 BSI를 통해 검증됐다고 설명하고, p.9에는 ESG Data 3자 검증의견서 다운로드 경로가 존재한다. 다만 첨부 파일 안에는 검증의견서 원문 자체가 포함돼 있지 않다. [감점사유] 페이지 바깥 설명만으로 검증의견서 안에 5가지 형식이 실제 들어갔다고 단정하지 않는다. 넓게 보면 기관명·독립성 2개로 25점 해석이 가능하지만, 이번 검수에서는 ‘의견서 내 기재’라는 기준을 엄격 적용해 0점 잠정으로 둔다. [보완 필요 증빙] BSI 검증의견서 원본 PDF, 검증계약서, 검증대상 지표목록. - BSI서명 명시 - 검증의견서 4개 - 검증대상(양산1공장, 울산1공장, 진주공장 온실가스) - 독립성 선언, 검증표준, 검증수준, 검증대상 모두 명시 부재 - 온열가스만 검증(ESG 전체 지표 미흡) | AB6: 즉시 | AC6: [현재 문제점] 검증을 받았다는 사실은 있으나 이번 증빙패키지만으로 검증의견서의 형식요건을 검사할 수 없다. [개선방향] 매년 검증의견서 원문을 ESG 페이지와 증빙 폴더에 함께 보관하고 5개 형식요건을 계약단계에서 체크한다. [필요 근거] BSI 의견서, 표준·수준·Scope 명시 페이지. | AD6: 대외 공시하는 ESG 정보에 대해 검증기관 정보, 독립성 선언, 검증표준, 검증수준 및 검증 대상 지표 등 주요 요건을 포함한 제3자 검증의견서를 갖추고 있습니까? | AE6: 선택형(요건 충족 수)
A7: 6 | B7: E-1-1 | C7: 기본진단항목(v2.0) | D7: 환경 | E7: 환경경영 목표 | F7: 환경경영 목표 수립 | G7: 조직이 책임있는 환경경영을 수행하기 위한 방향성을 명확히 설정하고 효율적인 자원 배분이 이루어지고 있는지, 또한 조직이 외부에 미치는 환경 영향을 최소화하고 내부 환경성과를 향상시키기 위한 구체적인 계획이 마련되어 있는지 점검 | 조직이 수립한 환경 분야 단기/중장기 목표 구체성과 내재화 수준을 확인 | H7: 환경 분야 목표 수립 현황 | I7: 직전 회계연도 | J7: N/A | K7: N/A | L7: 단계형 | M7: 5 | N7: 단계형: 1단계=0점 / 2단계=25점 / 3단계=50점 / 4단계=75점 / 5단계=100점 | O7: 1단계 | 단기/중장기 성과목표, 또는 조직의 환경경영 방향성을 나타내는 환경경영 미션/비전/지향점이 없는 경우 | 2단계 | 환경경영 미션/비전/지향점만 제시하고 있는 경우 | 3단계 | 2단계 + 조직의 환경 분야 핵심이슈에 대한 단기 목표만 설정하고 있는 경우 | 4단계 | 3단계 + 중장기 목표까지 수립하고 있는 경우 | 5단계 | 4단계 + 중장기 목표 달성을 위한 과제와, 이행점검 지표를 마련한 경우 | P7: 부분대응 | Q7: KSSB 제2호 문단 33~36(목표) 준용 가능 | R7: GRI 2-27 | S7: 1_2_0_업종별 K-ESG 가이드라인(v2.0) 진단항목 | T7: 2 | X7: =IF(T7="","",SUMPRODUCT(('02_점수산정참고표'!$A$2:$A$314=$B7)*('02_점수산정참고표'!$C$2:$C$314=T7)*'02_점수산정참고표'!$E$2:$E$314)) -> 25 | Y7: 조직은 중대성 평가(Materiality Test)를 통해 조직의 사업운영 및 외부환경에 중요한 영향력을 행사하는 핵심이슈를 도출할 수 있다. 조직은 사업운영에 해당하는 모든 직/간접 환경규제를 관리해야 함과 동시에 사업성과와 연계된 핵심이슈에 대해서는 목표에 의한 성과관리가 필요하다. 조직이 수립할 수 있는 환경 분야 목표와 관련된 핵심이슈에는 아래와 같은 이슈가 해당된다. 에너지 사용량 절감 재생에너지 투자 확대 온실가스 배출량 감축 탄소중립 기술 개발 및 관련 투자활동 폐기물 발생량 저감 플라스틱 사용량 절감 재사용 용수 확대 원자재 효율적 투입 산림 및 토양 복원 생물다양성 증진 및 관련 투자활동 친환경 공급망 구축 대기/수질/토양 오염 감소 유해물질 감소… | Z7: [자동채점] | 근거충분성: 충분 | 근거: [지배구조보고서] 45p. 아울러 당사는 에너지 목표관리, 환경인증 획득, 환경법규 및 규정 요구사항을 준수하는 등 환경 윤리를 준수하기 위해 지속적으로 노력하고 있습니다.(6번째 줄) → 환경경영에 대한 의지와 노력은 언급되어 있으나, 구체적인 단기 또는 중장기 정량적 환경 목표가 제시되어 있지 않아 2단계에 해당합니다. | 근거페이지: 사업보고서 14p, 65p, 134~135p, 229p, 253p, 300~301p / 지배구조보고서 3p, 9~10p, 15p, 17p, 32p, 45p | AA7: 부분 / 2단계 / 25점 [환경경영 정책 참고] https://drive.google.com/file/d/1T892x8VAlipB1OQn1SwKEUW5kTEsnrhu/view?usp=drive_link [판단근거] 2단계에서 환경경영 미션·비전·지향점, 3단계에서 이에 더해 핵심 환경이슈의 단기 성과목표, 4단계에서 중장기 성과목표, 5단계에서 중장기 목표별 세부과제와 이행점검 지표를 요구한다. [확인근거] Excel AA7에는 정성적인 환경경영 방향이 확인되지만 단기 정량목표와 이행점검 지표를 찾지 못했다고 되어 있고, 한편 AA18에는 "NDC 기준으로 2030년까지 탄소배출량 35% 절감, 2050년까지 Net Zero"라는 정량적 중장기 목표가 적혀 있다. 따라서 AA7의 "구체적인 정량적 목표 없음"은 **"정량적 중장기 목표는 있으나 단기 성과목표 및 목표별 이행점검 지표 미확인"**으로 수정해야 한다. 회사 공식 EHS 페이지도 2030년 35% 감축과 2050 Net Zero를 명시하고 있어 이 수정이 타당하다. [감점사유] 2030·2050 목표만으로는 3단계의 "단기 목표"가 충족되지 않으며, 단계형 기준이 누적구조이므로 중장기 목표가 있어도 단기 목표가 빠지면 4단계를 바로 인정하기 어렵다. 또한 기준연도와 조직경계가 명확하지 않다. [보완필요증빙] 2026~2028년 단기 온실가스·에너지·용수·폐기물 목표표, 기준연도·대상 사업장·산정방식, 담당부서, 분기/연간 KPI 이행점검표와 경영진 보고자료가 필요하다. | AB7: 즉시 | AC7: [현재 문제점] 2030·2050 방향은 있으나 단기 목표와 목표별 관리지표가 연결되지 않은 점이다. [개선방향] K-ESG에서 요구하는 정량적 단기/중장기 목표, 이행점검 지표가 명확해야 함, 2026년을 포함한 연차별 환경 KPI를 정량화하고 2030 목표까지의 감축 경로를 역산하는 것이다. -> ex.5년 내 온실가스 배출 5% 감축, 벤치마킹 사 참고 [필요근거] 이사회 또는 경영회의 승인 목표표, 연도별 KPI 대장, 분기별 목표 대비 실적 보고서이다. | AD7: 구체적이고 단기/중장기 환경경영 정량 목표를 설정하고, 달성을 위한 과제 및 이행점검을 위한 지표를 정의하고 있습니까? | AE7: 단계(1~5)
A8: 7 | B8: E-1-2 | C8: 기본진단항목(v2.0) | D8: 환경 | E8: 환경경영 목표 | F8: 환경경영 추진체계 | G8: 조직이 환경성과 향상과 환경 개선 등의 경영활동으로 인한 환경영향 관리, 원부자재/에너지/폐기물 등의 효율적 관리, 국제사회 등 이해관계자의 환경영역 요구 대응을 위해 체계적으로 환경경영을 추진하고 있는지 점검 | 국내외 규격에서 제시하는 환경경영시스템 구성요건을 기준으로 조직이 이를 따르거나, 준용하여 환경경영 추진체계를 갖추고 있는지 확인 | H8: 환경경영시스템, 환경경영 정책, 환경경영 가이던스 | I8: 직전 회계연도 | J8: N/A | K8: N/A | L8: 선택형 | M8: 5 | N8: 선택형 (5가지 형식적 요건의 충족 개수에 따른 점수 부여) | 세부 배점 기준: 1개 이하 충족=0점 / 2개 충족 = 25점 / 3개 충족= 50점 / 4개 충족= 75점 / 5개 충족= 100점 | O8: 요건1 | 환경경영 추진을 위한 전사 거버넌스 체계를 구축하고 있는 경우 (전담조직, 실무협의회, 경영회의 및 내부점검체계 등) | 요건2 | 환경경영 추진을 위한 전사 전담조직을 운영하고 있는 경우 (전사 환경경영 기획, 점검, 성과관리 등 실행업무 담당) | 요건3 | 환경경영 과제 실행에 필요한 자원을 투입하고 있는 경우 (환경투자 예산, 역량강화 교육, 내외부 전문인력 등) | 요건4 | 환경경영 추진 현황을 점검/분석/평가하는 시스템이 있는 경우 (IT기반 모니터링 시스템, 과제점검 회의, 제3자 의견수렴 등) | 요건5 | 환경경영 과제 이행현황이 경영진 포함 관련 구성원의 성과평가지표(KPIs)에 반영되어 있는 경우 | * 선택 항목의 합산값으로 평가 | P8: 부분대응 | Q8: KSSB 제2호 문단 6(거버넌스) 준용 가능 | R8: GRI 2-27, K-ESG | S8: 1_2_0_업종별 K-ESG 가이드라인(v2.0) 진단항목 | T8: 3 | X8: =IF(T8="","",SUMPRODUCT(('02_점수산정참고표'!$A$2:$A$314=$B8)*('02_점수산정참고표'!$C$2:$C$314=T8)*'02_점수산정참고표'!$E$2:$E$314)) -> 50 | Y8: 환경경영이란 조직의 사업운영 전 과정에 걸쳐 발생하는 환경영향을 최소화하면서 환경적으로 건전하고, 경제적으로 지속가능한 발전을 도모하고자 하는 경영활동이다. 조직의 환경경영 체계란 환경경영을 효과적으로 추진하기 위해 환경방침 개발, 이행, 달성, 검토 및 유지관리 할 수 있는 조직, 책임, 자원, 절차, 과정 및 성과관리 등을 종합적으로 구축한 것을 의미한다. 조직은 환경경영을 위해 아래와 같은 추진체계를 구축할 수 있으며, 해당 정보는 이해관계자와 공유할 필요가 있다. ; 1) 조직은 목표 달성과 관련된 제반업무를 관장하는 거버넌스 및 업무분장 체계를 구축해야 한다. 2) 목표 달성을 위한 추진과제와 실행계획을 수립해야 한다. 3) 목표 달성에 필요한 새로운… | Z8: [자동채점] | 근거충분성: 부분적 | 근거: [지배구조보고서] 17p. 아울러 당사는 에너지 목표관리, 환경인증 획득, 환경법규 및 규정 요구사항을 준수하는 등 환경 윤리를 준수하기 위해 지속적으로 노력하고 있습니다.(5번째 줄) → 환경경영을 위한 환경인증 획득 및 에너지 목표관리 등 환경 윤리 준수를 위해 노력하고 있다는 서술이 존재하여 1단계 요건인 환경경영 추진체계 구축을 충족하는 것으로 판단되나, 전담조직 운영, 자원 투입, 성과평가 반영 등 구체적인 체계에 대한 근거는 부족함. | 근거페이지: 사업보고서 142p, 240p, 301p / 지배구조보고서 3p, 17~18p, 27p, 32p, 45p | AA8: 부분 / 3개 충족 / 50점 [환경경영 정책 참고] 요건 1,3,4 충족 / 2,5 부분적 -> 거버넌스, 자원 투입, 모니터링 시스템은 구축되어 있으나, 경영진 KPI 반영이 명확하지 않음 거버넌스 체계 - ISO 14001 인증 유지: 국제 표준 환경경영시스템 구축 - 산업안전보건위원회 실시: 1회/분기 (환경경영 거버넌스 포함) - 노사협의회 실시: 1회/분기 및 고충처리반 운영을 통한 근로 환경 개선 자원 투입 - 환경투자: 고효율설비 설치, 환경 영향 평가 기준 설립, 대기 오염 방지 시설 설치 - 인력: 사내 환경 관리 및 화학물질·폐기물 관리 전담 인력 모니터링 및 점검 - 정기 모니터링: - 수질환경측정 (1회/분기) - 폐수 누출 훈련 정기 실시 - 에너지 사용, 용수 사용, 폐기물 배출량 년간 관리 [판단근거] O8은 전사 환경경영 거버넌스, 전담조직, 자원 투입, 점검·분석·평가 시스템, 경영진을 포함한 구성원의 KPI 반영 등 5가지를 평가하며 3개 충족 시 50점이다. [확인근거] AA8에는 "ISO 14001 인증 유지", "고효율설비 설치", "환경 영향 평가 기준 설립", "대기 오염 방지 시설 설치", "수질환경측정 1회/분기", "에너지 사용·용수 사용·폐기물 배출량 연간 관리"가 적혀 있어 거버넌스/관리체계, 자원 투입, 모니터링 체계는 인정 가능하다. 공식 홈페이지 역시 양산 1공장·울산 1공장의 ISO 14001 인증과 환경시설 투자, 내부기준 수립을 공개한다. [감점사유] T8에는 1개 요건으로 입력돼 있지만 AA8 자체는 3개 요건을 충족한다고 평가해 내부 불일치가 있다. 반면 "산업안전보건위원회"와 "노사협의회"만으로 환경경영 거버넌스를 완전히 입증하는 데에는 해석 위험이 있으며, 회사 차원의 독립적인 환경전담조직과 기후·환경 KPI의 보상·평가 연계는 확인되지 않는다. [보완필요증빙] 환경경영 조직도, 환경담당 조직의 R&R, 예산·CAPEX 내역, 환경 KPI 정의서, 임원·조직장 평가표, 환경실적 경영진 보고자료가 필요하다. | AB8: 중기 | AC8: [현재 문제점] 환경설비와 측정활동은 존재하지만 전사 환경 거버넌스와 개인·조직 KPI로 연결되는 구조가 불명확한 점이다. [개선방향] 환경총괄 책임자, 전담부서, 부서별 KPI와 경영진 보고체계를 하나의 환경경영 운영규정으로 통합하는 것이다. -> 환경 KPI 반영이 명확해야 함, 환경 KPI의 임직원 성과평가 반영 강화 및 공시 [필요근거] 조직도, 업무분장표, KPI 평가표, 환경위원회 또는 경영회의 회의록과 환경예산 집행내역이다. | AD8: 체계적인 환경경영 추진을 위해 전사 거버넌스 구축, 전담조직 운영, 자원 및 역량 투입, 이행현황 점검 시스템 구축, 경영진 및 구성원의 성과평가지표(KPIs) 반영 체계를 갖추고 있습니까? | AE8: 선택형(요건 충족 수)
A9: 8 | B9: E-3-1 | C9: 기본진단항목(v2.0) | D9: 환경 | E9: 온실가스 | F9: 온실가스 배출량 (Scope1 & Scope2) | G9: 조직이 소유, 관리, 통제하는 물리적 경계(사업장 등) 내에서 에너지 사용으로 인해 발생하는 온실가스 배출(Scope1 & Scope2)을 감축하고 있는지 점검 | 조직간 규모 차이(매출액, 생산량 등) 또는 사업 변동(구조조정, 인수합병 등)을 고려하여 상대적 비교가능성이 높은 ‘원단위’ 개념을 기반으로 온실가스 배출량을 확인 | H9: ‘전자공시시스템’ 上 사업보고서, ‘조직별 홈페이지’ 上 지속가능경영보고서, ‘국가온실가스종합관리 시스템’ 上 명세서배출량통계 | I9: 최근 4개년 회계연도 * 3개년 이하 데이터 보유 시 해당 데이터로 추세 산정 | J9: 국내외 사업장 및 기타 연결실체 | K9: 원단위 온실가스 배출량 = 총 온실가스 배출량 / 매출액(또는 생산량) | L9: 단계형 | M9: 3 | N9: 단계형: 1단계=0점 / 2단계=50점 / 3단계=100점 | O9: 1단계 | 지난 4개년 원단위 온실가스 배출량 증가 추세 | 2단계 | 지난 4개년 원단위 온실가스 배출량 변동 없음 | 3단계 | 지난 4개년 원단위 온실가스 배출량 감소 추세 | * 원단위 온실가스 배출량을 관리하고 있지 않은 경우 0점 적용 | * 국내 및 해외 모든 사업장이 ‘탄소중립’ 또는 ‘탄소제로’를 달성한 경우 100점 적용 | * 3개년 이하 데이터 보유 시 해당 데이터로 추세 산정 | * '유지 추세'로 판단할 경우 2단계로 적용하여 평가 | * (추세) 일정 기간 정량적 자료의 변동 방향성을 의미하며, 본 가이드라인에서는 4개년 데이터의 연평균 성장률(CAGR)을 추세로 정의 | * (원단위(per unit)) 어떤 제품/용역 1단위 생산을 위해 투입된 재화(자본, 시간, 에너지 등) 혹은 배출량을 측정하는 개념. 기업 간 규모를 고려하여 비교 가능성을 확보하기 위한 목적으로 활용 | P9: 완전대응 | Q9: KSSB 제2호 문단 29(1) — Scope1·2 배출량 | R9: GHG Protocol, GRI 305-1,2 | S9: 1_2_0_업종별 K-ESG 가이드라인(v2.0) 진단항목 | T9: 3 | X9: =IF(T9="","",SUMPRODUCT(('02_점수산정참고표'!$A$2:$A$314=$B9)*('02_점수산정참고표'!$C$2:$C$314=T9)*'02_점수산정참고표'!$E$2:$E$314)) -> 100 | Y9: Scope1 온실가스 배출량 산정방법 = ∑[고정연소, 이동연소, 공정배출, 탈루배출, 폐기물처리]  Scope2 온실가스 배출량 산정방법 = ∑[구매전기, 구매 열(온수, 스팀 등)] | 조직의 온실가스 배출량이 산업 내 어떠한 수준에 있는지 점검하는 방식에는 1) ‘온실가스 배출권의할당및거래에관한법률’ 등에 따른 할당량 대비, 2) ‘온실가스·에너지 목표관리제’에 따른 목표값 대비, 3) 조직의 과거년도 배출량을 기반으로 수립한 목표 대비, 4) 조직이 자체적으로 수립한 목표(SBTi* 등) 대비, 5) 조직이 벤치마킹하는 경쟁조직 대비 비교하는 방식 등이 있다. * Science Based Target Initiative : 조직의 과거년도 배출량이나, 국가별… | Z9: [자동채점] | 근거충분성: 충분 | 근거: [사업보고서] 301p. 제54기 직접배출(Scope1) 2,598.286, 간접배출(Scope2) 31,170.395 / 제53기 직접배출(Scope1) 3,545.624, 간접배출(Scope2) 28,024.755 / 제52기 직접배출(Scope1) 5,674.626, 간접배출(Scope2) 31,188.378 / 제51기 직접배출(Scope1) 3,654.116, 간접배출(Scope2) 19,130.372(표 4번째 행, 숫자 매칭) → 제54기 매출액(1,100,669,248천원) 대비 온실가스 배출량과 과거 연도 데이터를 비교 시, 배출량의 변동폭이 크고 원단위 배출량이 전반적으로 감소 추세로 보기 어려워 1단계로 판단함. | 근거페이지: 사업보고서 13p, 25~28p, 33p, 151p, 267p, 269p, 292p, 300~301p, 307p / 지배구조보고서 3p, 8p, 10p, 17p, 38p | AA9: 직접계산 / 감소 추세 / 3단계 / 100점 [홈페이지 공개 자료] - 2023~2025 https://drive.google.com/file/d/1sbXOoqD2wtmpGBb11NVWCzH5u6ikdsu9/view?usp=drive_link - 공개된 원단위 데이터가 없어 산식으로 계산. - 온실가스 배출량(VMS+BTS) / 생산실적(부품+배터리) - 온실가스 배출량 (30,002 -> 33,805 -> 33,464) - 원단위 계산 결과 (64.5 -> 61.1 -> 58.2) [보완필요증빙] 국내외 전 사업장 Scope 1·2 인벤토리, 법인별 활동자료, 연결범위 reconciliation, 배출계수·GWP 적용기준, 매출 또는 생산량 분모의 조직경계 일치표, 제3자 검증의견서가 필요하다. | AB9: 즉시 | AC9: [현재 문제점] 감소 추세는 확인되나 공시범위가 국내 3개 공장 중심이라는 점이다. [개선방향] 2026년부터 모든 연결법인을 대상으로 Scope 1·2 인벤토리를 단계적으로 통합하고 동일한 매출/생산 경계로 집약도를 산정하는 것이다. 2025년 데이터는 온실가스배출량 3자 검증(BSI)은 현상태유지 + scope3은 방향성 언급으로 [필요근거] 법인별 에너지 사용자료, 온실가스 산정 workbook, 연결경계 명세서, 배출계수 출처와 제3자 검증자료이다. | AD9: Scope 1 및 Scope 2 원단위 온실가스 배출량을 산정하고, 이에 대한 증감 현황을 점검·관리하고 있습니까? | AE9: 단계(1~3)
A10: 9 | B10: E-3-3 | C10: 기본진단항목(v2.0) | D10: 환경 | E10: 온실가스 | F10: 온실가스 배출량 검증 | G10: 온실가스 배출권 거래제, 온실가스 목표관리제, 기타 온실가스 정보를 기반으로 의사결정하는 이해관계자가 증가함에 따라, 조직이 대외공시하는 온실가스 배출량 데이터가 타당성/신뢰성/투명성을 확보하고 있는지 확인 | 조직의 온실가스 배출량 데이터에 관해 제3자 기관으로부터 검증을 받는 경우, 해당 검증의견이 갖추어야 할 형식적 요건을 점검 | H10: 온실가스 배출량 검증의견서 | I10: 직전 회계연도 | J10: N/A | K10: N/A | L10: 선택형 | M10: 5 | N10: 선택형 (5가지 형식적 요건의 충족 개수에 따른 점수 부여) | 세부 배점 기준: 1개 이하 충족=0점 / 2개 충족 = 25점 / 3개 충족= 50점 / 4개 충족= 75점 / 5개 충족= 100점 | O10: 요건1 | 검증의견서에 검증기관(또는 검증인)이 명시되어 있는 경우 (또는, 검증기관이 License Number를 갖추고 있는 경우) | 요건2 | 검증의견서에 검증표준(방법론)이 제시되어 있는 경우 (온실가스 배출권거래제의 배출량 보고 및 인증에 관한 지침, GHG Protocol, ISO14064-1 등) | 요건3 | 검증의견서에 ESG 정보 검증수준을 공개하고 있는 경우 (전체/일부 데이터 검증, 제한적/합리적 보증 등) | 요건4 | 제3자 검증기관이 검증한 온실가스 배출량 검증 범위가 적시되어 있는 경우 (즉, 조직의 사업장 중 온실가스 배출량을 검증받은 사업장 및 지역 등) | 요건5 | 조직의 온실가스 관리에 관한 제3자 검증기관 의견이 명시되어 있는 경우 (온실가스 관리 시스템 개선, 향후 검증값의 변동가능성 등) | P10: 완전대응 | Q10: KSSB 제1호 문단 50(3)(검증) | R10: GRI 305 | S10: 1_2_0_업종별 K-ESG 가이드라인(v2.0) 진단항목 | T10: 2 | X10: =IF(T10="","",SUMPRODUCT(('02_점수산정참고표'!$A$2:$A$314=$B10)*('02_점수산정참고표'!$C$2:$C$314=T10)*'02_점수산정참고표'!$E$2:$E$314)) -> 25 | Y10: ｢기후위기 대응을 위한 탄소중립·녹색성장 기본법｣에 따라 국가 온실가스 감축 목표(2030년의 국가 온실가스 총배출량을 2018년의 온실가스 총배출량의 40%만큼 감축)를 달성할 수 있도록 일정 수준 이상의 온실가스를 배출하고 에너지를 소비하는 업체 및 사업장은 관리업체로 지정되며, 해당 기업은 온실가스 감축목표, 에너지 절약목표를 설정하고 관리할 의무가 있다. 2023년 12월 14일 환경부 온실가스종합정보센터의 관리업체 고시 기준 온실가스·에너지 목표관리 대상은 총 331개로 관장기관별로 국토교통부 86개, 산업통상자원부 172개, 농림축산식품부 35개, 해양수산부 15개, 환경부 23개이며, 관리업체에 대한 선정기준은 최근 3년간 연평균 온실가스 배출총량을… | Z10: 25년 기준 단계 1충족 (점수0) [자동채점] | 근거충분성: 부분적 | 근거: [사업보고서] 300p. 외부기관에 의뢰하여 연 1회 온실가스 배출량 및 에너지 사용량을 측정하고 있으며(17번째 줄) → 외부기관에 의뢰하여 측정을 수행하고 있다는 언급은 있으나, 검증의견서의 형식적 요건(검증표준, 검증수준, 검증범위, 검증의견 등)에 대한 구체적인 정보가 제시되지 않아 1단계 요건만 충족함. | 근거페이지: 사업보고서 25p, 149p, 255p, 266p, 269p, 278p, 300~301p / 지배구조보고서 3p, 16p, 18p, 26p, 37p, 42p | AA10: 부분 / 2단계 / 25점 요건 1,4 충족 / 2,3,5 부분적 -> 거버넌스, 자원 투입, 모니터링 시스템은 구축되어 있으나, 경영진 KPI 반영이 명확하지 않음 온실가스 배출량 3자 검증의견서 있음(3곳, 양산/울산/진주) https://drive.google.com/file/d/1iQNVOvIEADyejTiLgIBKIwHVANz3Ni8J/view?usp=drive_link - 양산(VMS, TUBE) - 진주(VMS) - 울산(BTS) 요건1: 검증기관 명시 요건2: 검증표준(방법론) 제시 (정확한 명시 부족) -> 추정 가능, 보고서 정확히 명시 X 요건3: 검증수준 공개 (제한적/합리적 보증 구분 불명확) 요건4: 검증 범위 적시 (사업장별 구분 필요) - O 요건5: 온실가스 관리에 관한 제3자 의견 (의견서 상세 내용 미공시) 검증의견서 정보 - 검증기관: BSI - 검증표준: GHG Protocol 또는 ISO14064-1 준용으로 추정되나, 보고서에 명확히 명시되지 않음 - 검증 범위: VMS사업부 양산 1공장, 진주공장 / BTS 사업부 울산 1공장 (사업장별 구분) - 검증 시기: 2025년 데이터는 온실가스배출량 3자 검증 완료 [보완필요증빙] BSI 검증의견서 원문, 적용 검증기준, 중요성 기준, assurance level, 검증 대상 기간·사업장·Scope, 검증결론 및 발견사항을 공시자료에 포함해야 한다. | AB10: 중기 | AC10: [현재 문제점] 제3자 검증을 받고 있음에도 검증의 품질을 판단할 정보가 공시되지 않는 점이다. [개선방향] BSI 검증의견서에 기준·수준·범위·결론을 표준 항목으로 포함하고 이를 ESG 공시와 함께 공개하는 것이다. 검증기관과 검증 범위는 현재처럼 명시,검증표준, 검증수준, 제3자 의견이 보고서에서 충분히 공시할 것. [필요근거] 독립 검증의견서 원문, 검증계약서, 검증 Scope 문서, 시정조치 결과서이다. | AD10: 대외 공시하는 온실가스 배출량 데이터에 대해 검증기관 정보, 검증표준, 검증수준, 검증 범위 및 검증의견 등 주요 요건을 포함한 제3자 검증의견서를 갖추고 있습니까? | AE10: 선택형(요건 충족 수)
A11: 10 | B11: E-4-1 | C11: 기본진단항목(v2.0) | D11: 환경 | E11: 에너지 | F11: 에너지 사용량 | G11: 조직이 소유, 관리, 통제하는 물리적 경계(사업장 등) 내에서 직접 생산하거나, 외부로부터 구매하는 에너지 사용 총량을 절감하고 있는지 점검 | 조직간 규모 차이(매출액, 생산량 등) 또는 각 조직의 사업 변동(구조조정, 인수합병 등)을 고려하여 상대적으로 비교가 용이한 단위 당 개념의 ‘원단위’를 기반으로 에너지 사용량을 확인 | H11: ‘전자공시시스템’ 上 사업보고서, ‘조직별 홈페이지’ 上 지속가능경영보고서, ‘한국에너지공단 홈페이지’ 上 산업부문 에너지 사용 및 온실가스 배출량 통계 | I11: 최근 4개년 회계연도 * 3개년 이하 데이터 보유 시 해당 데이터로 추세 산정 | J11: 국내외 사업장 및 기타 연결실체 | K11: 원단위 에너지 사용량 = 총 에너지 사용량 / 매출액(또는 생산량) | L11: 단계형 | M11: 3 | N11: 단계형: 1단계=0점 / 2단계=50점 / 3단계=100점 | O11: 1단계 | 지난 4개년 원단위 에너지 사용량이 증가 추세 | 2단계 | 지난 4개년 원단위 에너지 사용량이 변동 없음 | 3단계 | 지난 4개년 원단위 에너지 사용량이 감소 추세 | * 원단위 에너지 사용량을 관리하지 않고 있는 경우 0점 적용 | * 3개년 이하 데이터 보유 시 해당 데이터로 추세 산정 | * '유지 추세'로 판단할 경우 2단계로 적용하여 평가 | * (추세) 일정 기간 정량적 자료의 변동 방향성을 의미하며, 본 가이드라인에서는 4개년 데이터의 연평균 성장률(CAGR)을 추세로 정의 | * (원단위(per unit)) 어떤 제품/용역 1단위 생산을 위해 투입된 재화(자본, 시간, 에너지 등) 혹은 배출량을 측정하는 개념. 기업 간 규모를 고려하여 비교 가능성을 확보하기 위한 목적으로 활용 | P11: 부분대응 | Q11: KSSB 제2호 문단 29 부속 에너지 사용 관련 준용 | R11: GRI 302-1 | S11: 1_2_0_업종별 K-ESG 가이드라인(v2.0) 진단항목 | T11: 3 | X11: =IF(T11="","",SUMPRODUCT(('02_점수산정참고표'!$A$2:$A$314=$B11)*('02_점수산정참고표'!$C$2:$C$314=T11)*'02_점수산정참고표'!$E$2:$E$314)) -> 100 | Y11: 에너지 사용량 = ‘조직에서 직접 사용한 화석연료’ + ‘조직에서 직접 사용한 재생연료’ + ‘외부로부터 구매한 전기, 열 등’ + ‘조직에서 생산한 전기, 열(스팀) 등’ - ‘조직에서 사용하지 않고 외부로 판매한 전기, 열 등’ (고체, 기체, 액체 연료) 에너지 사용량 환산방법 = 연료 사용량 × 총발열량 (전기) 에너지 사용량 환산방법 = 전력사용량 × 발열량(소비) 조직의 에너지 사용량이 산업 내 어떠한 수준에 있는지 점검하는 방식에는 1) ‘온실가스 배출권의할당및거래에관한법률’ 등에 따른 할당량 대비 비교, 2) ‘온실가스·에너지 목표관리제’에 따른 목표 대비 비교, 3) 조직의 과거년도 배출량을 기반으로 설정한 목표 대비 비교, 4) RE100… | Z11: [자동채점] | 근거충분성: 충분 | 근거: [사업보고서] 258p. 제54기 연간 에너지사용량(TJ) 687.511, 제53기 632.933, 제52기 618.881, 제51기 471.479(11번째 줄) → 제54기부터 제51기까지 4개년 에너지 사용량 총합이 지속적으로 증가하고 있으며, 매출액 대비 원단위 에너지 사용량 또한 증가 추세에 있어 1단계에 해당합니다. | 근거페이지: 사업보고서 25~28p, 151p, 228p, 258p, 269p, 282p, 292p, 300~301p, 307p / 지배구조보고서 8p, 17p, 45p | AA11: 직접 계산 / 감소 추세 / 3단계 / 100점 [홈페이지 공개 자료] - 2023~2025 https://drive.google.com/file/d/1sbXOoqD2wtmpGBb11NVWCzH5u6ikdsu9/view?usp=drive_link - 공개된 원단위 데이터가 없어 산식으로 계산. - 총 에너지 사용량 / 매출액 - 에너지 사용량 (611.8TJ -> 688TJ -> 681.8TJ) - 원단위 계산 결과 (0.394TJ -> 0.357TJ -> 0.389TJ) [보완필요증빙] 사업장별 전기·연료 사용량, 재생/비재생 에너지 구분, 매출 또는 생산량과 환경데이터 경계 일치표, 전사 연결기준 에너지 집약도 산식, 에너지 절감 프로젝트 실적이 필요하다. | AB11: 즉시 | AC11: [현재 문제점] 공개된 에너지 집약도는 개선되고 있으나 전사 연결범위와 자체 계산 원단위가 일치하지 않는 점이다. [개선방향] 가이드라인이 허용하는 대체 비교방식(온실가스·에너지 목표 대비, RE100 목표 대비, 벤치마킹 기업 대비)을 병행 공시해 단일 지표 변동 리스크를 보완한다. [필요 근거] 4개년 연속 원단위 데이터, 사업장별 utility 명세, 에너지 데이터 원장, 매출 경계 reconciliation과 연간 절감 프로젝트 효과 산정표필요 | AD11: 원단위 에너지 사용량을 산정하고, 이에 대한 증감 현황을 점검·관리하고 있습니까? | AE11: 단계(1~3)
A12: 11 | B12: E-5-1 | C12: 기본진단항목(v2.0) | D12: 환경 | E12: 용수 | F12: 용수 사용량 | G12: 조직이 용수를 공급받는 취수원을 보호하고 있는지, 또는 사업장이 위치한 지역의 수자원 고갈 리스크에 대비하고 있는지를 간접적으로 점검할 수 있는 항목으로써, 조직이 사용하는 용수 총량(신규 취수량, 내부 재사용량)을 효율적으로 관리하고 있는지 확인 | 조직간 규모 차이(매출액, 생산량 등) 또는 각 조직의 사업 변동(구조조정, 인수합병 등)을 고려하여 상대적 비교가능성이 높은 ‘원단위’ 개념을 기반으로 용수 사용량을 점검 | H12: ‘조직별 홈페이지’ 上 지속가능경영보고서, ‘한국에너지공단 물정보포털(My Water)’ 上 GIS 수자원 | I12: 최근 4개년 회계연도 * 3개년 이하 데이터 보유 시 해당 데이터로 추세 산정 | J12: 국내외 사업장 및 기타 연결실체 | K12: 원단위 용수 사용량 = 총 용수 사용량 / 매출액(또는 생산량) | L12: 단계형 | M12: 3 | N12: 단계형: 1단계=0점 / 2단계=50점 / 3단계=100점 | O12: 1단계 | 지난 4개년 원단위 용수 사용량이 증가 추세 | 2단계 | 지난 4개년 원단위 용수 사용량이 변동 없음 | 3단계 | 지난 4개년 원단위 용수 사용량이 감소 추세 | * 원단위 용수 사용량을 관리하고 있지 않은 경우 0점 적용 | * 3개년 이하 데이터 보유 시 해당 데이터로 추세 산정 | * '유지 추세'로 판단할 경우 2단계로 적용하여 평가 | * (추세) 일정 기간 정량적 자료의 변동 방향성을 의미하며, 본 가이드라인에서는 4개년 데이터의 연평균 성장률(CAGR)을 추세로 정의 | * (원단위(per unit)) 어떤 제품/용역 1단위 생산을 위해 투입된 재화(자본, 시간, 에너지 등) 혹은 배출량을 측정하는 개념. 기업 간 규모를 고려하여 비교 가능성을 확보하기 위한 목적으로 활용 | P12: GAP(대응지표 없음) | Q12: KSSB 제2호 직접 규정 없음(업종기반지표로만 요구 가능) | R12: GRI 303, CDSB 물 적용지침 | S12: 1_2_0_업종별 K-ESG 가이드라인(v2.0) 진단항목 | T12: 1 | X12: =IF(T12="","",SUMPRODUCT(('02_점수산정참고표'!$A$2:$A$314=$B12)*('02_점수산정참고표'!$C$2:$C$314=T12)*'02_점수산정참고표'!$E$2:$E$314)) -> 0 | Y12: UN의 환경경제 통합계정(System of Integrated Environmental and Economic Accounting, SEEA, 1993)에 따른 ‘용수 사용량’은 다음과 같이 정의할 수 있다. - 용수 사용량 = 환경에서 유입한 취수량 + 조직 내 재사용량 + 다른 조직에서 전달받은 폐수량 * 취수에 해당하는 경우 : 공업용수 外 표층수, 지하수, 토양수, 강우포집, 해양취수 용수 사용량은 산업분류, 사업특성, 생산규모에 따라 영향을 받는다. 따라서 조직의 용수 사용량이 산업 내 어떠한 수준에 있는지 점검하는 방식에는 1) 조직이 취수받는 수원별 공급능력 대비, 2) 조직의 사업장이 위치한 지역별 수자원 부존량 대비, 3) 조직의 과거년도 사용량… | Z12: [자동채점] | 근거충분성: 불충분 | 근거: [사업보고서] 300p. 당사는 온실가스, 에너지 관리업체 지정업체로 등록되었습니다. 외부기관에 의뢰하여 연 1회 온실가스 배출량 및 에너지 사용량을 측정하고 있으며, 각 분기별로는 당사 내부적으로 측정하고 있습니다.(16번째 줄) → 제시된 근거에는 온실가스와 에너지 사용량에 대한 측정 정보만 존재할 뿐, 용수 사용량에 대한 정량적 데이터가 전혀 포함되어 있지 않아 원단위 용수 사용량 추세를 확인할 수 없습니다. | 근거페이지: 사업보고서 13p, 25~28p, 151p, 228p, 258p, 265p, 269p, 282p, 292p, 300~301p, 307p / 지배구조보고서 3p, 8p | AA12: 직접 계산 / 증가 추세 / 1단계 / 0점 [홈페이지 공개 자료] - 2023~2025 https://drive.google.com/file/d/1sbXOoqD2wtmpGBb11NVWCzH5u6ikdsu9/view?usp=drive_link - 공개된 원단위 데이터가 없어 산식으로 계산. - 총 용수 사용량 / 매출액 - 용수 사용량 (75,077m^3 -> 98,031m^3 -> 108.840m^3) - 원단위 계산 결과 (48.3m^3 -> 50.9m^3 -> 62.1m^3) | AB12: 즉시 | AC12: [현재 문제점] 용수 사용 원단위와 절대 사용량이 동시에 상승한 점이다. [개선방향] 원단위 데이터 공개, BTS 등 사용량 증가 사업장을 우선 대상으로 공정별 물수지를 작성하고 재이용·순환수 확대와 사업장별 연간 감축목표를 설정하는 것이다. 이드라인이 허용하는 대체 비교방식(취수원 공급능력 대비, 지역 수자원 부존량 대비, 과거 목표 대비, 자체 절감목표 대비, 벤치마킹 대비) [필요근거] 공정별 water balance, 계량기 데이터, 재이용수 실적, 투자 전후 절감량과 연도별 용수 집약도 관리표 | AD12: 원단위 용수 사용량을 산정하고, 이에 대한 증감 현황을 점검·관리하고 있습니까? | AE12: 단계(1~3)
A13: 12 | B13: E-6-1 | C13: 기본진단항목(v2.0) | D13: 환경 | E13: 폐기물 | F13: 폐기물 배출량 | G13: 조직이 소유, 관리, 통제하는 물리적 경계(사업장 등) 내에서 사업 및 영업 활동(ex. 연구개발, 제품 생산/가공/포장 등 포함, 소비자가 사용 이후 폐기한 폐제품은 제외)에 따라 발생하는 폐기물을 저감하고 있는지 확인 | 조직간 규모 차이(매출액, 생산량 등) 또는 각 조직의 사업 변동(구조조정, 인수합병 등)을 고려하여 상대적 비교가능성 높은 ‘원단위’ 개념을 기반으로 폐기물 배출량을 점검 | H13: ‘조직별 홈페이지’ 上 지속가능경영보고서, ‘한국환경공단’>자원순환정보시스템>연도별 전국 폐기물 발생 및 처리현황 | I13: 최근 4개년 회계연도 * 3개년 이하 데이터 보유 시 해당 데이터로 추세 산정 | J13: 국내외 사업장 및 기타 연결실체 | K13: 원단위 폐기물 배출량 = 총 폐기물 배출량 / 매출액(또는 생산량) | L13: 단계형 | M13: 3 | N13: 단계형: 1단계=0점 / 2단계=50점 / 3단계=100점 | O13: 1단계 | 지난 4개년 원단위 폐기물 배출량이 증가 추세 | 2단계 | 지난 4개년 원단위 폐기물 배출량이 변동 없음 | 3단계 | 지난 4개년 원단위 폐기물 배출량이 감소 추세 | * 원단위 폐기물 배출량을 관리하지 않고 있는 경우 0점 적용 | * 3개년 이하 데이터 보유 시 해당 데이터로 추세 산정 | * '유지 추세'로 판단할 경우 2단계로 적용하여 평가 | * (추세) 일정 기간 정량적 자료의 변동 방향성을 의미하며, 본 가이드라인에서는 4개년 데이터의 연평균 성장률(CAGR)을 추세로 정의 | * (원단위(per unit)) 어떤 제품/용역 1단위 생산을 위해 투입된 재화(자본, 시간, 에너지 등) 혹은 배출량을 측정하는 개념. 기업 간 규모를 고려하여 비교 가능성을 확보하기 위한 목적으로 활용 | P13: GAP(대응지표 없음) | Q13: KSSB 제2호 직접 규정 없음(업종기반지표로만 요구 가능) | R13: GRI 306 | S13: 1_2_0_업종별 K-ESG 가이드라인(v2.0) 진단항목 | T13: 1 | X13: =IF(T13="","",SUMPRODUCT(('02_점수산정참고표'!$A$2:$A$314=$B13)*('02_점수산정참고표'!$C$2:$C$314=T13)*'02_점수산정참고표'!$E$2:$E$314)) -> 0 | Y13: 폐기물이란 쓰레기, 연소재, 오니, 폐유, 폐산, 폐알칼리 및 동물사체 등으로 사람의 생활이나 사업활동에 필요하지 않게 된 물질을 말하며, 조직에서 발생하는 폐기물의 종류는 ‘사업장배출시설계폐기물’, ‘사업장생활계폐기물’, ‘지정폐기물’, ‘건설폐기물’로 구분된다. - 조직이 배출하는 폐기물의 종류와 배출량은 ‘환경부-폐기물적법처리시스템(Allbaro)’, ‘환경부-환경정보 공개시스템’에서 확인 가능하다. 폐기물 배출량은 산업분류, 사업특성, 생산규모에 따라 영향을 받는다. 따라서 조직의 폐기물 배출량이 산업 내 어떠한 수준에 있는지 점검하는 방식에는 1) 업종별 총 폐기물 배출량 대비, 2) 조직의 사업장이 위치한 지역의 총 폐기물 배출량 대비, 3) 조직의… | Z13: [자동채점] | 근거충분성: 불충분 | 근거: [사업보고서] 258p. 당사는 온실가스, 에너지 관리업체 지정업체로 등록되었습니다. 외부기관에 의뢰하여 연 1회 온실가스 배출량 및 에너지 사용량을 측정하고 있으며, 각 분기별로는 당사 내부적으로 측정하고 있습니다.(11번째 줄) → 제공된 근거에는 온실가스 및 에너지 사용량에 대한 정보만 존재할 뿐, 폐기물 배출량에 대한 정량적 데이터가 전혀 포함되어 있지 않아 원단위 폐기물 배출량 산정 및 추세 확인이 불가능합니다. | 근거페이지: 사업보고서 19p, 25~28p, 33p, 151p, 258p, 260p, 269p, 292p, 300~301p, 307p / 지배구조보고서 3p, 8~9p, 17p | AA13: 직접 계산 / 증가 추세 / 1단계 / 0점 [홈페이지 공개 자료] - 2023~2025 https://drive.google.com/file/d/1sbXOoqD2wtmpGBb11NVWCzH5u6ikdsu9/view?usp=drive_link - 공개된 원단위 데이터가 없어 산식으로 계산. - 총 폐기물 배출량 / 매출액 - 폐기물 총 배출량 (2,351.3t -> 2,331.7t -> 2,740t) - 원단위 계산 결과 (1.513t -> 1.211t -> 1.562t) | AB13: 즉시 | AC13: [현재문제점] 폐기물 배출량 증가추세이며 원단위 데이터가 없다. [개선방향] 업종별/지역별 총량 대비, 과거 목표 대비, 자체 감축목표 대비, 벤치마킹 대비 중 하나를 도입해 '목표관리 중'으로 재평가받을 근거를 마련한다. [필요 근거] 공식 폐기물 원단위 산출에 사용한 매출액 분모, 사업장 범위, 지정·일반폐기물 원장, 처리방법별 실적, 폐기물 발생량과 생산량의 연결표가 필요하다. | AD13: 원단위 폐기물 배출량을 산정하고, 이에 대한 증감 현황을 점검·관리하고 있습니까? | AE13: 단계(1~3)
... A15: 14 | B15: E-7-2 | C15: 기본진단항목(v2.0) | D15: 환경 | E15: 오염물질 | F15: 수질오염물질 배출량 | G15: 조직이 소유, 관리, 통제하는 물리적 경계(사업장 등) 내에서 최종 발생하는 수질오염물질을 저감하는 등 수자원 보호를 위한 노력을 이행하고 있는지 확인 | ｢물환경보전법｣ 上 수질오염물질을 대표하는 생물화학적 산소요구량(BOD), 총 유기탄소량(TOC), 부유물질량(SS)의 배출 농도를 기간별 비교하는 방식으로 점검 | H15: ‘조직별 홈페이지’ 上 지속가능경영보고서, ‘환경부-물환경정보시스템’ 上 수질측정망 | I15: 최근 4개년 회계연도 * 3개년 이하 데이터 보유 시 해당 데이터로 추세 산정 | J15: 국내외 사업장 및 기타 연결실체 | K15: 수질오염물질 배출 = 생물화학적 산소요구량, 총 유기탄소량, 부유물질량의 배출농도(PPM, mg/l) | L15: 단계형 | M15: 3 | N15: 단계형: 1단계=0점 / 2단계=50점 / 3단계=100점 | O15: 1단계 | 지난 4개년 수질오염물질 평균 배출농도가 증가 추세 | 2단계 | 지난 4개년 수질오염물질 평균 배출농도가 변동 없음 | 3단계 | 지난 4개년 수질오염물질 평균 배출농도가 감소 추세 | * 수질오염물질 평균 배출농도를 관리하지 않고 있는 경우 0점 적용 | * 국내 및 해외 모든 사업장의 수질오염물질 배출농도가 ‘0’인 경우 100점 적용 | * 3개년 이하 데이터 보유 시 해당 데이터로 추세 산정 | * '유지 추세'로 판단할 경우 2단계로 적용하여 평가 | * (추세) 일정 기간 정량적 자료의 변동 방향성을 의미하며, 본 가이드라인에서는 4개년 데이터의 연평균 성장률(CAGR)을 추세로 정의 | P15: GAP(대응지표 없음) | Q15: KSSB 제2호 직접 규정 없음 | R15: GRI 303-4 | S15: 1_2_0_업종별 K-ESG 가이드라인(v2.0) 진단항목 | T15: 1 | X15: =IF(T15="","",SUMPRODUCT(('02_점수산정참고표'!$A$2:$A$314=$B15)*('02_점수산정참고표'!$C$2:$C$314=T15)*'02_점수산정참고표'!$E$2:$E$314)) -> 0 | Y15: 해당 지표에서 정의한 수질오염물질인 생물화학적 산소요구량(BOD), 총 유기탄소량(TOC), 부유물질량(SS)은 ｢물환경보전법 시행규칙｣ 별표13 上 ‘수질오염물질의 배출허용기준’ 항목이다.  수질오염물질 배출농도는 ｢환경분야 시험·검사 등에 관한 법률｣ 제6조제1항에 따라 환경부장관이 정하여 고시한 환경오염공정시험기준(또는 이에 준하는 국가별 관계법령)에 따라 측정한다. ｢물환경보전법｣ 제35조에 따른 수질오염물질 방지시설 면제사업장에 해당하는 경우 수질오염물질 배출 성과를 점검하지 아니할 수 있다. 조직의 수질오염물질 배출 수준을 점검하는 방식에는 1) 폐수를 방류하거나, 폐수처리시설과 관련된 수계의 평균 오염농도 대비, 2) 조직의 과거년도 배출농도를… | Z15: [자동채점] | 근거충분성: 불충분 | 근거: [사업보고서] 300p. 당사는 온실가스, 에너지 관리업체 지정업체로 등록되었습니다. 외부기관에 의뢰하여 연 1회 온실가스 배출량 및 에너지 사용량을 측정하고 있으며, 각 분기별로는 당사 내부적으로 측정하고 있습니다.(16번째 줄) → 제시된 근거에는 온실가스 및 에너지 사용량에 대한 측정 정보만 있을 뿐, 수질오염물질(BOD, TOC, SS) 배출량에 대한 정량적 데이터가 존재하지 않아 관리하지 않는 것으로 간주하여 1단계(0점)를 적용합니다. | 근거페이지: 사업보고서 25~26p, 129~130p, 149p, 224p, 265p, 269p, 278p, 281p, 300~301p / 지배구조보고서 8p, 10p, 38p | AA15: 채점 불가 [홈페이지 공개 자료] - 2023~2025 https://drive.google.com/file/d/1sbXOoqD2wtmpGBb11NVWCzH5u6ikdsu9/view?usp=drive_link - 자체 수질 정화 및 외부분석기관의뢰 수질환경측정 (분기 별 1회) - 폐수누출훈련 하지만, 배출관련 정량 데이터 X -> 그러나 배출농도 관련 정량 데이터 없음. -> K-ESG는 배출농도(BOD, TOC,SS)요구, 보고서 명시 X [판단근거] K15와 O15는 BOD·TOC·SS 등 수질오염물질의 평균 배출농도(ppm 또는 mg/L) 추세를 요구한다. [확인근거] AA15에는 "자체 수질 정화 및 외부분석기관의뢰 수질환경측정 1회/분기"와 폐수 누출 훈련은 확인되지만 BOD·TOC·SS의 정량 배출농도는 찾지 못했다고 적혀 있다. 회사 공식 ESG 페이지도 분기별 외부분석기관 수질환경측정과 폐수누출훈련을 설명하지만 공개된 정량 수자원 표는 취수·방류·사용량 중심으로 구성돼 있다. [감점사유] 수질 측정을 실시한다는 사실은 오히려 내부 농도자료가 존재할 가능성을 보여주지만, 현재 Excel에는 그 값이 없어 추세를 계산할 수 없다. 따라서 회사가 실제로 농도를 관리하지 않는다고 단정하기보다는 증빙 미제출에 따른 잠정 0점으로 표현하는 것이 정확하다. | AB15: 즉시 | AC15: [현재 문제점] 정기 수질검사는 시행하지만 배출농도 관련 BOD·TOC·SS 정량 데이터가 없음. [개선방향] 기존 시험성적서를 데이터화하고 사업장별 배출농도와 법정기준 대비 수준을 연간 KPI로 관리하는 것이다. 분기별 수질 시험성적서, BOD·TOC·SS 원자료, 사업장별 폐수 배출구 목록, 법정 기준, 연간 평균농도와 3개년 추세표가 필요하다. [필요근거] 외부분석기관 시험성적서, 폐수배출시설 관리대장, 오염물질별 연평균 산정표와 법정기준 대비표이다. | AD15: 최종 배출한 폐수 내 생물화학적 산소요구량(BOD), 총 유기탄소량(TOC), 부유물질량(SS)의 평균 배출 농도가 저감 추세입니까? | AE15: 단계(1~3)
A16: 15 | B16: E-8-1 | C16: 기본진단항목(v2.0) | D16: 환경 | E16: 환경 법/규제 위반 | F16: 환경 법/규제 위반 | G16: 조직이 사업을 운영하는 과정에서 준수해야 할 환경 관리 법/규제를 명확하게 인식하고, 환경 법/규제 리스크 해결을 위한 투자 및 개선활동이 효과적인지 확인 | 환경 관련 법/규제 위반 사건 중 조직의 재무구조 및 평판 관리에 상당한 영향력을 미치는 사법상 형벌, 행정상 처분(금전적, 비금전적)에 대해 가중치를 달리 적용하는 방식으로 ‘환경 법/규제 위반’을 점검 | H16: ‘전자공시시스템’ 上 사업보고서, ‘조직별 홈페이지’ 上 지속가능경영보고서 | I16: 최근 4개년 회계연도 * 3개년 이하 데이터 보유 시 해당 데이터로 추세 산정 | J16: 국내외 사업장 및 기타 연결실체 | K16: ∑(환경 법/규제 위반 건 * 처벌수위별 감점 기준) | L16: 감점형 | M16: 3 | N16: 감점형 (기본 100점에서 위반유형별 감점 차감, 최저 0점 제한) | 세부 배점 기준: 유형 1= -50점 / 유형 2 = -30점 / 유형 3 = -10점 | O16: 유형 1 | 지난 4개년 간 환경 법/규제 위반내역 중 판결이 확정된 건수에 대해, 처벌수위가 사법상 형벌, 벌금, 과료인 경우, 또는 국가나 지방자치단체를 당사자로 하는 계약에서 입찰참가자격을 제한당한 경우 | 유형 2 | 지난 4개년 간 환경 법/규제 위반내역 중 판결이 확정된 건수에 대해, 처벌수위가 행정상 처분 중 금전적 처분에 해당하는 과태료, 과징금, 이행강제금 등인 경우 | 유형 3 | 지난 4개년 간 환경 법/규제 위반내역 중 판결이 확정된 건수에 대해, 처벌수위가 행정상 처분 중 비금전적 처분에 해당하는 시정 명령, 시정권고, 경고 등인 경우 | * 감점 사항이 없을 경우, 감점 없음 | * 단, 처벌 및 조치내역의 발생횟수에 따른 감점 시 환경 분야의 총 평가 최저점은 0점으로 하한선 설정 | P16: 부분대응 | Q16: KSSB 제1호 문단 위험관리 원칙 준용 | R16: GRI 2-27(Compliance) | S16: 1_2_0_업종별 K-ESG 가이드라인(v2.0) 진단항목 | T16: 해당없음(감점형) | U16: 0 | V16: 0 | W16: 0 | X16: =MAX(0,100-(N(U16)*50+N(V16)*30+N(W16)*10)) -> 100 | Y16: 환경 법/규제 위반행위란 오염물질 불법배출의 가중처벌, 환경보호지역 오염행위 등의 가중처벌, 과실범, 멸종위기 야생생물의 포획 등의 가중처벌, 폐기물 불법처리의 가중처벌, 누범의 가중, 명령 불이행자에 대한 처벌의 규정에 해당하는 행위나 ｢대기환경보전법｣ 비산먼지 발생을 억제하기 위한 시설 설치 혹은 조치를 하지 않은 경우, ｢화학물질 등록 및 평가 등에 관한 법률｣ 또는 ｢화학물질관리법｣ 유해화학물질을 부적절하게 관리한 경우, ｢폐기물관리법｣ 생활폐기물을 불법 처리하는 행위 등으로써 ｢환경범죄 등의 단속 및 가중처벌에 관한 법률｣ 제3조에서 제14조를 통해 처벌수위를 규정하고 있다. - 제3조 : 오염물질 불법배출의 가중처벌 - 제4조 : 환경보호지역 오염행위 등의… | Z16: [자동채점] | 근거충분성: 충분 | 근거: 위반사항 없음 | 근거페이지: 사업보고서 14~32p, 94p, 110p, 163p, 251p, 254~255p, 259p, 275p, 293p, 300~301p / 지배구조보고서 6~25p, 45p | AA16: 부분 / 감점없음 / 100점 [판단근거] O16은 사법상 처벌·벌금·입찰제한, 금전적 행정처분, 비금전적 시정명령·경고 등을 유형별 감점하고 위반이 없으면 100점을 부여한다. [확인근거] Excel의 U16, V16, W16은 모두 0으로 기재돼 있고 AA16도 "사업보고서 기준 환경 제재 없음", "환경 관련 오염 행위, 불법 배출은 확인되지 않음"으로 정리한다. 따라서 Excel 내부 근거만으로는 감점할 사유가 없다. [감점사유] 기사에서 "납 검출" 등의 환경 우려가 언급됐다는 사실만으로는 K-ESG가 요구하는 확정된 사법·행정처분으로 간주할 수 없으므로 점수를 임의로 감점하면 안 된다. 다만 평가기간 동안 모든 국내외 사업장과 연결법인을 대상으로 한 환경 제재 조회표가 Excel에 첨부된 것은 아니므로 "완전 무위반"에 대한 방어근거는 보강할 필요가 있다. 회사 공식 EHS 정책은 국내외 환경법규·협약 준수 및 엄격한 내부기준 수립 방침을 공개하지만, 정책 자체가 무위반 실적을 증명하지는 않는다. | AB16: 중기 | AC16: [현재 문제점] 무위반으로 판단할 수는 있으나 이를 전 사업장·전 연결법인 기준으로 입증하는 중앙관리대장이 부족한 점이다. [개선방향] 법인·사업장별 환경법규 준수와 처분내역을 분기 단위로 취합하는 환경 compliance register를 운영하는 것이다. 최근 평가기간의 국내외 사업장별 환경 행정처분 조회표, 과태료·과징금·시정명령 현황, 환경법규 준수 평가 결과, 사건 발생 시 시정·재발방지 완료자료가 필요하다. [필요근거] 규제기관 처분통지서, 자체 법규준수평가표, 사업장 확인서, 시정조치 종결보고서이다. | AD16: 최근 환경 관련 법·규제 위반으로 인해 사법상 처벌, 입찰참가자격 제한, 또는 행정상 금전적·비금전적 처분이 확정된 내역이 있습니까? | AE16: 단계(1~3)/감점형
A17: 16 | B17: E-10-1 | C17: 기본진단항목(v2.0) | D17: 환경 | E17: 기후변화대응 | F17: 기후변화 거버넌스 | G17: 조직 내 기후변화 이슈에 체계적이고 효과적으로 대응할 수 있는 관리·감독(기구) 구축 여부 점검 | 조직 내 기후변화 대응 목표가 핵심성과지표(KPIs)에 반영되어 있는지 점검하고, 이를 통해 인센티브를 제공하고 있는지 확인 | H17: ‘조직별 홈페이지’ 上 지속가능성보고서, TCFD 보고서, 기후변화 대응계획, 이사회 또는 ESG위원회(지속가능경영위원회) 조직도 및 회의록 | I17: 직전 회계연도 기준 | J17: N/A | K17: N/A | L17: 단계형 | M17: 5 | N17: 단계형: 1단계=0점 / 2단계=25점 / 3단계=50점 / 4단계=75점 / 5단계=100점 | O17: 1단계 | 기후변화 문제에 대응할 수 있는 담당자(혹은 기구)가 없음 | 2단계 | 기후변화 문제에 대응하기 위한 관리자(혹은 담당부서)가 있으며, 담당부서의 KPIs에 조직의 기후변화 대응 목표가 반영되어 있음 | 3단계 | 기후변화 문제에 대응하기 위한 관리직(C-level) 혹은 위원회가 있으며, 관리직의 KPIs에 조직의 기후변화 대응 목표가 반영되어 있음 (예 : 기후/지속가능성/ESG 최고 책임자, 리스크 관리 최고 책임자(CEO 제외) 등) | 4단계 | 3단계 + 기후 관련 문제를 이사회 차원의 위원회에서 관리·감독하고 있으며, 이사회 안건으로 상정하고 있음 (예 : 기후/지속가능성/ESG 위원회, 리스크 관리 위원회 등) | 5단계 | 4단계 + 조직 구성원에게 기후변화 대응 목표 KPIs 달성도에 따라 인센티브를 제공하고 있음 | P17: 완전대응 | Q17: KSSB 제2호 문단 6(1),(2) — 기후 거버넌스 | R17: TCFD, GRI 2-9 | S17: 1_2_0_업종별 K-ESG 가이드라인(v2.0) 진단항목 | T17: 1 | X17: =IF(T17="","",SUMPRODUCT(('02_점수산정참고표'!$A$2:$A$314=$B17)*('02_점수산정참고표'!$C$2:$C$314=T17)*'02_점수산정참고표'!$E$2:$E$314)) -> 0 | Y17: TCFD(Task Force on Climate-related Financial Disclosures)는 조직이 자사가 직면한 기후변화 관련 위험과 기회를 평가해야 하며 이로 인해 발생할 수 있는 기업의 재무적 영향과 비용, 미래의 기회 등을 평가하는 것을 권고하고 있다. 조직은 기후변화에 대응할 수 있도록 명확한 목표를 설정하고, 이에 대한 중장기적 계획을 수립하며 이를 지속적으로 책임질 수 있는 담당자(혹은 기구)를 지정해야 한다. 기후변화 위기 대응 거버넌스를 구축하여 보다 체계적이고 효과적으로 관련 활동 및 성과를 관리해야 한다. 기후변화 대응을 위한 조직 활동으로는 온실가스 감축, 재생에너지 확대, 산림보호, 폐기물 관리, 관련 교육 등이 있으며, 위… | Z17: [자동채점] | 근거충분성: 충분 | 근거: ⚠️[출처 미확정, 검색 1위 후보로 대체] [사업보고서] 301p. 당사는 이사회 내 별도의 위원회를 설치하고 있지 않습니다.(줄 위치 특정 실패) → 기후변화 대응을 위한 전담 기구, 관리자, KPI 반영 및 인센티브 체계에 대한 근거가 확인되지 않으며, 이사회 내 ESG 위원회 또한 설치되어 있지 않아 1단계에 해당함. | 근거페이지: 사업보고서 269p, 301p / 지배구조보고서 3p, 15p, 17~19p, 32p, 35~39p, 44p | AA17: 부분 / 1단계 / 0점 [판단근거] O17의 2단계는 담당자·담당부서가 존재하는 것만으로 끝나지 않고 해당 조직의 KPI에 기후변화 목표가 포함되어야 한다. 3단계는 C-level 또는 경영위원회와 경영진 KPI, 4단계는 이사회 차원의 관리·감독과 안건, 5단계는 KPI와 인센티브 연동까지 요구한다. [확인근거] AA17은 스스로 "전담부서, 경영진 보고체계는 확인되나 KPI 반영, 이사회 차원 관리/감독, 인센티브 연동 근거 없음"이라고 적고 있다. 이 서술대로라면 2단계의 필수 KPI 요건을 충족하지 못하므로 "2단계 충족" 문구는 논리적으로 맞지 않는다. [감점사유] 환경담당조직 또는 경영진 보고가 존재한다는 운영사실과 K-ESG 단계 충족은 구분해야 한다. 기후 KPI를 업무평가에 포함했다는 증빙이 없고, 이사회가 기후리스크·온실가스 목표를 정기 감독한다는 회의체 근거와 보상 연계도 확인되지 않는다. | AB17: 즉시 | AC17: [현재 문제점] 기후업무 수행조직은 존재할 가능성이 높지만 KPI·이사회 감독·보상체계로 이어지는 책임구조가 입증되지 않는 점이다. [개선방향] 환경담당부서 KPI에서 시작해 C-level KPI, 이사회 기후안건, 성과보상까지 단계적으로 연결하는 기후 거버넌스를 구축하는 것이다. 3단계 도달을 위해 기후 대응을 총괄하는 C-level(CSO) 또는 전담 위원회를 지정하고 KPI를 반영한다. -> 후 책임자 지정문서, 환경부서 KPI, CEO/C-level KPI, 이사회 또는 ESG위원회 운영규정, 기후 안건 회의록, 경영진 보상 KPI 연계표가 필요 [필요근거] 조직별 KPI 정의서, 이사회 운영규정, 기후안건 회의록, 경영진 평가표와 인센티브 산정자료이다. | AD17: 조직 내 기후변화 이슈를 총괄 관리·감독하는 기구가 설치되어 있으며, 대응 목표가 임직원 KPI 및 인센티브(보상) 체계에 연동되어 운영되고 있습니까? | AE17: 단계(1~5)
A18: 17 | B18: E-10-5 | C18: 기본진단항목(v2.0) | D18: 환경 | E18: 기후변화대응 | F18: 온실가스 배출량 감축 선언 | G18: 국가온실가스감축목표(NDC)에 따른 국내 2030년 온실가스 감축 목표(2018년 수준 대비 40% 감축)를 고려하여, 조직이 온실가스 배출량 감축 목표를 설정하고 있는지 여부 확인 | H18: ‘조직별 홈페이지’ 上 지속가능경영보고서, TCFD 보고서, CDP 보고서, Net-zero선언문, 기타 기후관련 이니셔티브 가입 선언 등 | I18: 직전 회계연도 기준 | J18: 국내외 사업장 및 기타 연결실체 | K18: (구분1 + 구분2) * 1/2 | L18: 복합가중형 | N18: 복합가중형: 2개 세부요소의 균등가중평균 (1/2 + 1/2) — 최종 점수 = (구분1 점수 + 구분2 점수) × 1/2 | 세부 배점 기준 (구분별): 1개 이하 충족=0점 / 2개 이하 충족=25점 / 3개 이하 충족=50점 / 4개 이하 충족=75점 / 5개 이하 충족=100점 |*각 구분(구분1, 구분2)의 항목 충족 개수 확인 후 상세 배점표 참조하여 수동 산정 | O18: 구분1(1/2) | 구분2(1/2) 요건1 | 조직이 온실가스 배출 감축 선언(Commitment)을 하고 이를 공개하는 경우 | 조직이 사업장 내에서 배출하는 온실가스 배출량에 대해 파악하고 있는 경우 요건2 | 조직이 온실가스 배출량 감축을 위한 기준연도와 목표연도, 감축 범위를 설정한 경우 | 조직이 공급망에서 배출하는 온실가스 배출량을 관리하고 있는 경우 요건3 | 조직이 온실가스 배출량 감축을 위해 중간목표를 포함한 중장기 로드맵을 가지고 있는 경우 | Scope1, 2 영역의 구체적인 온실가스 감축 프로그램을 이행하는 경우 요건4 | 조직이 온실가스 배출량 감축을 위한 구체적인 감축 계획을 수립한 경우 | Scope3 영역을 포함한 구체적인 온실가스 감축 프로그램을 이행하는 경우 요건5 | 조직의 온실가스 감축 목표를 SBTi 등 과학적 기반으로 검증받고 있는 경우 | 탄소제거 인증 프레임워크에 따라 인증된 탄소배출 상쇄(Carbon offset) 계획을 수립한 경우 ※ 온실가스 배출 감축선언을 하지 않은 경우, 사업장 내 온실가스 배출량을 관리하지 않는 경우 0점 처리 | P18: 완전대응 | Q18: KSSB 제2호 문단 33~36 — 감축목표·SBTi 정합 | R18: GRI 305-5, SBTi | S18: 1_2_0_업종별 K-ESG 가이드라인(v2.0) 진단항목 | T18: 해당없음(복합가중형) | X18: 0 | Y18: 본 항목은 조직이 온실가스 배출량 감축 목표 설정 및 이를 공약하는지 여부와 이를 달성하기 위해 어떤 활동을 하고 있는지를 점검한다. 파리 협약에 따라 조직은 산업화 이전 수준보다 지구 온도 상승을 1.5°C로 제한한다는 목표에 맞게 비즈니스 활동 조정 등 온실가스 배출 감축을 위한 노력을 다해야 한다. 조직의 온실가스 배출 감소 전략은 사업장 내, 혹은 공급망에 이르기까지, Scope1,2 및 Scope3를 관리 할 수 있으며, 탄소 배출량 ‘0’ 또는 1.5°C 조정 경로에서 순배출량 ‘0’에 도달하는 것과 일치하는 수준으로 달성 목표를 설정하여야 한다. 조직의 온실가스 배출량 감축 목표연도는 파리협약에 따른 2050년 혹은 그 이전으로 설정해야 하며,… | Z18: [자동채점] | 근거충분성: 충분 | 근거: [구분1 0/5개→0점] [구분2 1/5개→0점] 평균 0.0점 | 근거페이지: 사업보고서 13p, 300~301p / 지배구조보고서 3p, 8~9p, 17p, 29p, 32p, 43~45p | [AI검토필요] 복합가중형(정밀계산) - 표본검증 권장 | AA18: 부분 / 12.5점 / 요건 1 충족, 요건 2 부분충족 [판단근거] O18은 두 개의 5개 요건군을 각각 채점한 뒤 평균하는 복합가중형이다. 구분 1에서는 공개적 감축선언은 명확히 인정된다. [확인근거] AA18은 "NDC 기준으로 2030년까지 탄소배출량 35% 절감, 2050년까지 Net Zero"를 명시하고 있고 회사 공식 EHS 페이지도 동일 목표를 공개한다. 그러나 기준연도, 정확한 감축 경계, 세부 로드맵, 과학기반 목표 검증은 확인되지 않아 구분 1은 1개 요건·0점이 방어적이다. 구분 2에서는 Scope 1·2 배출량 관리가 확인되고, Excel AA8에 고효율설비 설치와 에너지 사용 관리 등 Scope 1·2 감축에 연결되는 실행활동이 기재되어 있어 이를 "구체적 Scope 1·2 프로그램"으로 인정하면 2개 요건·25점이 가능하다. 두 구분 평균은 (0+25)/2=12.5점이다. [감점사유] 두 번째 요건군의 고효율설비를 명시적인 "온실가스 감축 프로그램"으로 인정하지 않는 평가자는 구분 2도 1개 요건으로 판단할 수 있어 최종점수가 0점까지 내려갈 해석 위험이 있다. 또한 공식 공시된 Scope 3는 지속적인 공급망 배출관리 체계로 보기 어려우며, SBTi 검증과 상쇄계획도 확인되지 않는다. 공식 ESG 페이지는 2023년 Scope 3 Category 1 데이터를 공개했지만 2024·2025년 값은 0으로 기재하고 있어 연속적인 Scope 3 관리 증거로 활용하기에는 한계가 있다. | AB18: 즉시 | AC18: [현재 문제점] 2030·2050 감축선언은 있으나 기준연도·감축경계·연차별 경로·Scope 3 계획이 하나의 로드맵으로 연결되지 않은 점이다. [개선방향] 2030년 35% 목표를 기준연도 절대배출량으로 환산하고 Scope별·사업장별 감축과제와 연간 마일스톤을 설정하는 것이다. -> 기준연도, 조직·운영경계, 2030·2050 목표의 절대배출량, 2026~2030 연차별 경로, Scope 1·2 프로젝트별 감축량, Scope 3 카테고리별 인벤토리, SBTi 또는 이에 준하는 목표 검증자료가 필요 [필요근거] 탄소중립 로드맵, Scope별 인벤토리, 감축 프로젝트 business case, 연간 감축실적 보고서와 외부 검증자료이다. | AD18: 국가 2030 NDC(2018년 대비 40% 감축) 수준을 고려하여 온실가스 감축 선언을 대내외에 공개하고, Scope 1·2를 포함한 배출량 파악·관리, 중간목표 기반 중장기 로드맵, 구체적 감축 프로그램(SBTi 등 외부 검증 및 탄소상쇄 포함)을 수립 및 이행하고 있습니까? | AE18: 단계(1~5)/복합가중형
A19: 18 | B19: G-1-1 | C19: 기본진단항목(v2.0) | D19: 지배구조 | E19: 이사회 구성 | F19: 이사회 내 ESG 안건 상정 | G19: 조직의 최고의사결정기구인 이사회 또는 산하 위원회가 ESG 관련 안건을 보고받고 있으며, 특히 중대한 ESG 안건에 대해서는 심의/의결하고 있는지 확인 | 이사회 또는 산하 위원회를 통해 조직의 ESG 경영이 효율적으로 관리 및 감독되고 있는지 점검하기 위해 1) 활동내역, 2) 운영 규정의 2가지를 점검 | 조직은 ESG 안건을 다루기 위해 이사회 산하에 ‘지속가능경영위원회(ESG위원회)’를 설립할 수 있으나, 이사회, 또는 기존의 산하 위원회(사회책임위원회, 투명경영위원회, 거버넌스위원회, 경영위원회, 감사위원회 등)를 통해서도 ESG 안건을 다룰 수 있음 | H19: 이사회 또는 산하 위원회 개최 내역, 이사회 또는 산하 위원회 운영규정 | I19: 직전 회계연도 | J19: N/A | K19: N/A | L19: 복합가중형 | N19: 복합가중형: 2개 세부요소의 균등가중평균 (1/2 + 1/2) — 최종 점수 = (영역1 점수 + 영역2 점수) × 1/2 | 세부 배점 기준 (단계별): 1단계=0점 / 2단계=50점 / 3단계=100점 *각 영역(영역1, 영역2)의 달성 단계(1~3단계) 확인 후 상세 배점표 참조하여 수동 산정 | O19: 영역1(1/2) | 영역2(1/2) 1단계 | 이사회 또는 산하 위원회에서 ESG 관련 안건을 다루고 있지 않은 경우 | 이사회 또는 산하 위원회 운영규정에 ESG 관련 사항을 명시하지 않는 경우 2단계 | 최근 1년간 ESG 관련 안건이 모두 '보고' 사항인 경우 | 이사회 또는 산하 위원회 운영규정에 'ESG'라는 단어만 기재하고 있는 경우 3단계 | 최근 1년간 ESG 관련 안건 중 '심의/의결' 사항이 있는 경우 | 이사회 또는 산하 위원회 운영규정에 ESG 이외에, 조직과 관련된 중요 ESG 이슈 또는 안건을 명시하고 있는 경우 | P19: 완전대응 | Q19: KSSB 제1호 문단 27(1) — 이사회 ESG 안건 감독 | R19: GRI 2-9, KCGS | S19: 1_2_0_업종별 K-ESG 가이드라인(v2.0) 진단항목 | T19: 해당없음(복합가중형) | X19: 50 | Y19: ESG가 사업운영 및 중장기 발전을 위한 중요한 요인으로 등장함에 따라, 조직의 최고의사결정기구인 이사회에서 ESG 안건을 검토/심의/의결하도록 요구받고 있다. 조직은 이사회에서 ESG와 관련한 중요 안건을 보고받거나, 심의/의결할 수도 있으며, 이사회 산하 위원회를 설치하여 ESG 관련 안건을 다루도록 함으로써 이사회 역할 수행의 전문성과 효율성을 제고할 수 있다. 조직은 ESG 안건을 다루기 위해 이사회 산하에 ‘ESG위원회’를 신설할 수 있으나, 이사회, 또는 기존에 설치한 위원회(사회책임위원회, 투명경영위원회, 거번너스위원회, 경영위원회, 감사위원회 등)를 통해서도 ESG 안건을 다룰 수 있다. 즉, ‘ESG위원회’ 설치 여부가 중요한 것이 아니라, 어떠한… | Z19: [자동채점] | 근거충분성: 충분 | 근거: [이사회/산하위원회의 ESG 안건 다루는 수준, 가중치0.50] [지배구조보고서] 31p. 내부회계관리제도 운영실태 보고의 건 ② 내부회계관리제도 운영실태 평가보고의 건(4번째 줄) → 이사회 안건 중 내부회계관리제도 운영실태 및 평가보고와 같은 ESG 관련 내부통제 및 감사 관련 사항이 심의/의결 안건으로 포함되어 있습니다. (100점) / [운영규정 상 ESG 명시 수준, 가중치0.50] [지배구조보고서] 19p. 당사는 이사회 내 ESG 위원회를 설치하고 있지 않습니다.(9번째 줄) → 제시된 근거 자료 내에서 운영규정이나 정관 등에 ESG 관련 사항을 명시하고 있다는 내용을 확인할 수 없으며, 오히려 ESG 위원회 미설치 사실만 명시되어 있습니다. (0점) | 근거페이지: 지배구조보고서 15p, 17~19p, 21~22p, 30~31p, 33~36p, 41p | [AI검토필요] 복합가중형(정밀계산) - 표본검증 권장 | AA19: 부분 / 영역 1 = 3단계, 영역 2 = 근거 부족 / 1단계 / 50점 [최종판단] 근거충분성: 부분 / 영역1 3단계, 영역2 근거부족→보수적 1단계 / 50점. [판단근거] 2025년 이사회가 안전보건경영 계획을 승인한 명확한 ESG 의결 증거가 있으나, 이사회/위원회 운영규정에 ESG 및 중요 ESG 이슈가 명시됐다는 증거가 없음. 기준표는 ① 최근 1년 이사회·위원회의 ESG 안건 처리 수준과 ② 운영규정의 ESG 명시 수준을 각각 50% 평가한다. 2025년에는 ESG의 S영역에 해당하는 안전보건 안건이 실제 승인되어 영역1은 3단계가 가능하다. 그러나 이사회·위원회 운영규정에 ESG 또는 중요 ESG 이슈를 명시한 근거는 사업보고서에서 확인되지 않는다. [확인근거] 007340_2026_business.pdf, PDF p.287 / DART p.283, VI.1.2 주요 의결사항: “2025년 안전보건경영 계획 승인의 건”, 결과 “가결”, 이사 전원 찬성. PDF p.14 / DART p.10, I.5 정관 변경이력에는 “위원회 설치에 관한 조항 신설 / 이사회내 위원회 설치를 위한 기준 마련”까지만 확인된다. [감점사유] 정관상 위원회 설치 가능성은 운영규정상 ESG 감독책임 명시와 동일하지 않다. 영역2를 상향시킬 직접 증빙이 없다.[보완 필요 증빙] 이사회규정 또는 ESG위원회 운영규정, ESG 감독책임 조항, 기후·안전·인권·공급망 등 중요 ESG 안건 목록, 연간 ESG 이사회 안건계획 | AB19: 즉시 | AC19: [현재 문제점] ESG 안건의 실제 의결은 있으나 이사회의 ESG 감독권한이 규정으로 연결되지 않음. [개선방향] 이사회/위원회 규정에 ESG 감독권한과 중요 ESG 이슈를 문장화하고 정례 안건, 의사록 증빙체계 구축, 이사회/위원회 규정에 ESG 감독범위와 정례 보고·심의 대상을 명시하고 연간 캘린더화. [필요 근거] 개정 이사회규정, ESG위원회규정, 연간 안건계획, 의사록·이사회 자료. | AD19: 이사회 또는 산하 위원회 운영규정에 ESG 관련 권한과 역할이 명시되어 있으며, 실제 활동 내역을 통해 ESG 안건을 보고·심의·의결하며 관리·감독하고 있습니까? | AE19: 단계(1~3)/복합가중형
A20: 19 | B20: G-1-2 | C20: 기본진단항목(v2.0) | D20: 지배구조 | E20: 이사회 구성 | F20: 사외이사 비율 | G20: 조직이 사외이사 제도를 통해 경영진 및 지배주주에 대한 견제, 기업경영 투명성의 제고, 소수주주의 권리보호 등의 목적을 달성하고 있는지 확인 | 경영진의 의사결정 행위를 견제할 수 있으며, 독립적인 시각에서 기업 발전에 관한 제언을 할 수 있는 사외이사 비율이 충분한지 점검 | H20: 이사회 구성현황, 전자공시시스템 [사업보고서-이사회에 관한 사항] | I20: 지난 1개 회계연도 기준 | J20: N/A | K20: N/A | L20: 단계형 | M20: 5 | N20: 단계형: 1단계=0점 / 2단계=25점 / 3단계=50점 / 4단계=75점 / 5단계=100점 | O20: 1단계 | 총원의 과반수로 구성되었으나, 사외이사가 3인인 경우 | 2단계 | 3인 이상, 이사 총원의 과반수를 차지하고 있으나, 전체 이사 중 60% 미만인 경우 | 3단계 | 3인 이상, 이사 총원의 과반수를 차지, 전체 이사 중 60% 이상 ~ 70% 미만인 경우 | 4단계 | 3인 이상, 이사 총원의 과반수를 차지, 전체 이사 중 70% 이상 ~ 80% 미만인 경우 | 5단계 | 3인 이상, 이사 총원의 과반수를 차지, 전체 이사 중 80% 이상인 경우 | P20: 부분대응 | Q20: KSSB 제1호 문단 27(1) 취지상 이사회 역량 요구와 연관 | R20: 지배구조보고서 가이드라인, GRI 2-9 | S20: 1_2_0_업종별 K-ESG 가이드라인(v2.0) 진단항목 | T20: 1 | X20: =IF(T20="","",SUMPRODUCT(('02_점수산정참고표'!$A$2:$A$314=$B20)*('02_점수산정참고표'!$C$2:$C$314=T20)*'02_점수산정참고표'!$E$2:$E$314)) -> 0 | Y20: 이사회가 조직의 경영활동에 대한 감독과 견제의 기능을 효과적으로 수행하며, 경영진이 합리적이고 객관적인 의사결정을 내릴 수 있도록 제언하기 위해서는 사외이사의 독립성이 확보되어야 한다. 사외이사의 독립성 요건(또는 사외이사 결격사유)은 ｢상법｣ 제382조 및 제542조, 금융회사의 지배구조에 관한 법률｣ 제12조를 통해 확인할 수 있다. 사외이사가 경영진의 의사결정에 중요한 영향력을 행사하거나, 이사회 의결사항에 상당한 의사결정권한을 갖추기 위해서는 충분한 수의 사외이사가 확보되어야 한다. 따라서 사외이사 비율은 이사회가 경영진 등을 충분히 견제할 수 있는 수준에서 결정되어야 한다. ｢상법｣ 및 ｢금융회사의 지배구조에 관한 법률｣에서 제시하는 사외이사 비율… | Z20: [자동채점] | 근거충분성: 충분 | 근거: [지배구조보고서] 4p. 2025년 5월 현재 총 5명의 이사 중 3명의 사내이사와 2명의 사외이사로 구성되어(2번째 줄) → 사외이사 수가 3인 미만(2인)으로, 단계별 상세 판단기준의 3인 이상 요건을 충족하지 못하여 1단계에 해당함. | 근거페이지: 사업보고서 271~272p / 지배구조보고서 4p, 20~21p, 25~30p, 38p | AA20: 충분 / 1단계 / 0점 대표이사와 이사회 의장 동일 [판단근거] 기준표의 상위 구간은 기본적으로 사외이사 3인 이상·과반을 전제로 한다. DN오토모티브는 전체 5인 중 사외이사 2인으로 40%이므로 최저 명시요건에도 미달한다. [확인근거] 사업보고서 PDF p.287 / DART p.283, VI.1.1: “3인의 상근이사, 2인의 사외이사 등 총 5인의 이사”. 즉 2/5=40%. [감점사유] 사외이사 수가 3인 미만이고 과반에 미달.<br><br>[보완 필요 증빙] 향후 이사회 구성계획, 사외이사 후보군·추천기준, 주총 선임결의 및 변경 후 이사회 구성표. | AB20: 즉시 | AC20: [현재 문제점] 사외이사 2/5, 40%로 독립적 견제 비중이 낮음. [개선방향] 우선 3/5 이상으로 확대하고 이후 이사회 개편 시 독립이사 비율을 지속 상향. 3/5 달성 시 최소 60% 구간, 장기적으로 80% 이상, 독립 사외이사 의장으로 분리. 전환 전까지 선임사외이사 제도를 브리지로 도입 [필요 근거] 이사회 구성 로드맵, 후보추천 기준, 주총 의안·선임결과, 독립성 확인서. | AD20: 경영진 견제를 위해 기업 발전에 관한 제언을 할 수 있는 사외이사의 비율이 충분합니까? | AE20: 단계(1~5)
A21: 20 | B21: G-1-3 | C21: 기본진단항목(v2.0) | D21: 지배구조 | E21: 이사회 구성 | F21: 대표이사와 이사회 의장 분리 | G21: 경영진의 경영활동을 감독하고 견제하는 이사회의 역할을 제대로 수행하기 위한 독립성 확보 여부를 확인 | 이사회의 의장과 경영진의 대표인 대표이사와의 분리 여부 및 선임사외이사 임명 등을 점검 | H21: 이사회 구성 현황, 전자공시시스템[사업보고서-이사회에 관한 사항] | I21: 지난 1개 회계연도 기준 | J21: N/A | K21: N/A | L21: 단계형 | M21: 5 | N21: 단계형: 1단계=0점 / 2단계=25점 / 3단계=50점 / 4단계=75점 / 5단계=100점 | O21: 1단계 | 현재 대표이사와 이사회 의장이 동일한 경우 | 2단계 | 과거 대표이사 또는 이사회 의장을 역임했던 자가 현재 이사회 의장인 경우 | 3단계 | 현재 이사회 의장이 과거 또는 현재의 대표이사나 이사회 의장을 역임하지 않았으나, 모회사 또는 자회사의 임원 등 독립성이 결여된 자가 이사회 의장인 경우 | 4단계 | 과거 또는 현재 대표이사이거나, 이사회 의장을 역임하였거나, 독립성이 결여된 자가 현재 이사회 의장인 경우. 단, 이사회 의장과 이해관계 상충하는 안건 등에 있어, 이사회 의장 역할을 대신하는 ‘선임사외이사’를 임명하고 있는 경우 | 5단계 | 과거 또는 현재 대표이사이거나, 이사회 의장을 역임한 적이 없으며, 회사로부터 독립성이 확보된 이사가 현재 이사회의 의장인 경우 | P21: GAP(대응지표 없음) | Q21: KSSB 별도 규정 없음 | R21: 지배구조보고서 가이드라인 | S21: 1_2_0_업종별 K-ESG 가이드라인(v2.0) 진단항목 | T21: 1 | X21: =IF(T21="","",SUMPRODUCT(('02_점수산정참고표'!$A$2:$A$314=$B21)*('02_점수산정참고표'!$C$2:$C$314=T21)*'02_점수산정참고표'!$E$2:$E$314)) -> 0 | Y21: 경영진을 대표하는 대표이사와 이사회를 대표하는 이사회 의장이 동일하다면 경영진의 경영활동을 감독하고 견제하는 이사회의 역할을 제대로 수행할 수 없다. 다만, 대표이사와 이사회 의장이 분리되지 않은 경우에도 독립성을 갖춘 선임사외이사를 두어 이사회의 기능과 역할을 주도적으로 수행하도록 할 수 있다. 선임사외이사는 이사회(대표이사 또는 특수관계인이 이사회 의장으로 선임된)에서 대표이사의 이해와 관계된 의사결정 사안에 대해 이사회 의장을 대리하며, 사외이사들의 의견을 대표로 사내이사 및 경영진에게 전달하는 역할을 수행한다. 국내외 법/규제, ESG 평가기관 등은 대표이사의 이사회 의장 분리 및 선임사외이사 임명 관련 사항을 아래와 같이 명시하고 있으므로, 해당 지표… | Z21: [자동채점] | 근거충분성: 충분 | 근거: [지배구조보고서] 20p. 당사는 정관에서 대표이사를 이사회의장으로 지정하고 있습니다.(7번째 줄) → 대표이사가 이사회 의장을 겸직하고 있으며, 선임사외이사 제도 또한 운영하고 있지 않아 1단계에 해당함. | 근거페이지: 사업보고서 270~271p / 지배구조보고서 4p, 15p, 18~22p, 25~26p, 30p | AA21: [확인필요] 충분 / 1단계 / 0점 26년 최근 기준으로 한 번 더 확인 필요, 사외이사 2/5=40%, 최소구간 미달 [판단근거] 기준표 1단계는 현 대표이사와 이사회 의장이 동일한 경우다. 회사가 정확히 이에 해당한다. [확인근거] 사업보고서 PDF p.287 / DART p.283, VI.1.1: “김상헌 대표이사를 의장으로 선임하였습니다.” 같은 페이지에서 김상헌은 대표이사임이 확인된다. [감점사유] 대표이사와 의장이 동일하고, 기준표 4단계를 가능하게 하는 선임사외이사 운영 근거도 두 문서에서 확인되지 않는다. [보완 필요 증빙] 독립 이사회 의장 선임결의 또는 선임사외이사 규정·선임결의·권한규정. | AB21: 즉시 | AC21: [현재 문제점] 대표이사가 이사회 의장을 겸해 감독주체와 피감독 경영진 간 역할분리가 약함. [개선방향] - 사외이사 최소 3/5=60%, 장기적으로 4/5=80%를 계획에 반영 - 독립 사외이사 의장 체계로 전환하고, 과도기에는 선임사외이사 제도를 운영. [필요 근거] 이사회규정, 선임사외이사 직무규정, 이사회 선임결의, 이해상충 안건 운영기록 | AD21: 경영진 감독 및 견제를 위한 이사회 독립성을 확보하기 위해 이사회 의장과 대표이사를 분리하거나, 선임사외이사를 임명하여 운영하고 있습니까? | AE21: 단계(1~5)
A22: 21 | B22: G-1-4 | C22: 기본진단항목(v2.0) | D22: 지배구조 | E22: 이사회 구성 | F22: 이사회 성별 다양성 | G22: 이사회가 다양한 이해관계자들의 요구사항을 두루 고려하여 폭넓은 시각과 경험을 바탕으로 중요한 의사결정에 임할 수 있도록 이사회 구성원이 다양한 배경을 가지고 있는지 확인 | 다양성과 포용성의 대표적인 분류인 남성 대비 여성 비율(혹은 여성 대비 남성 비율)을 점검 | H22: 이사회 구성 현황, 전자공시시스템[사업보고서-이사회에 관한 사항] | I22: 지난 1개 회계연도 기준 | J22: N/A | K22: 이사회 여성 비율 = (여성 이사 수 / 전체 이사회 구성원 수) | L22: 단계형 | M22: 5 | N22: 단계형: 1단계=0점 / 2단계=25점 / 3단계=50점 / 4단계=75점 / 5단계=100점 | O22: 1단계 | 이사회 내 여성 이사가 선임되어 있지 않는 경우 | 2단계 | 이사회 내 여성 이사가 1명만 선임되어 있는 경우 | 3단계 | 이사회 내 여성 이사가 2명 이상이며, 그 비율이 10% 이상 ~ 20% 미만인 경우 | 4단계 | 이사회 내 여성 이사가 2명 이상이며, 그 비율이 20% 이상 ~ 30% 미만인 경우 | 5단계 | 이사회 내 여성 이사가 2명 이상이며, 그 비율이 30% 이상인 경우 | * 이사회 내 다수 성(性)이 여성일 경우에는 반대로 적용 | P22: 부분대응 | Q22: KSSB 제1호 문단 27(1) 이사회 역량·다양성 취지 준용 | R22: GRI 405-1 | S22: 1_2_0_업종별 K-ESG 가이드라인(v2.0) 진단항목 | T22: 1 | X22: =IF(T22="","",SUMPRODUCT(('02_점수산정참고표'!$A$2:$A$314=$B22)*('02_점수산정참고표'!$C$2:$C$314=T22)*'02_점수산정참고표'!$E$2:$E$314)) -> 0 | Y22: 조직이 대내외 환경 변화에 유연하게 대처하고 장기적인 지속가능성을 확보하기 위해서는 다양한 시각과 관점에서 당면한 문제를 바라보고 해결할 수 있는 다양한 배경과 경험을 가진 이사를 선임해야 할 필요가 있다. 본 지표는 이러한 다양성을 확인할 수 있는 대표적 기준 중 하나인 성(性) 비율을 통해 이사회 내 성별 다양성을 점검하도록 요구하고 있다. 이사회를 구성하는 이사가 특정 성(性)에 치우치지 않는다는 것은 성별에서 기인하는 특정한 관점, 이해관계 등에서 벗어난 다양한 의견이 이사회의 의사결정에 반영될 수 있다는 것을 의미한다. 특히, 국내의 경우 독립적이고 다양한 전문성을 가지는 사외이사를 선임하는 등의 노력은 지속되고 있으나 이사회의 성별 다양성은 부족한… | Z22: [자동채점] | 근거충분성: 충분 | 근거: [지배구조보고서] 21p. 다만, 이사회 전원 같은 성별로서 다양성을 확보함에 있어 미비한 부분이 존재하기 때문에(5번째 줄) → 이사회 구성원 전원이 동일한 성별로 구성되어 있어 여성 이사가 선임되어 있지 않으므로 1단계에 해당합니다. | 근거페이지: 사업보고서 270p / 지배구조보고서 3~4p, 15p, 18p, 20~22p, 26p, 30p, 32p | AA22: [확인필요] 충분 / 1단계 / 0점 2025년 여성 이사 0명, 26년 현재 있음 [판단근거] 기준표 1단계는 여성 이사가 없는 경우이다. 2025년 말 기준 등기이사 5명의 성별이 모두 남성으로 공시된다. [확인근거] 사업보고서 PDF p.296 / DART p.292, VIII.1 임원 현황에서 김상헌·김인환·박길준·송호근·이기영의 성별이 모두 “남”으로 표시. [감점사유] 여성 이사 0명. [보완 필요 증빙] 다양성 정책, 이사 후보 다양성 기준, 여성 후보군 관리자료, 실제 주총 선임결과. | AB22: 즉시 | AC22: [현재 문제점] 2025년 이사회가 단일 성별로 구성되어 있음. [개선방향] - 여성 비율 30%이상 - 여성 이사를 단순 1명이 아닌 최소 2명으로 확대 - 차기 선임에서 여성 이사를 최소 2명까지 단계적으로 확대해 기준표의 상위구간 진입을 목표화. [필요 근거] 이사회 다양성 정책, 후보군·선정기준, 주총 의안 및 선임 후 구성표 | AD22: 이사회의 다양성과 포용성을 확보하고 폭넓은 시각의 의사결정을 도모하기 위해 전체 대비 여성 이사 비율을 충분히 확보하여 운영하고 있습니까? | AE22: 단계(1~5)
A23: 22 | B23: G-1-5 | C23: 기본진단항목(v2.0) | D23: 지배구조 | E23: 이사회 구성 | F23: 사외이사 전문성 | G23: 사내이사와 사외이사의 정보 비대칭이 존재하는 상황에서 사외이사가 조직의 중장기 발전에 관한 충분한 의견을 제공하거나, 경영진의 의사결정을 견제할 수 있는 전문성을 갖추고 있는지 확인 | 사외이사가 조직의 사업 방향에 대해 전문적인 의견을 제시할 수 있는지 점검 (사외이사가 동종산업의 업무경력을 보유하고 있는지 확인) | H23: 사외이사 경력사항 | I23: 직전 회계연도 | J23: N/A | K23: N/A | L23: 단계형 | M23: 3 | N23: 단계형: 1단계=0점 / 2단계=50점 / 3단계=100점 | O23: 1단계 | 동종산업 경력을 보유한 사외이사가 없는 경우 | 2단계 | 동종산업 경력을 보유한 사외이사가 1명 이상인 경우 | 3단계 | 동종산업 경력을 보유한 사외이사가 50% 이상인 경우 | P23: 완전대응 | Q23: KSSB 제1호 문단 27(1)ㄏ — 이사회 전문성 판단·개발계획 | R23: 지배구조보고서 가이드라인, KCGS | S23: 1_2_0_업종별 K-ESG 가이드라인(v2.0) 진단항목 | T23: 1 | X23: =IF(T23="","",SUMPRODUCT(('02_점수산정참고표'!$A$2:$A$314=$B23)*('02_점수산정참고표'!$C$2:$C$314=T23)*'02_점수산정참고표'!$E$2:$E$314)) -> 0 | Y23: 전문성 있는 사외이사란 사내이사(경영진 등)의 경영의사결정에 대한 제언과 감독 기능을 충실히 이행할 수 있도록 해당 산업 전문지식과 경력을 보유하고 있는 자를 말하다. 이때, 해당 산업 전문지식과 경력이란 한국표준산업분류의 대분류(2자리 코드) 기준 동종산업에서 실무자 또는 경영진으로써 재직하였거나, 관련 연구기관 및 서비스기관에서 종사한 경험이 있는 것을 의미하며, 대학을 포함한 고등교육기관 및 학술기관 경력은 제외한다. 글로벌 ESG 평가기관은 ‘산업 전문성을 갖춘 사외이사 비율’을 평가지표로 운용하고 있으며, 조직은 사외이사 선임 시 평가기관 등이 제시하는 ‘산업 전문성’ 요건을 참고할 수 있다. - (S&P Global) 국제산업분류표준(GICS)… | Z23: [자동채점] | 근거충분성: 불충분 | 근거: [지배구조보고서] 25p. 당사의 사외이사는 상법 및 관계법령에서 요구하는 기본적인 법적 요건을 갖추고 있고, 실무 경험과 전문성을 두루 갖춘 전문가로 구성되어 있습니다.(3번째 줄) → 제공된 근거 자료 내에 사외이사들의 구체적인 경력이나 동종산업(반도체/전자) 종사 여부에 대한 정보가 명시되어 있지 않아 1단계로 판단함. | 근거페이지: 사업보고서 271~272p / 지배구조보고서 18p, 20~22p, 25~29p | AA23: [확인필요] 부분 / 1단계 / 0점 동아타이어 사외이사 경력의 동종산업 업무경력 인정 여부 불명확 [판단근거] 기준표는 동종산업에서의 실무자·경영진 재직 등 업무경력을 요구하며, 1명 이상이면 2단계, 사외이사의 50% 이상이면 3단계다. 이기영 사외이사는 동아타이어공업 사외이사 경력이 있으나 이것을 기준표상의 “동종산업 실무·경영경력”으로 인정할지는 불명확하다. 송호근 사외이사는 학계·사회정책 경력이다. [확인근거] PDF p.288 / DART p.284: 이기영에 대해 “금융감독원 회계조사국장 및 동아타이어공업주식회사 사외이사를 역임”. PDF p.289 / DART p.285: 송호근에 대해 서울대학교 교수·정책자문 경력을 기재. [감점사유] 이기영의 타이어업계 사외이사 경력은 확인되나, 직접적인 산업 실무·경영경력인지 명확하지 않다. 이를 인정하면 2명 중 1명=50%로 3단계가 될 수 있어 점수 민감도가 매우 큰 항목이다. [보완 필요 증빙] 사외이사 상세 경력기술서, KSIC 기준 동종산업 경력 매핑표, 직무·재직형태·경력기간 확인자료. | AB23: 중기 | AC23: [현재 문제점] 현 공시는 전문성을 설명하지만 기준표가 요구하는 ‘동종산업 업무경력’을 명확히 입증하지 못함. [개선방향] 자동차부품·타이어·배터리 등 직접 산업 실무/경영 경험자를 사외이사 후보 기준에 반영. 평가 정의를 먼저 고정한 뒤, 논란 없는 직접 산업 실무·경영경력 보유 사외이사 비율 50% 이상으로 구성 [필요 근거] 경력증명, 상세 CV, 산업분류 매핑표, 후보추천 검토서 | AD23: 동종산업(반도체/전자)에서 경력을 보유한 사외이사가 포함되어 있습니까? | AE23: 단계(1~3)
A24: 23 | B24: G-2-1 | C24: 기본진단항목(v2.0) | D24: 지배구조 | E24: 이사회 활동 | F24: 전체 이사 출석률 | G24: 조직의 최고의사결정기구인 이사회가 검토/심의/의결 기능을 효과적으로 수행하기 위해서는 이사회 구성원의 적극적인 참여가 중요함. 이사회 구성원이 이사회에 참여하여 조직의 성장 및 발전에 관한 제언, 주요안건에 대한 의사결정 행위를 하고 있는지 확인 | 이사회 구성원별 출석률을 평균하여, 전체 이사 출석률이 일정 수준 이상인지 점검 | H24: 이사회 구성 현황, 이사회 회의록 등 | I24: 직전 회계연도 | J24: N/A | K24: 이사회 구성원 평균 출석률 = ∑(출석한 전체 이사 인원 수 / 전체 이사 정원) / 이사회 개최 횟수 | L24: 단계형 | M24: 5 | N24: 단계형: 1단계=0점 / 2단계=25점 / 3단계=50점 / 4단계=75점 / 5단계=100점 | O24: 1단계 | 이사회 구성원 평균 출석률이 75% 미만인 경우 | 2단계 | 이사회 구성원 평균 출석률이 75% 이상 85% 미만인 경우 | 3단계 | 이사회 구성원 평균 출석률이 85% 이상 90% 미만인 경우 | 4단계 | 이사회 구성원 평균 출석률이 90% 이상 95% 미만인 경우 | 5단계 | 이사회 구성원 평균 출석률이 95% 이상인 경우 | P24: 부분대응 | Q24: KSSB 제1호 문단 27(1)ㄒ — 보고주기 준용 | R24: GRI 2-9 | S24: 1_2_0_업종별 K-ESG 가이드라인(v2.0) 진단항목 | T24: 5 | X24: =IF(T24="","",SUMPRODUCT(('02_점수산정참고표'!$A$2:$A$314=$B24)*('02_점수산정참고표'!$C$2:$C$314=T24)*'02_점수산정참고표'!$E$2:$E$314)) -> 100 | Y24: ｢상법｣에서는 이사의 이사회 출석의무를 규정하고 있지 않으나, 이사 출석률은 이사가 수행해야 할 역할을 충실히 하고 있는지를 대변하는 중요한 지표가 된다. 특히 ｢상법｣ 제393조 제4항은 “이사는 3월에 1회 이상 업무의 진행사항을 이사회에 보고하여야 한다”라고 규정하고 있으며, 이를 해석하면 업무 진행사항을 보고하는 ‘사내이사’와 보고받는 ‘사외이사’가 1년 동안 최소 4회는 이사회에 참여하여야 한다는 것이다. 이사회 참여는 법/규제를 벗어나지 않는 범위에서 선관주의에 따른 이사회 구성원의 자율사항이다. 따라서 개별 이사에 대해 이사회 참여를 강제할 수 없으나, 이사회 구성원의 참여가 저조하거나 소극적인 경우, 이를 강제하기 위한 방식에는 다음과 같은… | Z24: [자동채점] | 근거충분성: 충분 | 근거: ⚠️[출처 미확정, 검색 1위 후보로 대체] [지배구조보고서] 32p. 이사 평균 출석률 (%) | 정기 100 | 임시 100(줄 위치 특정 실패) → 제시된 근거에서 이사 평균 출석률이 100%로 확인되어 95% 이상인 5단계 요건을 충족함. | 근거페이지: 사업보고서 270p / 지배구조보고서 5p, 22p, 28p, 30p, 32~33p, 35~36p, 41p | AA24: 충분 / 5단계 / 100점 [판단근거] 95% 이상이 5단계이며 5명 모두 100%. [확인근거] 사업보고서 DART p.283 이사 5명 각각 “출석률:100%”. [감점사유] 없음. [보완] 참석대장·연간 산출표. | AB24: 장기 | AC24: 현재 상태 유지관리 필요 [현재 문제점] 정량 출석률은 우수하지만 이사의 실질적 기여 수준은 출석률만으로 설명되지 않음 [개선방향] 참석률과 함께 사전자료 제공·질의·의견반영 실적을 관리. [필요 근거] 회의별 참석대장, 사전자료 발송기록, 질의응답·의견반영 자료. | AD24: 이사회 전체 이사 평균 출석률이 75% 수준 이상입니까? | AE24: 단계(1~5)
