Workbook

Sheet 00_사용안내
B2: ESG 핵심지표 채점 기준표
B3: K-ESG 가이드라인 v2.0 기반 통합 채점 도구
B5: 1. 목적
B6: 기업의 ESG 현황을 공식 가이드라인 기준으로 정량 진단·채점하고, KSSB 공시기준 대비 GAP을 분석하는 컨설팅용 도구입니다.
B8: 2. 적용 기준 (공식 출처)
B9: · 기본 69 + 추가 16개(85개) 배점: K-ESG 가이드라인 v2.0 (산업통상자원부·한국생산성본부, 2024.12)
B10: · 반도체 특화 6개: 업종별 K-ESG 가이드라인(반도체, 2023.12) — v2.0 기본체계에 보완지표로 적용
B11: · 지배구조 세부지표(129개, 03번 시트): 한국거래소 기업지배구조보고서 가이드라인(2025.2 개정본)
B12: · 공시 GAP 분석(04번 시트): KSSB(한국회계기준원 산하) 지속가능성 공시기준서 제1호·제2호(2026.2.26 최종 제정)
B14: 3. 점수 체계
B15: · 채점 유형 구성: 단계형·선택형 74개 / 복합가중형 11개 / 감점형 6개 (총 91개)
B16: · 단계형/선택형: 단계 수에 따라 0~100점 균등 배분 (원문 그대로)
... B33: 문서 구성: 00_사용안내 · 01_ESG통합진단마스터 · 02_점수산정참고표 · 03_지배구조세부점검(KRX) · 04_KSSB갭분석 · 05_요약대시보드

Sheet 01_ESG통합진단마스터
A1: No | B1: 분류코드 | C1: 적용구분 | D1: 영역 | E1: 범주 | F1: 진단항목명 | G1: 항목설명 | H1: 데이터원천(수집처) | I1: 데이터기간 | J1: 데이터범위 | K1: 데이터산식(정량화공식) | L1: 채점유형 | M1: 최대단계수 | N1: 배점구조 요약 | O1: 점검기준 상세(K-ESG v2.0 원문) | P1: KSSB 대응현황 | Q1: KSSB 참고근거 | R1: 기타 참고기준(GRI/SASB/TCFD/KCGS 등) | S1: 원본 출처파일 | T1: [입력]충족단계/요건수 | U1: [입력]위반유형1 | V1: [입력]위반유형2 | W1: [입력]위반유형3 | X1: 자사취득점수(0~100) | Y1: 개선 가이드 | Z1: 비고 | AA1: 실사 진단 질문 | AB1: 답변형식
A2: 1 | B2: P-1-1 | C2: 기본진단항목(v2.0) | D2: 정보공시 | E2: 정보공시 형식 | F2: ESG 정보공시 방식 | G2:  조직이 ESG 정보공시 동향에 맞추어 정보 수요자의 접근성을 고려한 ESG 정보공시 방식을 정립하고 있는지 점검  ESG 정보를 종합한 온/오프라인 채널 운영 및 ESG 정보공시 외부 확산/전파 등 정보 접근성 향상 측면의 노력을 확인 | H2: 홈페이지, 지속가능경영보고서, 사업보고서, 기타간행물, 전자공시시스템 上 ‘자율공시’ | I2: 직전 회계연도 | J2: N/A | K2: N/A | L2: 단계형 | M2: 5 | N2: 단계형: 1단계=0점 / 2단계=25점 / 3단계=50점 / 4단계=75점 / 5단계=100점 | O2: 1단계 | 조직이 어떠한 방식으로든 ESG 정보를 공시하지 않는 경우 | 2단계 | 조직의 홈페이지, 지속가능경영보고서, 사업보고서, 기타 간행물 등에 ESG 정보를 분산하여 공시하고 있는 경우 | 3단계 | 조직의 홈페이지, 지속가능경영보고서, 사업보고서, 기타 간행물 등에 ESG 정보를 통합하여 공시하고 있는 경우 | 4단계 | ESG 정보를 통합한 조직의 홈페이지, 지속가능경영보고서, 사업보고서, 기타 간행물 등을 지정된 장소에 비치하거나, | 특정 URL에 담고 있는 경우 | 5단계 | ESG 정보를 통합한 조직의 홈페이지, 지속가능경영보고서, 사업보고서, 기타 간행물 등의 발행여부를 ‘전자공시시스템-자율공시’ | 사항으로 알리는 경우 | P2: 부분대응 | Q2: KSSB 제1호 문단 64~70(보고시기·장소), 21~24(연계된 정보) | R2: GRI 2-3 | S2: 1_2_0_업종별 K-ESG 가이드라인(v2.0) 진단항목 | X2: =IF(T2="","",MAX(1,SUMPRODUCT(('02_점수산정참고표'!$A$2:$A$314=$B2)*('02_점수산정참고표'!$C$2:$C$314=T2)*'02_점수산정참고표'!$E$2:$E$314))) | Y2:  ESG 정보공시란 투자자를 비롯한 다양한 이해관계자의 의사결정 및 가치판단에 영향을 미칠 수 있는 환경, 사회, 지배구조와 관련된 정보를 공개적으로 널리 알리는 행위를 의미한다. 조직은 정기적으로 특정한 정보공시 창구(홈페이지, 사업보고서, 지속가능경영보고서, 기타 간행물 등)에 ESG 관련 정보를 종합적으로 수록하고 있으며, 해당 정보공시 창구를 통해 이해관계자 누구나 ESG 정보를 접근/열람할 수 있고, 정보공시 여부를 대내외에 알리는 행위를 한 경우 ESG 정보공시를 하였다고 정의한다.  ESG 정보란 중대성 평가(Materiality Test) 결과에 따른 핵심이슈, 또는 조직의 사업운영 과정에서 지속적 관리가 필요한 ESG 이슈별로 ‘전략’, ‘조직’,… | AA2: 정보 수요자의 접근성을 고려하여 홈페이지, 지속가능경영보고서 등을 통해 ESG 정보를 통합 공시하고 있습니까? | AB2: 단계(1~5)
A3: 2 | B3: P-1-2 | C3: 기본진단항목(v2.0) | D3: 정보공시 | E3: 정보공시 형식 | F3: ESG 정보공시 주기 | G3:  투자자, 고객 등 정보 수요자의 의사결정 및 가치판단에 필요한 최신 ESG 정보를 적시에 제공하고 있는지 점검  조직의 ESG 데이터 취합/분석/마감 기간을 고려하여 1년 단위로 ESG 정보공시 주기를 설정하고 있는지 확인 | H3: ESG 정보공시 일자, 지속가능경영보고서 발간 주기 | I3: 최근 4개년 회계연도 * 3개년 이하 데이터 보유 시 해당 데이터로 추세 산정 | J3: N/A | K3: N/A | L3: 단계형 | M3: 3 | N3: 단계형: 1단계=0점 / 2단계=50점 / 3단계=100점 | O3: 1단계 | ESG 정보공시 주기를 특정할 수 없거나, 명시하고 있지 않는 경우 | 2단계 | 2년 단위로 보고서 발간 및 ESG 정보를 공시하는 경우 | 3단계 | 1년 단위로 보고서 발간 및 ESG 정보를 공시하는 경우 | P3: 부분대응 | Q3: KSSB 제1호 문단 60~63(보고빈도) | R3: GRI 2-3 | S3: 1_2_0_업종별 K-ESG 가이드라인(v2.0) 진단항목 | X3: =IF(T3="","",MAX(1,SUMPRODUCT(('02_점수산정참고표'!$A$2:$A$314=$B3)*('02_점수산정참고표'!$C$2:$C$314=T3)*'02_점수산정참고표'!$E$2:$E$314))) | Y3:  ESG 정보 수요자가 조직의 ESG 정보를 효과적으로 활용하기 위해서는, 조직이 ESG 정보를 주기적으로 공시하는 것이 중요하다. ESG 정보가 적시성을 확보하기 위해서는 ESG 정보공시 주기를 재무정보 공시주기와 동일하게 하거나, 재무정보 공시 이후 최대한 빠른 시기에 ESG 정보를 공시할 필요가 있다. 또한, ESG 정보 수요자에 상당한 영향력을 미칠 수 있는 정보는 이를 확인한 즉시 대외공시할 것을 권장한다.  조직은 ESG 정보공시 주기를 자율적으로 정할 수 있다. 일부 조직은 주요한 ESG 성과가 창출되는 시점마다 공시하기도 하며, 어떠한 조직은 ESG 정보공시에 따른 업무/비용 부담을 고려하여 격년 주기로 공시하기도 한다. 반면 ESG 정보공시 규제 및… | AA3: 최신 ESG 정보를 적시에 제공하기 위해 1년 단위로 정기 공시합니까? | AB3: 단계(1~5)
A4: 3 | B4: P-1-3 | C4: 기본진단항목(v2.0) | D4: 정보공시 | E4: 정보공시 형식 | F4: ESG 정보공시 범위 | G4:  ESG 정보공시 제도화 움직임에 따라, 조직의 ESG 활동 및 성과를 충분히 대표하고 나타낼 수 있는 정보가 공시되고 있는지 점검  조직의 영향력과 통제력이 미치는 사업장(자회사 포함)의 ESG 정보가 최대한 공시되고 있는지 확인 | H4: 홈페이지, 지속가능경영보고서, 사업보고서, 전자공시시스템 上 ‘자율공시’ | I4: 직전 회계연도 | J4: 사업적 영향력 및 통제력을 행사하는 사업장 및 기타 연결실체 | K4: ESG 정보공시 범위 = ESG 정보공시에 포함된 사업장 등의 (매출액 등) / 전체 조직의 (매출액 등) | L4: 단계형 | M4: 5 | N4: 단계형: 1단계=0점 / 2단계=25점 / 3단계=50점 / 4단계=75점 / 5단계=100점 | O4: 1단계 | ESG 정보공시 범위를 특정할 수 없거나, 명시하고 있지 않는 경우 | 2단계 | 조직이 법적으로 직접 소유하고 있는 사업장(ex. 별도재무제표 기준)의 일부 또는 모든 ESG 정보를 공시하고 있는 경우 | 3단계 | 조직의 영향력과 통제력 범위에 있는 곳(자회사, 종속법인, 연결실체 등)의 일부 ESG 정보를 공시하고 있는 경우 | 4단계 | 조직의 영향력과 통제력 범위에 있는 곳(자회사, 종속법인, 연결실체 등)의 일부 ESG 정보를 공시하고 있는 경우. | 단, 조직의 영향력과 통제력 범위로 ESG 정보공시 범위를 확대한다는 계획을 제시하고 있는 경우 | 5단계 | 조직의 영향력과 통제력 범위에 있는 곳(자회사, 종속법인, 연결실체 등)의 모든 ESG 정보를 공시하고 있는 경우 | P4: 부분대응 | Q4: KSSB 제1호 문단 21~24(연계된 정보) | R4: GRI 2-2 | S4: 1_2_0_업종별 K-ESG 가이드라인(v2.0) 진단항목 | X4: =IF(T4="","",MAX(1,SUMPRODUCT(('02_점수산정참고표'!$A$2:$A$314=$B4)*('02_점수산정참고표'!$C$2:$C$314=T4)*'02_점수산정참고표'!$E$2:$E$314))) | Y4:  조직은 ESG 정보공시 전 어떠한 범위까지 성과관리를 할 것인지, 또는 성과관리가 가능한지 등 최대 범위를 설정해야 한다. ESG 개념을 조직의 재무적 정보를 기반으로 투자의사결정을 하는 자본시장에서 등장하였기 때문에, 장기적으로 ESG 성과관리 및 정보공시 최대범위는 ‘(연결)재무제표’에 포함되는 ‘재무정보’ 범위와 동일시하려는 논의가 진행될 것으로 예상된다. 따라서 조직은 아래의 ‘영향력’과 ‘통제력’이 행사되는 범위에서 발생하는 환경, 사회, 지배구조 관련 정보를 공시할 필요가 있다. (예를 들어, US GAAP, IFRS 회계지침에는 20% 이상 지분을 보유한 조직을 상당한 영향력이 행사되는 조직으로 간주한다.) 1) ESG 정보를 공시하는 조직이 직접적으로… | AA4: 조직 통제력이 미치는 종속/연결실체 등 최대 범위를 공시합니까? | AB4: 단계(1~5)
A5: 4 | B5: P-2-1 | C5: 기본진단항목(v2.0) | D5: 정보공시 | E5: 정보공시 내용 | F5: ESG 핵심이슈 및 KPI | G5:  조직의 사업성과 및 환경/사회에 상당한 영향력을 미치는 핵심이슈를 명확히 정의하고, 이를 관리하기 위한 시스템 및 절차를 갖추고 있는지 확인  조직이 인식하고 관리하고 있는 핵심 ESG 이슈에 대한 조직의 정보공시 수준을 점검 | H5: 홈페이지, 지속가능경영보고서, 사업보고서, 전자공시시스템 上 ‘자율공시’ | I5: 직전 회계연도 | J5: N/A | K5: N/A | L5: 단계형 | M5: 5 | N5: 단계형: 1단계=0점 / 2단계=25점 / 3단계=50점 / 4단계=75점 / 5단계=100점 | O5: 1단계 | 중대성 평가 결과 또는 ESG 핵심이슈를 공시하고 있지 않은 경우 | 2단계 | 중대성 평가 결과와 핵심이슈를 명확히 정의하고 있는 경우 | 3단계 | 2단계 + 핵심이슈에 대해 조직이 관리하고 있는 성과지표를 설명하고 있는 경우 | (예를 들어, 기후변화가 핵심이슈일 경우, 온실가스 배출량 데이터 제시) | 4단계 | 3단계 + 핵심이슈가 사업적/사회적 관점에서 중요한 사유를 설명하고 있는 경우 | (예를 들어, 사업적/사회적 관점의 기회 요인과 리스크 요인 등) | 5단계 | 4단계 + 핵심이슈를 관리하기 위한 시스템 및 절차를 설명하고 있는 경우 | (조직, 전략 및 계획, 고충처리체계, 활동 및 교육 등) | P5: 부분대응 | Q5: KSSB 제1호 문단 17~19(중요성 판단, 이중중대성 개념 미흡) | R5: GRI 3(중대성평가) | S5: 1_2_0_업종별 K-ESG 가이드라인(v2.0) 진단항목 | X5: =IF(T5="","",MAX(1,SUMPRODUCT(('02_점수산정참고표'!$A$2:$A$314=$B5)*('02_점수산정참고표'!$C$2:$C$314=T5)*'02_점수산정참고표'!$E$2:$E$314))) | Y5:  조직의 중요한 경제적, 환경적, 사회적 영향을 반영하는 측면 또는 이해관계자들의 평가와 의사결정에 실질적으로 영향을 미치는 측면을 모두 고려하여 보고서에서 다룰 가치가 있다고 판단되는 주제를 선정하는 과정을 거쳐야 한다. 이러한 이슈의 중대성을 판별하기 위한 방법으로는 일반적으로 ‘중대성 평가(Materiality Assessment)’ 또는 ‘이중 중대성 평가(Double Materiality Assessment)’가 있으며, 중대 측면을 정의하는 데 있어 조직이 참작해야 할 요인들은 다음과 같다. - 지속가능성에 영향, 위험, 기회 요소가 될 수 있는 항목(ex. 지구 온난화, 에이즈, 빈곤 등) 중 합리적 평가가 가능하고, 전문가나 해당 분야에 자격을 갖춘 전문… | AA5: 이중 중대성 평가 기반 핵심이슈, 위기/기회, KPI를 공시합니까? | AB5: 단계(1~5)
A6: 5 | B6: P-3-1 | C6: 기본진단항목(v2.0) | D6: 정보공시 | E6: 정보공시 검증 | F6: ESG 정보공시 검증 | G6:  조직의 ESG 정보를 직접적으로 또는 가공하여 활용하는 이해관계자가 증가함에 따라, 조직이 대외공시하는 ESG 정보가 타당성/신뢰성/투명성을 확보하고 있는지 확인  조직이 대외공시하는 정보에 관해 제3자 기관으로부터 검증을 받는 경우, 해당 검증의견이 갖추어야 할 형식적 요건을 점검 | H6: ESG 정보 검증의견서, 지속가능경영보고서 검증의견서 | I6: 직전 회계연도 | J6: N/A | K6: N/A | L6: 선택형 | M6: 5 | N6: 선택형: 요건1=0점 / 요건2=25점 / 요건3=50점 / 요건4=75점 / 요건5=100점 | O6: 요건1 | 검증의견서에 검증기관(또는 검증인)이 명시되어 있는 경우 | (또는, 검증기관이 License Number를 보유하고 있는 경우) | 요건2 | 검증의견서에 검증기관과의 독립성 성명이 포함되어 있는 경우 | (즉, 검증기관과 검증받는 조직간 이해관계 상충이 없음을 선언한 경우) | 요건3 | 검증의견서에 검증표준(방법론)이 제시되어 있는 경우 | (AA1000AS, ISAE3000, 또는 제3자 검증기관이 개발한 자체 검증표준 등) | 요건4 | 검증의견서에 ESG 정보 검증수준을 공개하고 있는 경우 | (Type1/Type2, Moderate/High, 제한적/합리적 등) | 요건5 | 검증의견서에 제3자 검증기관이 검증한 정보공시 지표가 적시되어 있는 경우 | (즉, 조직의 모든 ESG 정보 중 어떠한 정보를 검증하였는지 명시하는 경우) | P6: 완전대응 | Q6: KSSB 제1호 문단 50(3)(외부검증) | R6: GRI 2-5, AA1000AS, ISAE3000 | S6: 1_2_0_업종별 K-ESG 가이드라인(v2.0) 진단항목 | X6: =IF(T6="","",MAX(1,SUMPRODUCT(('02_점수산정참고표'!$A$2:$A$314=$B6)*('02_점수산정참고표'!$C$2:$C$314=T6)*'02_점수산정참고표'!$E$2:$E$314))) | Y6:  조직은 지속가능경영보고서 발간 등 ESG 정보공시 지표 및 기준을 자율적으로 선택할 수 있으며, ESG 정보가 갖추어야 할 신뢰성을 강제할 수 있는 법적/제도적 장치도 마련되어 있지 않은 상황이다. 따라서 ESG 정보 검증은 이러한 문제점을 개선하기 위한 조직의 의지이자 자율적 활동으로 조직이 공시하는 ESG 정보의 신뢰성을 확보하는 수단으로 인정받고 있다.  ESG 정보 검증의 타당성과 신뢰성을 확인하기 위한 기준은 ‘검증기관의 적격성’, ‘검증기관과의 독립성’, ‘검증방법론의 합리성’, ‘검증수준의 명확성’, ‘검증지표의 구체성’으로 구분할 수 있다.  글로벌 시장에서 통용되는 ESG 검증표준에는 1) 지속가능경영 관련 국제표준 제정기관인… | AA6: 적격/독립된 제3자 검증기관으로부터 인증을 획득했습니까? | AB6: 단계(1~5)
A7: 6 | B7: E-1-1 | C7: 기본진단항목(v2.0) | D7: 환경 | E7: 환경경영 목표 | F7: 환경경영 목표 수립 | G7:  조직이 책임있는 환경경영을 수행하기 위한 방향성을 명확히 설정하고 효율적인 자원 배분이 이루어지고 있는지, 또한 조직이 외부에 미치는 환경 영향을 최소화하고 내부 환경성과를 향상시키기 위한 구체적인 계획이 마련되어 있는지 점검  조직이 수립한 환경 분야 단기/중장기 목표 구체성과 내재화 수준을 확인 | H7: 환경 분야 목표 수립 현황 | I7: 직전 회계연도 | J7: N/A | K7: N/A | L7: 단계형 | M7: 5 | N7: 단계형: 1단계=0점 / 2단계=25점 / 3단계=50점 / 4단계=75점 / 5단계=100점 | O7: 1단계 | 단기/중장기 성과목표, 또는 조직의 환경경영 방향성을 나타내는 환경경영 미션/비전/지향점이 없는 경우 | 2단계 | 환경경영 미션/비전/지향점만 제시하고 있는 경우 | 3단계 | 2단계 + 조직의 환경 분야 핵심이슈에 대한 단기 목표만 설정하고 있는 경우 | 4단계 | 3단계 + 중장기 목표까지 수립하고 있는 경우 | 5단계 | 4단계 + 중장기 목표 달성을 위한 과제와, 이행점검 지표를 마련한 경우 | P7: 부분대응 | Q7: KSSB 제2호 문단 33~36(목표) 준용 가능 | R7: GRI 2-27 | S7: 1_2_0_업종별 K-ESG 가이드라인(v2.0) 진단항목 | X7: =IF(T7="","",MAX(1,SUMPRODUCT(('02_점수산정참고표'!$A$2:$A$314=$B7)*('02_점수산정참고표'!$C$2:$C$314=T7)*'02_점수산정참고표'!$E$2:$E$314))) | Y7:  조직은 중대성 평가(Materiality Test)를 통해 조직의 사업운영 및 외부환경에 중요한 영향력을 행사하는 핵심이슈를 도출할 수 있다. 조직은 사업운영에 해당하는 모든 직/간접 환경규제를 관리해야 함과 동시에 사업성과와 연계된 핵심이슈에 대해서는 목표에 의한 성과관리가 필요하다. 조직이 수립할 수 있는 환경 분야 목표와 관련된 핵심이슈에는 아래와 같은 이슈가 해당된다. 에너지 사용량 절감 재생에너지 투자 확대 온실가스 배출량 감축 탄소중립 기술 개발 및 관련 투자활동 폐기물 발생량 저감 플라스틱 사용량 절감 재사용 용수 확대 원자재 효율적 투입 산림 및 토양 복원 생물다양성 증진 및 관련 투자활동 친환경 공급망 구축 대기/수질/토양 오염 감소 유해물질 감소… | AA7: 단기/중장기 환경경영 정량 목표 및 점검 지표를 수립했습니까? | AB7: 단계(1~5)
A8: 7 | B8: E-1-2 | C8: 기본진단항목(v2.0) | D8: 환경 | E8: 환경경영 목표 | F8: 환경경영 추진체계 | G8:  조직이 환경성과 향상과 환경 개선 등의 경영활동으로 인한 환경영향 관리, 원부자재/에너지/폐기물 등의 효율적 관리, 국제사회 등 이해관계자의 환경영역 요구 대응을 위해 체계적으로 환경경영을 추진하고 있는지 점검  국내외 규격에서 제시하는 환경경영시스템 구성요건을 기준으로 조직이 이를 따르거나, 준용하여 환경경영 추진체계를 갖추고 있는지 확인 | H8: 환경경영시스템, 환경경영 정책, 환경경영 가이던스 | I8: 직전 회계연도 | J8: N/A | K8: N/A | L8: 선택형 | M8: 5 | N8: 선택형: 요건1=0점 / 요건2=25점 / 요건3=50점 / 요건4=75점 / 요건5=100점 | O8: 요건1 | 환경경영 추진을 위한 전사 거버넌스 체계를 구축하고 있는 경우 | (전담조직, 실무협의회, 경영회의 및 내부점검체계 등) | 요건2 | 환경경영 추진을 위한 전사 전담조직을 운영하고 있는 경우 | (전사 환경경영 기획, 점검, 성과관리 등 실행업무 담당) | 요건3 | 환경경영 과제 실행에 필요한 자원을 투입하고 있는 경우 | (환경투자 예산, 역량강화 교육, 내외부 전문인력 등) | 요건4 | 환경경영 추진 현황을 점검/분석/평가하는 시스템이 있는 경우 | (IT기반 모니터링 시스템, 과제점검 회의, 제3자 의견수렴 등) | 요건5 | 환경경영 과제 이행현황이 경영진 포함 관련 구성원의 | 성과평가지표(KPIs)에 반영되어 있는 경우 | * 선택 항목의 합산값으로 평가 | P8: 부분대응 | Q8: KSSB 제2호 문단 6(거버넌스) 준용 가능 | R8: GRI 2-27, K-ESG | S8: 1_2_0_업종별 K-ESG 가이드라인(v2.0) 진단항목 | X8: =IF(T8="","",MAX(1,SUMPRODUCT(('02_점수산정참고표'!$A$2:$A$314=$B8)*('02_점수산정참고표'!$C$2:$C$314=T8)*'02_점수산정참고표'!$E$2:$E$314))) | Y8:  환경경영이란 조직의 사업운영 전 과정에 걸쳐 발생하는 환경영향을 최소화하면서 환경적으로 건전하고, 경제적으로 지속가능한 발전을 도모하고자 하는 경영활동이다. 조직의 환경경영 체계란 환경경영을 효과적으로 추진하기 위해 환경방침 개발, 이행, 달성, 검토 및 유지관리 할 수 있는 조직, 책임, 자원, 절차, 과정 및 성과관리 등을 종합적으로 구축한 것을 의미한다.  조직은 환경경영을 위해 아래와 같은 추진체계를 구축할 수 있으며, 해당 정보는 이해관계자와 공유할 필요가 있다. ; 1) 조직은 목표 달성과 관련된 제반업무를 관장하는 거버넌스 및 업무분장 체계를 구축해야 한다. 2) 목표 달성을 위한 추진과제와 실행계획을 수립해야 한다. 3) 목표 달성에 필요한 새로운… | AA8: 거버넌스, 전담조직, 예산 투입, 구성원 KPI 연계 체계가 있습니까? | AB8: 단계(1~5)
A9: 8 | B9: E-2-1 | C9: 기본진단항목(v2.0) | D9: 환경 | E9: 원부자재 | F9: 원부자재 사용량 | G9:  조직이 이윤을 창출하기 위한 재화를 생산하는 과정에서 자연으로부터 가져온 원부자재를 효율적으로 관리하고 있는지 점검  조직 규모 차이(매출액, 생산량 등) 또는 사업 변동(구조조정, 인수합병 등)을 고려하여 상대적 비교가능성이 높은 ‘원단위’ 개념을 기반으로 원부자재의 물리적·화학적 특성을 포괄한 사용량을 점검 | H9: ‘조직별 홈페이지’ 上 지속가능경영보고서, 환경정보공개시스템>자원/에너지>원부자재 사용량, 조직의 원부자재 구매 및 사용량 실적 | I9: 최근 4개 회계연도 | J9: 국내외 사업장 및 기타 연결실체 | K9: 총 원단위 원부자재 사용량 = 총 원부자재 사용량(재생불가능한, 재생가능한, 재생/재활용) / 원단위 활용 분모 (매출액 등) | L9: 단계형 | M9: 3 | N9: 단계형: 1단계=0점 / 2단계=50점 / 3단계=100점 | O9: 1단계 | 지난 4개년 원단위 원부자재 사용량 증가 추세 | 2단계 | 지난 4개년 원단위 원부자재 사용량 변동 없음 | 3단계 | 지난 4개년 원단위 원부자재 사용량 감소 추세 | * 원단위 원부자재 사용량을 관리하지 않는 경우 0점 적용 | * 3개년 이하 데이터 보유 시 해당 데이터로 추세 산정 | * '유지 추세'로 판단할 경우 2단계로 적용하여 평가 | P9: GAP(대응지표 없음) | Q9: KSSB 원부자재 지표 미규정 | R9: GRI 301 | S9: 1_2_0_업종별 K-ESG 가이드라인(v2.0) 진단항목 | X9: =IF(T9="","",MAX(1,SUMPRODUCT(('02_점수산정참고표'!$A$2:$A$314=$B9)*('02_점수산정참고표'!$C$2:$C$314=T9)*'02_점수산정참고표'!$E$2:$E$314))) | Y9:  본 ‘원부자재 사용량’ 항목 정의서를 참고할 수 있는 산업군을 좁은 범위로 해석한다면 원부자재를 가공하여 제품을 대량 생산하는 광업, 제조업, 건설업, 전기/가스/증기업 등으로 한정할 수 있으나, 넓은 범위로 해석한다면 서비스 운용/제공하는 과정에서 광물, 종이, 플라스틱 등을 사용하는 도매/소매, 운수/창고, 정보통신, 금융/보험, 기타 전문 서비스업으로 확대할 수 있다.  원부자재는 기본적으로 재생가능 여부에 따라 재생가능한 원부자재, 재생불가능한 원부자재로 분류되며, 해당 원부자재의 원천(Source)에 따라 재생/재활용 원부자재, 천연 원부자재로 분류된다. 아래 분류별 예시를 참고하되 절대적인 기준은 아니므로 원료 특성 및 가공 방법에 따라 보편적·합리적… | AA9: 원단위 원부자재 사용량이 4개년 간 감소 추세입니까? | AB9: 단계(1~5)
A10: 9 | B10: E-2-2 | C10: 기본진단항목(v2.0) | D10: 환경 | E10: 원부자재 | F10: 재생 원부자재 비율 | G10:  지속적인 경제 성장으로 인한 천연자원 고갈 이슈가 증가함에 따라, 원부자재 조달-투입 방식을 자원순환형 체계로 전환하고 있는지 점검  조직이 생산하는 제품 중 재생 원부자재를 적용할 수 있는 부분을 실제 재생 원부자재로 대체하는 등의 자원순환 이행성과를 확인 | H10: ‘전자공시시스템’ 上 사업보고서, ‘조직별 홈페이지’ 上 지속가능경영보고서, 조직의 원부자재 구매 및 사용량 실적 | I10: 최근 4개 회계연도 | J10: 국내외 사업장 및 기타 연결실체 | K10: 재생 원부자재 사용 비율 = 총 재생 원부자재 사용량 / 총 원부자재 사용량 | L10: 단계형 | M10: 3 | N10: 단계형: 1단계=0점 / 2단계=50점 / 3단계=100점 | O10: 1단계 | 지난 4개년 재생 원부자재 사용 비율 감소 추세 | 2단계 | 지난 4개년 재생 원부자재 사용 비율 변동 없음 | 3단계 | 지난 4개년 재생 원부자재 사용 비율 증가 추세 | * 재생 원부자재를 사용하지 않는 경우 0점 적용 | * 국내 및 해외 모든 사업장에서 재생 원부자재를 100% 사용하는 경우 100점 적용 | * 3개년 이하 데이터 보유 시 해당 데이터로 추세 산정 | * '유지 추세'로 판단할 경우 2단계로 적용하여 평가 | P10: GAP(대응지표 없음) | Q10: KSSB 원부자재 지표 미규정 | R10: GRI 301 | S10: 1_2_0_업종별 K-ESG 가이드라인(v2.0) 진단항목 | X10: =IF(T10="","",MAX(1,SUMPRODUCT(('02_점수산정참고표'!$A$2:$A$314=$B10)*('02_점수산정참고표'!$C$2:$C$314=T10)*'02_점수산정참고표'!$E$2:$E$314))) | Y10:  원료, 생산, 소비, 폐기로 이어지는 기존의 선형 경제 대안으로 유럽연합 등 선진국을 중심으로 자원순환 경제 모델(3R: Reduce, Recycle, Reuse)이 확산되고 있다. 자원순환 경제는 폐기 이후의 재활용, 자원의 절약 등을 통해 사회 전반의 순환성을 높이고 지속가능성을 추구하는 모델이다.  본 ‘재생 원부자재 비율’ 항목 정의서를 참고할 수 있는 산업군을 좁은 범위로 해석한다면 원부자재를 가공하여 제품을 대량 생산하는 광업, 제조업, 건설업, 전기/가스/증기업 등으로 한정할 수 있으나, 넓은 범위로 해석한다면 서비스 운용/제공하는 과정에서 광물, 종이, 플라스틱 등을 사용하는 도매/소매, 운수/창고, 정보통신, 금융/보험, 기타 전문 서비스업으로… | AA10: 재생/재활용 투입 원부자재 비율이 4개년 간 증가 추세입니까? | AB10: 단계(1~5)
A11: 10 | B11: E-3-1 | C11: 기본진단항목(v2.0) | D11: 환경 | E11: 온실가스 | F11: 온실가스 배출량 (Scope1 & Scope2) | G11:  조직이 소유, 관리, 통제하는 물리적 경계(사업장 등) 내에서 에너지 사용으로 인해 발생하는 온실가스 배출(Scope1 & Scope2)을 감축하고 있는지 점검  조직간 규모 차이(매출액, 생산량 등) 또는 사업 변동(구조조정, 인수합병 등)을 고려하여 상대적 비교가능성이 높은 ‘원단위’ 개념을 기반으로 온실가스 배출량을 확인 | H11: ‘전자공시시스템’ 上 사업보고서, ‘조직별 홈페이지’ 上 지속가능경영보고서, ‘국가온실가스종합관리 시스템’ 上 명세서배출량통계 | I11: 최근 4개 회계연도 | J11: 국내외 사업장 및 기타 연결실체 | K11: 원단위 온실가스 배출량 = 총 온실가스 배출량 / 원단위 활용 분모 | L11: 단계형 | M11: 3 | N11: 단계형: 1단계=0점 / 2단계=50점 / 3단계=100점 | O11: 1단계 | 지난 4개년 원단위 온실가스 배출량 증가 추세 | 2단계 | 지난 4개년 원단위 온실가스 배출량 변동 없음 | 3단계 | 지난 4개년 원단위 온실가스 배출량 감소 추세 | * 원단위 온실가스 배출량을 관리하고 있지 않은 경우 0점 적용 | * 국내 및 해외 모든 사업장이 ‘탄소중립’ 또는 ‘탄소제로’를 달성한 경우 100점 적용 | * 3개년 이하 데이터 보유 시 해당 데이터로 추세 산정 | * '유지 추세'로 판단할 경우 2단계로 적용하여 평가 | P11: 완전대응 | Q11: KSSB 제2호 문단 29(1) — Scope1·2 배출량 | R11: GHG Protocol, GRI 305-1,2 | S11: 1_2_0_업종별 K-ESG 가이드라인(v2.0) 진단항목 | X11: =IF(T11="","",MAX(1,SUMPRODUCT(('02_점수산정참고표'!$A$2:$A$314=$B11)*('02_점수산정참고표'!$C$2:$C$314=T11)*'02_점수산정참고표'!$E$2:$E$314))) | Y11:  Scope1 온실가스 배출량 산정방법 = ∑[고정연소, 이동연소, 공정배출, 탈루배출, 폐기물처리]  Scope2 온실가스 배출량 산정방법 = ∑[구매전기, 구매 열(온수, 스팀 등)]  조직의 온실가스 배출량이 산업 내 어떠한 수준에 있는지 점검하는 방식에는 1) ‘온실가스 배출권의할당및거래에관한법률’ 등에 따른 할당량 대비, 2) ‘온실가스·에너지 목표관리제’에 따른 목표값 대비, 3) 조직의 과거년도 배출량을 기반으로 수립한 목표 대비, 4) 조직이 자체적으로 수립한 목표(SBTi* 등) 대비, 5) 조직이 벤치마킹하는 경쟁조직 대비 비교하는 방식 등이 있다. * Science Based Target Initiative : 조직의 과거년도 배출량이나, 국가별… | AA11: 온실가스 배출량 (Scope1 & Scope2)에 대한 현황을 관리·공시하고 있습니까? | AB11: 단계(1~5)
A12: 11 | B12: E-3-2 | C12: 기본진단항목(v2.0) | D12: 환경 | E12: 온실가스 | F12: 온실가스 배출량 (Scope3) | G12:  조직이 온실가스 배출량 감축 목표를 달성하기 위해 물리적 경계 내에서 발생하는 Scope1 & Scope2 배출량뿐만 아니라, 조직의 외부에서 발생하는 Scope3 배출량의 감축도 관리하고 있는지 점검  Scope3는 조직이 통제할 수 없는 범주에 속하기 때문에, 조직이 Scope3를 직접 감축하고 있는지를 확인하기보다는 Scope3의 인식/산정/검증 등 성과를 관리하는 노력 수준을 확인 | H12: Scope3 측정 범주, Scope3 배출 데이터, Scope3 검증의견서 | I12: 직전 회계연도 | J12: 국내외 사업장 및 기타 연결실체 | K12: N/A | L12: 복합가중형 | N12: 복합가중형: 2~3개 세부요소를 균등가중평균(예: 1/2+1/2, 1/3×3) — 세부 배점은 점검기준 상세 참조, 자사취득점수는 수동 산정 | O12: Scope3 범주 인식 Scope3 배출량 산정 Scope3 배출량 검증 | (1/3) (1/3) (1/3) | 1단계 조직의 Scope3 범주를 인식하고 조직의 Scope3 배출량을 Scope3 배출량에 대한 제3자 | 있지 않는 경우 측정하고 있지 않는 경우 검증을 하지 않는 경우 | 2단계 조직의 가치사슬 관련 일부 국내 등 일부 사업장의 일부 Scope3 범주 및 측정값에 | Scope3 범주만 인식하고 Scope3 배출량만 측정하고 대해서만 제3자 검증을 하는 경우 | 있는 경우 있는 경우 | 3단계 조직의 가치사슬 관련 모든 조직의 모든 사업장의 Scope3 모든 Scope3 범주 및 측정값에 | Scope3 범주를 인식하고 배출량을 측정하고 있는 경우 대해 제3자 검증을 하는 경우 | 있는 경우 | P12: 부분대응 | Q12: KSSB 제2호 문단 29(1)(사) — Scope3 15개 카테고리 요구(K-ESG는 범주인식·산정·검증 3단계로 단순화) | R12: GHG Protocol, GRI 305-3 | S12: 1_2_0_업종별 K-ESG 가이드라인(v2.0) 진단항목 | T12: 해당없음(복합가중형) | Y12:  Scope3 온실가스란 조직이 소유하고 관리하는 사업장(경계) 외 가치사슬에서 발생하는 간접적인 온실가스 배출이다. 조직의 경계 내에서 직접 배출되는 Scope1과 외부 전력 및 열 소비로 인해 배출되는 Scope2에 비해 감축의무 대상은 아니지만, 기후변화 이슈가 가속화됨에 따라 Scope3 관리 필요성도 증가하고 있다. 특히, [조달-개발-생산-유통-판매- 유지-폐기] 등 경영활동 전반을 내재화한 조직과 달리, 사업 운영의 대부분을 외주화(Outsourcing)한 조직은 Scope1 & Scope2 못지않게, Scope3 관리가 중요하다. GreenHouse Gas Protocol이 제시한 ‘Corporate Value Chain(Scope3) Accounting… | AA12: 가치사슬 전반 Scope 3 15개 범주를 인식/산정/검증합니까? | AB12: 단계(1~5)
A13: 12 | B13: E-3-3 | C13: 기본진단항목(v2.0) | D13: 환경 | E13: 온실가스 | F13: 온실가스 배출량 검증 | G13:  온실가스 배출권 거래제, 온실가스 목표관리제, 기타 온실가스 정보를 기반으로 의사결정하는 이해관계자가 증가함에 따라, 조직이 대외공시하는 온실가스 배출량 데이터가 타당성/신뢰성/투명성을 확보하고 있는지 확인  조직의 온실가스 배출량 데이터에 관해 제3자 기관으로부터 검증을 받는 경우, 해당 검증의견이 갖추어야 할 형식적 요건을 점검 | H13: 온실가스 배출량 검증의견서 | I13: 직전 회계연도 | J13: N/A | K13: N/A | L13: 선택형 | M13: 5 | N13: 선택형: 요건1=0점 / 요건2=25점 / 요건3=50점 / 요건4=75점 / 요건5=100점 | O13: 요건1 | 검증의견서에 검증기관(또는 검증인)이 명시되어 있는 경우 | (또는, 검증기관이 License Number를 갖추고 있는 경우) | 요건2 | 검증의견서에 검증표준(방법론)이 제시되어 있는 경우 | (온실가스 배출권거래제의 배출량 보고 및 인증에 관한 지침, GHG Protocol, ISO14064-1 등) | 요건3 | 검증의견서에 ESG 정보 검증수준을 공개하고 있는 경우 | (전체/일부 데이터 검증, 제한적/합리적 보증 등) | 요건4 | 제3자 검증기관이 검증한 온실가스 배출량 검증 범위가 적시되어 있는 경우 | (즉, 조직의 사업장 중 온실가스 배출량을 검증받은 사업장 및 지역 등) | 요건5 | 조직의 온실가스 관리에 관한 제3자 검증기관 의견이 명시되어 있는 경우 | (온실가스 관리 시스템 개선, 향후 검증값의 변동가능성 등) | P13: 완전대응 | Q13: KSSB 제1호 문단 50(3)(검증) | R13: GRI 305 | S13: 1_2_0_업종별 K-ESG 가이드라인(v2.0) 진단항목 | X13: =IF(T13="","",MAX(1,SUMPRODUCT(('02_점수산정참고표'!$A$2:$A$314=$B13)*('02_점수산정참고표'!$C$2:$C$314=T13)*'02_점수산정참고표'!$E$2:$E$314))) | Y13:  ｢기후위기 대응을 위한 탄소중립·녹색성장 기본법｣에 따라 국가 온실가스 감축 목표(2030년의 국가 온실가스 총배출량을 2018년의 온실가스 총배출량의 40%만큼 감축)를 달성할 수 있도록 일정 수준 이상의 온실가스를 배출하고 에너지를 소비하는 업체 및 사업장은 관리업체로 지정되며, 해당 기업은 온실가스 감축목표, 에너지 절약목표를 설정하고 관리할 의무가 있다.  2023년 12월 14일 환경부 온실가스종합정보센터의 관리업체 고시 기준 온실가스·에너지 목표관리 대상은 총 331개로 관장기관별로 국토교통부 86개, 산업통상자원부 172개, 농림축산식품부 35개, 해양수산부 15개, 환경부 23개이며, 관리업체에 대한 선정기준은 최근 3년간 연평균 온실가스 배출총량을… | AA13: 온실가스 배출량에 대해 적격한 제3자 검증을 획득했습니까? | AB13: 단계(1~5)
A14: 13 | B14: E-4-1 | C14: 기본진단항목(v2.0) | D14: 환경 | E14: 에너지 | F14: 에너지 사용량 | G14:  조직이 소유, 관리, 통제하는 물리적 경계(사업장 등) 내에서 직접 생산하거나, 외부로부터 구매하는 에너지 사용 총량을 절감하고 있는지 점검  조직간 규모 차이(매출액, 생산량 등) 또는 각 조직의 사업 변동(구조조정, 인수합병 등)을 고려하여 상대적으로 비교가 용이한 단위 당 개념의 ‘원단위’를 기반으로 에너지 사용량을 확인 | H14: ‘전자공시시스템’ 上 사업보고서, ‘조직별 홈페이지’ 上 지속가능경영보고서, ‘한국에너지공단 홈페이지’ 上 산업부문 에너지 사용 및 온실가스 배출량 통계 | I14: 최근 4개 회계연도 | J14: 국내외 사업장 및 기타 연결실체 | K14: 원단위 에너지 사용량 = 총 에너지 사용량 / 원단위 활용 분모 | L14: 단계형 | M14: 3 | N14: 단계형: 1단계=0점 / 2단계=50점 / 3단계=100점 | O14: 1단계 | 지난 4개년 원단위 에너지 사용량이 증가 추세 | 2단계 | 지난 4개년 원단위 에너지 사용량이 변동 없음 | 3단계 | 지난 4개년 원단위 에너지 사용량이 감소 추세 | * 원단위 에너지 사용량을 관리하지 않고 있는 경우 0점 적용 | * 3개년 이하 데이터 보유 시 해당 데이터로 추세 산정 | * '유지 추세'로 판단할 경우 2단계로 적용하여 평가 | P14: 부분대응 | Q14: KSSB 제2호 문단 29 부속 에너지 사용 관련 준용 | R14: GRI 302-1 | S14: 1_2_0_업종별 K-ESG 가이드라인(v2.0) 진단항목 | X14: =IF(T14="","",MAX(1,SUMPRODUCT(('02_점수산정참고표'!$A$2:$A$314=$B14)*('02_점수산정참고표'!$C$2:$C$314=T14)*'02_점수산정참고표'!$E$2:$E$314))) | Y14:  에너지 사용량 = ‘조직에서 직접 사용한 화석연료’ + ‘조직에서 직접 사용한 재생연료’ + ‘외부로부터 구매한 전기, 열 등’ + ‘조직에서 생산한 전기, 열(스팀) 등’ - ‘조직에서 사용하지 않고 외부로 판매한 전기, 열 등’  (고체, 기체, 액체 연료) 에너지 사용량 환산방법 = 연료 사용량 × 총발열량  (전기) 에너지 사용량 환산방법 = 전력사용량 × 발열량(소비)  조직의 에너지 사용량이 산업 내 어떠한 수준에 있는지 점검하는 방식에는 1) ‘온실가스 배출권의할당및거래에관한법률’ 등에 따른 할당량 대비 비교, 2) ‘온실가스·에너지 목표관리제’에 따른 목표 대비 비교, 3) 조직의 과거년도 배출량을 기반으로 설정한 목표 대비 비교, 4) RE100… | AA14: 원단위 에너지 사용량이 최근 4개년 간 절감 추세입니까? | AB14: 단계(1~5)
A15: 14 | B15: E-4-2 | C15: 기본진단항목(v2.0) | D15: 환경 | E15: 에너지 | F15: 재생에너지 사용 비율 | G15:  조직이 에너지 체계를 재생에너지로 전환하고 있는지 확인  조직의 총 에너지 사용량 대비 신에너지 및 재생에너지가 차지하는 비율로 해당 항목을 점검  국내 ‘신에너지 및 재생에너지 개발·이용·보급촉진법’ 上 2025년까지 대규모 발전소가 공급하는 신재생에너지공급의무비율 (RPS)은 25%로써 수요 대비 한계가 있으므로, 해당 지표에서 다루는 재생에너지 범위는 ‘자가 재생에너지 발전’, ‘녹색프리미엄 요금제 사용’, ‘재생에너지 크레딧 구매’, ‘재생에너지 발전사업 지분 참여’, ‘제3자 전력구매계약’ 등을 포괄함 | H15: ‘조직별 홈페이지’ 上 지속가능경영보고서 | I15: 최근 4개 회계연도 | J15: 국내외 사업장 및 기타 연결실체 | K15: 재생에너지 사용 비율 = 총 재생에너지 사용량 / 총 에너지 사용량 * 신에너지 사용량 포함 | L15: 단계형 | M15: 3 | N15: 단계형: 1단계=0점 / 2단계=50점 / 3단계=100점 | O15: 1단계 | 지난 4개년 재생에너지 사용비율이 감소 추세 | 2단계 | 지난 4개년 재생에너지 사용비율이 변동 없음 | 3단계 | 지난 4개년 재생에너지 사용비율이 증가 추세 | * 재생에너지를 사용하고 있지 않은 경우 0점 적용 | * 국내 및 해외 모든 사업장에서 재생에너지를 100% 사용하는 경우 100점 적용 | * 3개년 이하 데이터 보유 시 해당 데이터로 추세 산정 | * '유지 추세'로 판단할 경우 2단계로 적용하여 평가 | P15: 부분대응 | Q15: KSSB 제2호 문단 29(4) 친환경 기회 관련 준용 | R15: GRI 302-1 | S15: 1_2_0_업종별 K-ESG 가이드라인(v2.0) 진단항목 | X15: =IF(T15="","",MAX(1,SUMPRODUCT(('02_점수산정참고표'!$A$2:$A$314=$B15)*('02_점수산정참고표'!$C$2:$C$314=T15)*'02_점수산정참고표'!$E$2:$E$314))) | Y15:  ‘신에너지 및 재생에너지 개발·이용·보급촉진법’ 제2조에서는 신재생에너지를 “기존의 화석연료를 변환시켜 이용하거나 햇빛·물·지열·강수·생물유기체 등을 포함하여 재생가능한 에너지를 변환시켜 이용하는 에너지”로 정의하고 있으며, 신재생에너지의 종류는 다음과 같다. - 신에너지 : 연료전지, 수소, 석탄액화·가스화 및 중질잔사유 가스화 - 재생에너지 : 태양광, 태양열, 바이오, 풍력, 수력, 해양, 폐기물, 지열  조직이 사업을 영위하는 국가 또는 지역의 에너지 체계에 따라, 또는 태양광, 대기, 조류 등의 양적/질적 조건에 따라 재생에너지 사용 비율을 확대하는데 한계가 있다. 반면, 국가별 재생에너지 이용·보급·확산을 위해 조직이 재생에너지를 직접 구매·생산하지… | AA15: 재생에너지(PPA, REC 등) 사용 비율이 4개년 간 증가 추세입니까? | AB15: 단계(1~5)
A16: 15 | B16: E-5-1 | C16: 기본진단항목(v2.0) | D16: 환경 | E16: 용수 | F16: 용수 사용량 | G16:  조직이 용수를 공급받는 취수원을 보호하고 있는지, 또는 사업장이 위치한 지역의 수자원 고갈 리스크에 대비하고 있는지를 간접적으로 점검할 수 있는 항목으로써, 조직이 사용하는 용수 총량(신규 취수량, 내부 재사용량)을 효율적으로 관리하고 있는지 확인  조직간 규모 차이(매출액, 생산량 등) 또는 각 조직의 사업 변동(구조조정, 인수합병 등)을 고려하여 상대적 비교가능성이 높은 ‘원단위’ 개념을 기반으로 용수 사용량을 점검 | H16: ‘조직별 홈페이지’ 上 지속가능경영보고서, ‘한국에너지공단 물정보포털(My Water)’ 上 GIS 수자원 | I16: 최근 4개 회계연도 | J16: 국내외 사업장 및 기타 연결실체 | K16: 원단위 용수 사용량 = 총 용수 사용량 / 원단위 활용 분모 | L16: 단계형 | M16: 3 | N16: 단계형: 1단계=0점 / 2단계=50점 / 3단계=100점 | O16: 1단계 | 지난 4개년 원단위 용수 사용량이 증가 추세 | 2단계 | 지난 4개년 원단위 용수 사용량이 변동 없음 | 3단계 | 지난 4개년 원단위 용수 사용량이 감소 추세 | * 원단위 용수 사용량을 관리하고 있지 않은 경우 0점 적용 | * 3개년 이하 데이터 보유 시 해당 데이터로 추세 산정 | * '유지 추세'로 판단할 경우 2단계로 적용하여 평가 | P16: GAP(대응지표 없음) | Q16: KSSB 제2호 직접 규정 없음(업종기반지표로만 요구 가능) | R16: GRI 303, CDSB 물 적용지침 | S16: 1_2_0_업종별 K-ESG 가이드라인(v2.0) 진단항목 | X16: =IF(T16="","",MAX(1,SUMPRODUCT(('02_점수산정참고표'!$A$2:$A$314=$B16)*('02_점수산정참고표'!$C$2:$C$314=T16)*'02_점수산정참고표'!$E$2:$E$314))) | Y16:  UN의 환경경제 통합계정(System of Integrated Environmental and Economic Accounting, SEEA, 1993)에 따른 ‘용수 사용량’은 다음과 같이 정의할 수 있다. - 용수 사용량 = 환경에서 유입한 취수량 + 조직 내 재사용량 + 다른 조직에서 전달받은 폐수량 * 취수에 해당하는 경우 : 공업용수 外 표층수, 지하수, 토양수, 강우포집, 해양취수  용수 사용량은 산업분류, 사업특성, 생산규모에 따라 영향을 받는다. 따라서 조직의 용수 사용량이 산업 내 어떠한 수준에 있는지 점검하는 방식에는 1) 조직이 취수받는 수원별 공급능력 대비, 2) 조직의 사업장이 위치한 지역별 수자원 부존량 대비, 3) 조직의 과거년도 사용량… | AA16: 수자원 취수 원단위 총 용수 사용량이 감소 추세입니까? | AB16: 단계(1~5)
A17: 16 | B17: E-5-2 | C17: 기본진단항목(v2.0) | D17: 환경 | E17: 용수 | F17: 재사용 용수 비율 | G17:  조직이 도시화와 산업화 진전으로 인해 발생되는 수자원 부족 문제에 대비하여, 지속가능한 용수 순환 체계를 구축하고 있는지 확인  조직이 소유, 관리, 통제하는 물리적 경계(사업장 등) 내에서 중수도, 하·폐수처리수 재이용시설 등을 설치하여 오수(汚水), 하수, 폐수를 효과적으로 순환·재사용하는지 점검 | H17: ‘조직별 홈페이지’ 上 지속가능경영보고서 | I17: 최근 4개 회계연도 | J17: 국내외 사업장 및 기타 연결실체 | K17: 재사용 용수 비율 = 총 재사용 용수량 / 총 용수 사용량 | L17: 단계형 | M17: 3 | N17: 단계형: 1단계=0점 / 2단계=50점 / 3단계=100점 | O17: 1단계 | 지난 4개년 재사용 용수 비율이 감소 추세 | 2단계 | 지난 4개년 재사용 용수 비율이 변동 없음 | 3단계 | 지난 4개년 재사용 용수 비율이 증가 추세 | * 용수를 재사용하지 않고 있는 경우 0점 적용 | * 국내 및 해외 모든 사업장이 폐수 무방류 시스템을 구축한 경우 100점 적용 | * 3개년 이하 데이터 보유 시 해당 데이터로 추세 산정 | * '유지 추세'로 판단할 경우 2단계로 적용하여 평가 | P17: GAP(대응지표 없음) | Q17: KSSB 제2호 직접 규정 없음 | R17: GRI 303 | S17: 1_2_0_업종별 K-ESG 가이드라인(v2.0) 진단항목 | X17: =IF(T17="","",MAX(1,SUMPRODUCT(('02_점수산정참고표'!$A$2:$A$314=$B17)*('02_점수산정참고표'!$C$2:$C$314=T17)*'02_점수산정참고표'!$E$2:$E$314))) | Y17:  물의 순환 개념은 ‘우수→하천→취수→[1회사용]→배출→하천→해양’으로써, 용수 재사용이란 인공적인 순환을 개념을 추가한 ‘우수→하천→취수→[사용→처리→재사용]→배출→하천→해양’이라 할 수 있다. 해당 지표에서 정의하는 재사용은 재생처리된 폐수를 방류한 후 이를 다시 취수하는 간접 재사용(Indirect Reuse)을 의미하는 것이 아니라, 재생처리된 폐수를 방류하지 않고 조직의 사업 및 영업 행위에 다시 사용하는 직접 재사용(Direct Reuse)을 의미한다.  조직의 사업 특성에 따라 재사용 또는 재활용 불가능한 수준의 오수, 하수, 폐수가 발생할 수 있으나, 해당 오수, 하수, 폐수를 재사용 또는 재활용할 수 있는 수처리 기술도 발전하고 있다. 따라서 재사용… | AA17: 사용한 용수를 직접 재사용/순환하는 비율이 증가 추세입니까? | AB17: 단계(1~5)
A18: 17 | B18: E-6-1 | C18: 기본진단항목(v2.0) | D18: 환경 | E18: 폐기물 | F18: 폐기물 배출량 | G18:  조직이 소유, 관리, 통제하는 물리적 경계(사업장 등) 내에서 사업 및 영업 활동(ex. 연구개발, 제품 생산/가공/포장 등 포함, 소비자가 사용 이후 폐기한 폐제품은 제외)에 따라 발생하는 폐기물을 저감하고 있는지 확인  조직간 규모 차이(매출액, 생산량 등) 또는 각 조직의 사업 변동(구조조정, 인수합병 등)을 고려하여 상대적 비교가능성 높은 ‘원단위’ 개념을 기반으로 폐기물 배출량을 점검 | H18: ‘조직별 홈페이지’ 上 지속가능경영보고서, ‘한국환경공단’>자원순환정보시스템>연도별 전국 폐기물 발생 및 처리현황 | I18: 최근 4개 회계연도 | J18: 국내외 사업장 및 기타 연결실체 | K18: 원단위 폐기물 배출량 = 총 폐기물 배출량 / 원단위 활용 분모 | L18: 단계형 | M18: 3 | N18: 단계형: 1단계=0점 / 2단계=50점 / 3단계=100점 | O18: 1단계 | 지난 4개년 원단위 폐기물 배출량이 증가 추세 | 2단계 | 지난 4개년 원단위 폐기물 배출량이 변동 없음 | 3단계 | 지난 4개년 원단위 폐기물 배출량이 감소 추세 | * 원단위 폐기물 배출량을 관리하지 않고 있는 경우 0점 적용 | * 3개년 이하 데이터 보유 시 해당 데이터로 추세 산정 | * '유지 추세'로 판단할 경우 2단계로 적용하여 평가 | P18: GAP(대응지표 없음) | Q18: KSSB 제2호 직접 규정 없음(업종기반지표로만 요구 가능) | R18: GRI 306 | S18: 1_2_0_업종별 K-ESG 가이드라인(v2.0) 진단항목 | X18: =IF(T18="","",MAX(1,SUMPRODUCT(('02_점수산정참고표'!$A$2:$A$314=$B18)*('02_점수산정참고표'!$C$2:$C$314=T18)*'02_점수산정참고표'!$E$2:$E$314))) | Y18:  폐기물이란 쓰레기, 연소재, 오니, 폐유, 폐산, 폐알칼리 및 동물사체 등으로 사람의 생활이나 사업활동에 필요하지 않게 된 물질을 말하며, 조직에서 발생하는 폐기물의 종류는 ‘사업장배출시설계폐기물’, ‘사업장생활계폐기물’, ‘지정폐기물’, ‘건설폐기물’로 구분된다. - 조직이 배출하는 폐기물의 종류와 배출량은 ‘환경부-폐기물적법처리시스템(Allbaro)’, ‘환경부-환경정보 공개시스템’에서 확인 가능하다.  폐기물 배출량은 산업분류, 사업특성, 생산규모에 따라 영향을 받는다. 따라서 조직의 폐기물 배출량이 산업 내 어떠한 수준에 있는지 점검하는 방식에는 1) 업종별 총 폐기물 배출량 대비, 2) 조직의 사업장이 위치한 지역의 총 폐기물 배출량 대비, 3) 조직의… | AA18: 지정/일반 폐기물 발생 총량의 원단위 감축 추세입니까? | AB18: 단계(1~5)
A19: 18 | B19: E-6-2 | C19: 기본진단항목(v2.0) | D19: 환경 | E19: 폐기물 | F19: 폐기물 재활용 비율 | G19:  조직이 자원순환 경제로 전환에 동참하기 위해, 생산 단계에서부터 폐기물을 원천 감량하는 것을 넘어, 폐기물의 순환이용을 높이고 있는지 확인  조직이 가공-생산-보관-유통 과정에서 발생하는 폐기물이 생산 과정에 재투입되거나, 조직 내/외부에서 2차 자원으로 재활용 되고 있는지 점검 | H19: ‘조직별 홈페이지’ 上 지속가능경영보고서, ‘한국환경공단’ 연도별 전국 폐기물 발생 및 처리현황, 폐기물 재활용 실적 및 업체현황, 재활용지정사업자 재활용실적, 포장재폐기물 발생량 및 재활용량 | I19: 최근 4개 회계연도 | J19: 국내외 사업장 및 기타 연결실체 | K19: 폐기물 재활용 비율 = 폐기물 재활용량(재사용 포함) / 재활용(재사용 포함) 대상 폐기물 발생량 | L19: 단계형 | M19: 3 | N19: 단계형: 1단계=0점 / 2단계=50점 / 3단계=100점 | O19: 1단계 | 지난 4개년 폐기물 재활용 비율이 감소 추세 | 2단계 | 지난 4개년 폐기물 재활용 비율이 변동 없음 | 3단계 | 지난 4개년 폐기물 재활용 비율이 증가 추세 | * 폐기물 재활용 비율을 관리하지 않고 있는 경우 0점 적용 | * 국내 및 해외 모든 사업장이 재활용 및 재사용 가능한 폐기물 전부를 재활용 및 재사용하고 있는 경우 100점 적용 | * 3개년 이하 데이터 보유 시 해당 데이터로 추세 산정 | * '유지 추세'로 판단할 경우 2단계로 적용하여 평가 | P19: GAP(대응지표 없음) | Q19: KSSB 제2호 직접 규정 없음 | R19: GRI 306 | S19: 1_2_0_업종별 K-ESG 가이드라인(v2.0) 진단항목 | X19: =IF(T19="","",MAX(1,SUMPRODUCT(('02_점수산정참고표'!$A$2:$A$314=$B19)*('02_점수산정참고표'!$C$2:$C$314=T19)*'02_점수산정참고표'!$E$2:$E$314))) | Y19:  폐기물 재사용이란 원부자재 또는 재공품의 본래 용도 및 사용 목적과 같은 목적으로 사용하는 것을 의미하며, 폐기물 재활용이란 폐기된 원부자재 또는 재공품에서 유용한 자원을 회수하여 활용하는 것을 의미한다. 폐기물 재활용은 크게 아래와 같은 3가지 기준으로 구분할 수 있다. - 물질적 회수 : 폐기물이나 부산물을 처리하여 유가금속, 철스크랩, 종이류, 목재 등 특정 2차 물질을 회수하여 재활용하는 방식 - 화학적 회수 : 폐기물이나 부산물의 분자구조를 변형시키는 것으로 이전에는 실질적으로 재활용할 수 없었던 것을 재활용 할 수 있도록 변형하는 방식 - 에너지 전환 : 폐기물이나 부산물로부터 고형연료, 메탄가스 또는 기타 에너지원을 회수하여 새로운 에너지원으로 전환하는… | AA19: 물질/화학적 회수를 통한 전체 폐기물 재활용률이 증가 추세입니까? | AB19: 단계(1~5)
A20: 19 | B20: E-7-1 | C20: 기본진단항목(v2.0) | D20: 환경 | E20: 오염물질 | F20: 대기오염물질 배출량 | G20:  조직이 소유, 관리, 통제하는 물리적 경계(사업장 등) 내에서 발생하는 대기오염물질을 지속적으로 저감하는 등 대기환경 개선을 위한 노력을 이행하고 있는지 확인  ｢대기환경보전법｣ 上 64개 대기오염물질 중 대다수를 구성하는 질소산화물, 황산화물, 미세먼지 배출농도를 기간별 비교하는 방식으로 점검 | H20: ‘조직별 홈페이지’ 上 지속가능경영보고서, ‘한국환경공단-에어코리아’ 上 실시간 자료조회 | I20: 최근 4개년 회계연도 | J20: 국내외 사업장 및 기타 연결실체 | K20: 대기오염물질 배출 = 질소산화물, 황산화물, 미세먼지의 배출농도(PPM, mg/㎥) | L20: 단계형 | M20: 3 | N20: 단계형: 1단계=0점 / 2단계=50점 / 3단계=100점 | O20: 1단계 | 지난 4개년 대기오염물질 평균 배출농도가 증가 추세 | 2단계 | 지난 4개년 대기오염물질 평균 배출농도가 변동 없음 | 3단계 | 지난 4개년 대기오염물질 평균 배출농도가 감소 추세 | * 대기오염물질 평균 배출농도를 관리하지 않고 있는 경우 0점 적용 | * 국내 및 해외 모든 사업장의 대기오염물질 배출농도가 ‘0’인 경우 100점 적용 | * 3개년 이하 데이터 보유 시 해당 데이터로 추세 산정 | * '유지 추세'로 판단할 경우 2단계로 적용하여 평가 | P20: GAP(대응지표 없음) | Q20: KSSB 제2호 직접 규정 없음 | R20: GRI 305-7 | S20: 1_2_0_업종별 K-ESG 가이드라인(v2.0) 진단항목 | X20: =IF(T20="","",MAX(1,SUMPRODUCT(('02_점수산정참고표'!$A$2:$A$314=$B20)*('02_점수산정참고표'!$C$2:$C$314=T20)*'02_점수산정참고표'!$E$2:$E$314))) | Y20:  해당 항목에서 정의한 대기오염물질인 질소산화물(NOx), 황산화물(SOx), 먼지(TSP)는 환경부의 ‘사업장 대기오염물질 총량관리제도’에서 규정한 ‘관리대상 오염물질’이다. ‘사업장 대기오염물질 총량관리제도’는 사업장에 연도별로 배출허용총량을 할당하고, 이를 준수하는 사업장은 잔여 할당량을 판매할 수 있고, 이를 초과하는 사업장은 총량초과과징금을 부과한다.  대기오염물질 배출농도 및 가스유량은 ｢환경분야 시험·검사 등에 관한 법률｣ 제6조제1항에 따라 환경부장관이 정하여 고시한 환경오염공정시험기준(또는 이에 준하는 국가별 관계법령)에 따라 측정한다.  ｢대기환경보전법｣에 따른 대기오염물질 방지시설 설치 면제사업장의 경우, 동법 시행규칙 별지 제7호 서식에 따라… | AA20: NOx, SOx, 미세먼지 원단위 배출농도가 감소 추세입니까? | AB20: 단계(1~5)
A21: 20 | B21: E-7-2 | C21: 기본진단항목(v2.0) | D21: 환경 | E21: 오염물질 | F21: 수질오염물질 배출량 | G21:  조직이 소유, 관리, 통제하는 물리적 경계(사업장 등) 내에서 최종 발생하는 수질오염물질을 저감하는 등 수자원 보호를 위한 노력을 이행하고 있는지 확인  ｢물환경보전법｣ 上 수질오염물질을 대표하는 생물화학적 산소요구량(BOD), 총 유기탄소량(TOC), 부유물질량(SS)의 배출 농도를 기간별 비교하는 방식으로 점검 | H21: ‘조직별 홈페이지’ 上 지속가능경영보고서, ‘환경부-물환경정보시스템’ 上 수질측정망 | I21: 최근 4개 회계연도 | J21: 국내외 사업장 및 기타 연결실체 | K21: 수질오염물질 배출 = 생물화학적 산소요구량, 총 유기탄소량, 부유물질량의 배출농도(PPM, mg/l) | L21: 단계형 | M21: 3 | N21: 단계형: 1단계=0점 / 2단계=50점 / 3단계=100점 | O21: 1단계 | 지난 4개년 수질오염물질 평균 배출농도가 증가 추세 | 2단계 | 지난 4개년 수질오염물질 평균 배출농도가 변동 없음 | 3단계 | 지난 4개년 수질오염물질 평균 배출농도가 감소 추세 | * 수질오염물질 평균 배출농도를 관리하지 않고 있는 경우 0점 적용 | * 국내 및 해외 모든 사업장의 수질오염물질 배출농도가 ‘0’인 경우 100점 적용 | * 3개년 이하 데이터 보유 시 해당 데이터로 추세 산정 | * '유지 추세'로 판단할 경우 2단계로 적용하여 평가 | P21: GAP(대응지표 없음) | Q21: KSSB 제2호 직접 규정 없음 | R21: GRI 303-4 | S21: 1_2_0_업종별 K-ESG 가이드라인(v2.0) 진단항목 | X21: =IF(T21="","",MAX(1,SUMPRODUCT(('02_점수산정참고표'!$A$2:$A$314=$B21)*('02_점수산정참고표'!$C$2:$C$314=T21)*'02_점수산정참고표'!$E$2:$E$314))) | Y21:  해당 지표에서 정의한 수질오염물질인 생물화학적 산소요구량(BOD), 총 유기탄소량(TOC), 부유물질량(SS)은 ｢물환경보전법 시행규칙｣ 별표13 上 ‘수질오염물질의 배출허용기준’ 항목이다.  수질오염물질 배출농도는 ｢환경분야 시험·검사 등에 관한 법률｣ 제6조제1항에 따라 환경부장관이 정하여 고시한 환경오염공정시험기준(또는 이에 준하는 국가별 관계법령)에 따라 측정한다.  ｢물환경보전법｣ 제35조에 따른 수질오염물질 방지시설 면제사업장에 해당하는 경우 수질오염물질 배출 성과를 점검하지 아니할 수 있다.  조직의 수질오염물질 배출 수준을 점검하는 방식에는 1) 폐수를 방류하거나, 폐수처리시설과 관련된 수계의 평균 오염농도 대비, 2) 조직의 과거년도 배출농도를… | AA21: BOD, TOC, SS 배출농도가 감소 추세입니까? | AB21: 단계(1~5)
A22: 21 | B22: E-8-1 | C22: 기본진단항목(v2.0) | D22: 환경 | E22: 환경 법/규제 위반 | F22: 환경 법/규제 위반 | G22:  조직이 사업을 운영하는 과정에서 준수해야 할 환경 관리 법/규제를 명확하게 인식하고, 환경 법/규제 리스크 해결을 위한 투자 및 개선활동이 효과적인지 확인  환경 관련 법/규제 위반 사건 중 조직의 재무구조 및 평판 관리에 상당한 영향력을 미치는 사법상 형벌, 행정상 처분(금전적, 비금전적)에 대해 가중치를 달리 적용하는 방식으로 ‘환경 법/규제 위반’을 점검 | H22: ‘전자공시시스템’ 上 사업보고서, ‘조직별 홈페이지’ 上 지속가능경영보고서 | I22: 최근 4개 회계연도 | J22: 국내외 사업장 및 기타 연결실체 | K22: ∑(환경 법/규제 위반 건 * 처벌수위별 감점 기준) | L22: 감점형 | M22: 3 | N22: 감점형: 기준 100점에서 위반유형별(-50/-30/-10점) 차감(중복 적용 가능), 최저 0점 | O22: 유형 1 | 지난 4개년 간 환경 법/규제 위반내역 중 판결이 확정된 건수에 대해, 처벌수위가 사법상 형벌, 벌금, 과료인 경우, 또는 국가나 | 지방자치단체를 당사자로 하는 계약에서 입찰참가자격을 제한당한 경우 | 유형 2 | 지난 4개년 간 환경 법/규제 위반내역 중 판결이 확정된 건수에 대해, 처벌수위가 행정상 처분 중 금전적 처분에 해당하는 과태료, | 과징금, 이행강제금 등인 경우 | 유형 3 | 지난 4개년 간 환경 법/규제 위반내역 중 판결이 확정된 건수에 대해, 처벌수위가 행정상 처분 중 비금전적 처분에 해당하는 시정 | 명령, 시정권고, 경고 등인 경우 | * 감점 사항이 없을 경우, 감점 없음 | * 단, 처벌 및 조치내역의 발생횟수에 따른 감점 시 환경 분야의 총 평가 최저점은 0점으로 하한선 설정 | P22: 부분대응 | Q22: KSSB 제1호 문단 위험관리 원칙 준용 | R22: GRI 2-27(Compliance) | S22: 1_2_0_업종별 K-ESG 가이드라인(v2.0) 진단항목 | T22: 해당없음(감점형) | U22: 0 | V22: 0 | W22: 0 | X22: =MAX(1,100-(N(U22)*50+N(V22)*30+N(W22)*10)) | Y22:  환경 법/규제 위반행위란 오염물질 불법배출의 가중처벌, 환경보호지역 오염행위 등의 가중처벌, 과실범, 멸종위기 야생생물의 포획 등의 가중처벌, 폐기물 불법처리의 가중처벌, 누범의 가중, 명령 불이행자에 대한 처벌의 규정에 해당하는 행위나 ｢대기환경보전법｣ 비산먼지 발생을 억제하기 위한 시설 설치 혹은 조치를 하지 않은 경우, ｢화학물질 등록 및 평가 등에 관한 법률｣ 또는 ｢화학물질관리법｣ 유해화학물질을 부적절하게 관리한 경우, ｢폐기물관리법｣ 생활폐기물을 불법 처리하는 행위 등으로써 ｢환경범죄 등의 단속 및 가중처벌에 관한 법률｣ 제3조에서 제14조를 통해 처벌수위를 규정하고 있다. - 제3조 : 오염물질 불법배출의 가중처벌 - 제4조 : 환경보호지역 오염행위 등의… | AA22: 환경 관계 법령 위반 처벌 및 제재 이력이 있습니까? | AB22: 단계(1~5)
A23: 22 | B23: E-9-1 | C23: 기본진단항목(v2.0) | D23: 환경 | E23: 환경 라벨링 | F23: 친환경 인증 제품 및 서비스 비율 | G23:  제품의 생산 과정에서 자원·에너지 사용, 오염물질 배출, 인체·생태계 독성 등 환경영향을 파악하며, 제품의 긍정적 환경영향을 확대하고 부정적 환경영향은 축소하고 있는지 확인  ISO 등 국제인증표준에 준하거나, 환경부 등 정부기관에서 시행하고 있는 친환경 인증 획득 제품이 전체 제품에서 차지하는 비율을 점검 | H23: ‘전자공시시스템’ 上 사업보고서, ‘조직별 홈페이지’ 上 지속가능경영보고서 | I23: 직전 회계연도 | J23: 국내외 사업장 및 기타 연결실체 | K23: 친환경 인증 제품 및 서비스 비율 = (친환경 인증 제품 및 서비스 매출액 / 조직의 총 매출액) | L23: 단계형 | M23: 3 | N23: 단계형: 1단계=100점 / 2단계=50점 / 3단계=0점 | O23: 1단계 | 친환경 인증을 획득한 제품 및 서비스, 또는 친환경 인증 원부자재 등이 포함된 제품군의 매출비율이 증가 추세 | 2단계 | 친환경 인증을 획득한 제품 및 서비스, 또는 친환경 인증 원부자재 등이 포함된 제품군의 매출비율이 변동 없음 | 3단계 | 친환경 인증을 획득한 제품 및 서비스, 또는 친환경 인증 원부자재 등이 포함된 제품군의 매출비율이 감소 추세 | * 완성품이 아닌 원부자재 생산 업종의 경우 원부자재에 대한 친환경 인증을 기준으로 점검 | * 3개년 이하 데이터 보유 시 해당 데이터로 추세 산정 | * '유지 추세'로 판단할 경우 2단계로 적용하여 평가 | P23: 부분대응 | Q23: KSSB 제2호 문단 29(4) 친환경 기회(택소노미 부합 매출) 취지 유사 | R23: K-ESG 고유지표, K-Taxonomy | S23: 1_2_0_업종별 K-ESG 가이드라인(v2.0) 진단항목 | X23: =IF(T23="","",MAX(1,SUMPRODUCT(('02_점수산정참고표'!$A$2:$A$314=$B23)*('02_점수산정참고표'!$C$2:$C$314=T23)*'02_점수산정참고표'!$E$2:$E$314))) | Y23:  친환경 제품 및 서비스 인증은 1) 제품 및 서비스 자체의 친환경성을 확인, 2) 제품 및 서비스가 환경에 미치는 계량적 정보를 라벨링하는 것에 대해 공신력 있는 제3자기관으로부터 인증을 획득하거나 국내외 표준규격을 준용하여 조직이 자체적으로 선언하는 것을 포함한다. 친환경 제품 및 서비스 인증표준 및 관련 제도는 국가별, 지역별 또는 제품/서비스 유형별로 다양하게 도입되고 있어, 조직은 해당 산업 내 통용되는 친환경 제품 및 서비스 인증표준 및 관련 제도를 파악하고, 해당 인증을 획득한 제품 및 서비스가 차지하는 비율을 관리할 수 있다. - 해외 주요 인증 : ISO14021, ISO14024, ISO14025, CE Marking - 국내 주요 인증 : 환경마크,… | AA23: 친환경 인증 제품 및 서비스 비율을 정량적으로 산정하여 관리·공시하고 있습니까? | AB23: 단계(1~5)
A24: 23 | B24: E-10-1 | C24: 기본진단항목(v2.0) | D24: 환경 | E24: 기후변화대응 | F24: 기후변화 거버넌스 | G24:  조직 내 기후변화 이슈에 체계적이고 효과적으로 대응할 수 있는 관리·감독(기구) 구축 여부 점검  조직 내 기후변화 대응 목표가 핵심성과지표(KPIs)에 반영되어 있는지 점검하고, 이를 통해 인센티브를 제공하고 있는지 확인 | H24: ‘조직별 홈페이지’ 上 지속가능성보고서, TCFD 보고서, 기후변화 대응계획, 이사회 또는 ESG위원회(지속가능경영위원회) 조직도 및 회의록 | I24: 직전 회계연도 기준 | J24: N/A | K24: N/A | L24: 단계형 | M24: 5 | N24: 단계형: 1단계=0점 / 2단계=25점 / 3단계=50점 / 4단계=75점 / 5단계=100점 | O24: 1단계 | 기후변화 문제에 대응할 수 있는 담당자(혹은 기구)가 없음 | 2단계 | 기후변화 문제에 대응하기 위한 관리자(혹은 담당부서)가 있으며, 담당부서의 KPIs에 조직의 기후변화 대응 목표가 반영되어 | 있음 | 3단계 | 기후변화 문제에 대응하기 위한 관리직(C-level) 혹은 위원회가 있으며, 관리직의 KPIs에 조직의 기후변화 대응 목표가 반영되어 | 있음 (예 : 기후/지속가능성/ESG 최고 책임자, 리스크 관리 최고 책임자(CEO 제외) 등) | 4단계 | 3단계 + 기후 관련 문제를 이사회 차원의 위원회에서 관리·감독하고 있으며, 이사회 안건으로 상정하고 있음 | (예 : 기후/지속가능성/ESG 위원회, 리스크 관리 위원회 등) | 5단계 | 4단계 + 조직 구성원에게 기후변화 대응 목표 KPIs 달성도에 따라 인센티브를 제공하고 있음 | P24: 완전대응 | Q24: KSSB 제2호 문단 6(1),(2) — 기후 거버넌스 | R24: TCFD, GRI 2-9 | S24: 1_2_0_업종별 K-ESG 가이드라인(v2.0) 진단항목 | X24: =IF(T24="","",MAX(1,SUMPRODUCT(('02_점수산정참고표'!$A$2:$A$314=$B24)*('02_점수산정참고표'!$C$2:$C$314=T24)*'02_점수산정참고표'!$E$2:$E$314))) | Y24:  TCFD(Task Force on Climate-related Financial Disclosures)는 조직이 자사가 직면한 기후변화 관련 위험과 기회를 평가해야 하며 이로 인해 발생할 수 있는 기업의 재무적 영향과 비용, 미래의 기회 등을 평가하는 것을 권고하고 있다.  조직은 기후변화에 대응할 수 있도록 명확한 목표를 설정하고, 이에 대한 중장기적 계획을 수립하며 이를 지속적으로 책임질 수 있는 담당자(혹은 기구)를 지정해야 한다. 기후변화 위기 대응 거버넌스를 구축하여 보다 체계적이고 효과적으로 관련 활동 및 성과를 관리해야 한다.  기후변화 대응을 위한 조직 활동으로는 온실가스 감축, 재생에너지 확대, 산림보호, 폐기물 관리, 관련 교육 등이 있으며, 위… | AA24: 기후변화 대응을 위한 이사회 감독 및 구성원 KPI 연계 체계가 있습니까? | AB24: 단계(1~5)
A25: 24 | B25: E-10-2 | C25: 기본진단항목(v2.0) | D25: 환경 | E25: 기후변화대응 | F25: 기후변화 중장기 리스크 식별 | G25:  조직이 기후변화 이슈에 대응하기 위해 경영전략에 시나리오 분석을 도입해 활용하고 있는지 확인  조직의 리스크 분석 및 경영전략의 회복탄력성을 설명하기 위해 활용된 기후변화 시나리오가 ‘전환 시나리오’와 ‘물리적 시나리오’를 포함하고 있는지 확인 | H25: ‘조직별 홈페이지’ 上 지속가능경영보고서, TCFD 보고서, CDP 보고서 등 | I25: 직전 회계연도 기준 | J25: 국내외 사업장 및 기타 연결실체 | K25: N/A | L25: 복합가중형 | N25: 복합가중형: 2~3개 세부요소를 균등가중평균(예: 1/2+1/2, 1/3×3) — 세부 배점은 점검기준 상세 참조, 자사취득점수는 수동 산정 | O25: 구분1(1/2) 구분2(1/2) | 전환 시나리오 물리 시나리오 | 요건1 (50점) 전환 시나리오 1개만 적용한 경우 물리 시나리오 1개만 적용한 경우 | 요건2 (100점) 2개 이상의 전환 시나리오를 적용한 경우 2개 이상의 물리 시나리오를 적용한 경우 | ※ 기후변화 시나리오별 분석을 수행하지 않는 경우 0점 처리 | P25: 완전대응 | Q25: KSSB 제2호 문단 10 — 단기·중기·장기 위험/기회 식별 | R25: TCFD | S25: 1_2_0_업종별 K-ESG 가이드라인(v2.0) 진단항목 | T25: 해당없음(복합가중형) | Y25:  조직은 기후변화 시나리오를 통해 지구온난화에 따른 불확실한 미래 상황을 예측하고, 각 시나리오별 상황이 조직의 사업에 미치는 잠재적인 영향을 분석할 수 있다.  조직은 기후변화가 비즈니스, 전략 및 재무성과에 미치는 잠재적 영향력을 사전에 파악하기 위해 기후 시나리오 분석 방법을 적용해야 하며, CDP(Conference of the Parties) 권고에 따라 1.5℃ 이하 시나리오를 포함하는 다양한 기후 관련 시나리오를 고려해야 한다.  조직은 1.5℃ 이하 시나리오, 1.5℃ 초과 시나리오를 모두 적용하여 분석한 후 각 시나리오를 비교 분석해야 한다.  ‘녹색금융협의체(NGFS)’는 기후 시나리오를 기후변화 자체에 의한 물리적 손해인 ‘물리적… | AA25: 기후변화 중장기 리스크 식별을 정기적으로 실시하고 있습니까? | AB25: 단계(1~5)
A26: 25 | B26: E-10-3 | C26: 기본진단항목(v2.0) | D26: 환경 | E26: 기후변화대응 | F26: 기후변화 물리 리스크 및 대응 방안 | G26:  조직이 기후변화에 따라 비즈니스 운영, 전략, 수익 또는 지출에 실질적인 변화가 발생할 가능성이 있는 리스크를 식별하고 있는지 확인  물리적 기후변화(물 부족, 홍수 등)로 인한 정량적인 재무 리스크를 추정하고 소요 비용, 대응 전략, 관련 사업기회를 모색하고 있는지 점검  조직의 상황 및 수준에 따라 본 지표의 선택적 적용을 권고 | H26: ‘조직별 홈페이지’ 上 지속가능경영보고서, TCFD 보고서, CDP 보고서 등 | I26: 직전 회계연도 기준 | J26: 국내외 사업장 및 기타 연결실체 | K26: N/A | L26: 단계형 | M26: 5 | N26: 단계형: 1단계=0점 / 2단계=25점 / 3단계=50점 / 4단계=75점 / 5단계=100점 | O26: 1단계 | 조직이 기후변화로 인한 물리 리스크를 분석하지 않는 경우 | 2단계 | 조직이 기후변화로 인한 조직 전체 차원의 물리 리스크를 식별하고 정의하는 경우 | 3단계 | 2단계 + 물리 리스크로 인한 사업 영향력을 정성적으로 측정하는 경우 | 4단계 | 3단계 +물리 리스크로 인한 사업 영향력을 정량적으로 측정하여 리스크 해소한 경우 | 5단계 | 4단계 + 물리 리스크로 인해 발생할 수 있는 리스크에 대한 새로운 사업기회를 모색하는 등 기업의 회복탄력성을 수립한 경우 | * 4단계에서 리스크에 따른 사업 영향력을 정량적으로 측정할 경우, 재해보험의 위험 전가율(%) 등도 고려할 수 있음 | P26: 부분대응 | Q26: KSSB 제2호 문단 22, B1~B18 — 시나리오분석·회복력(1.5℃ 등 특정 시나리오 요건은 K-ESG에 미명시) | R26: TCFD | S26: 1_2_0_업종별 K-ESG 가이드라인(v2.0) 진단항목 | X26: =IF(T26="","",MAX(1,SUMPRODUCT(('02_점수산정참고표'!$A$2:$A$314=$B26)*('02_점수산정참고표'!$C$2:$C$314=T26)*'02_점수산정참고표'!$E$2:$E$314))) | Y26:  해당 지표는 기후변화 관련 리스크 중 특히 물리 리스크를 식별하고 이를 조치하는 프로세스가 마련되어 있는지를 확인하는 항목이다.  기후변화로 인해 발생 가능한 물리적인 리스크의 비용뿐만 아니라 이를 통해 새롭게 발생할 수 있는 신기술 개발 또는 시설 구축 등과 같은 비즈니스 기회까지 포함한다.  해당 지표에서 의미하는 물리적 기후변화 리스크는 태풍, 홍수, 물 부족 등 극한의 기상 현상으로 인해 발생 가능한 사업장 및 생산시설의 손해와 같은 재무적 손실, 이를 예방하기 위한 조치 비용, 풍수해 보험 비용 등의 추정치를 포함한다.  물리 리스크는 태풍, 집중호우 등 비교적 짧은 시간에 발생하는 단기적 리스크(급성)와 해수면 상승, 평균기온 상승 등 장기적으로… | AA26: 기후변화 물리 리스크 및 대응 방안을 파악하고 대응 방안을 마련하고 있습니까? | AB26: 단계(1~5)
A27: 26 | B27: E-10-4 | C27: 기본진단항목(v2.0) | D27: 환경 | E27: 기후변화대응 | F27: 기후변화 전환 리스크 및 대응 방안 | G27:  조직이 기후변화에 따라 비즈니스 운영, 전략, 수익 또는 지출에 실질적인 변화가 발생할 가능성이 있는 리스크를 식별하고 있는지 확인  기후변화 대응을 위해 규제에 따른 리스크(온실가스 배출권거래제, NDC 등) 발생 시 나타날 수 있는 정량적인 재무 리스크를 추정하고 소요 비용, 대응 전략, 관련 사업기회를 모색하고 있는지 점검  조직의 상황 및 수준에 따라 본 지표의 선택적 적용을 권고 | H27: ‘조직별 홈페이지’ 上 지속가능경영보고서, TCFD 보고서, CDP 보고서 등 | I27: 직전 회계연도 기준 | J27: 국내외 사업장 및 기타 연결실체 | K27: N/A | L27: 단계형 | M27: 5 | N27: 단계형: 1단계=0점 / 2단계=25점 / 3단계=50점 / 4단계=75점 / 5단계=100점 | O27: 1단계 | 조직이 기후변화로 인한 전환 리스크를 분석하지 않는 경우 | 2단계 | 조직이 기후변화로 인한 조직 전체 차원의 전환 리스크를 식별하고 정의하는 경우 | 3단계 | 2단계 + 전환 리스크로 인한 사업 영향력을 정량적으로 측정하는 경우 | 4단계 | 3단계+ 전환리스크로인한사업영향력을사업장별로측정해리스크해소에드는예상비용, 예상평균소요기간 등을분석하는경우 | 5단계 | 4단계 + 전환 리스크로 인해 발생할 수 있는 새로운 사업 기회를 모색하고 수립한 경우 | P27: 부분대응 | Q27: KSSB 제2호 문단 22, B1~B18 — 전환위험 시나리오분석(정량 재무영향 산정은 K-ESG에 미요구) | R27: TCFD | S27: 1_2_0_업종별 K-ESG 가이드라인(v2.0) 진단항목 | X27: =IF(T27="","",MAX(1,SUMPRODUCT(('02_점수산정참고표'!$A$2:$A$314=$B27)*('02_점수산정참고표'!$C$2:$C$314=T27)*'02_점수산정참고표'!$E$2:$E$314))) | Y27:  해당 지표는 기후변화 관련 리스크 중 특히 기후변화를 해결하기 위한 규제 등을 이행 시 발생할 수 있는 전환적 리스크를 식별하고 이를 조치하는 프로세스가 마련되어 있는지를 확인하는 항목이다.  기후변화로 인해 발생 가능한 전환 리스크는 기후변화와 관련된 정책, 법률, 기술 및 시장 변화 등 광범위한 분야에 걸쳐 존재하며 이는 변화의 특성, 속도에 따라 조직의 재무 및 조직에 대한 소비자 평판 등에 영향을 줄 수 있다.  파리협정 장기 온도목표 달성을 위해 각 국가가 자발적으로 제출한 온실가스 감축 목표제(NDC) 이행에 필요한 배출권거래제, 연비규제, 에너지 관련 법안 등 정책적 리스크가 이에 포함된다.  TCFD는 조직에 잠재적인 영향을 미칠 수 있는 전환… | AA27: 기후변화 전환 리스크 및 대응 방안을 파악하고 대응 방안을 마련하고 있습니까? | AB27: 단계(1~5)
A28: 27 | B28: E-10-5 | C28: 기본진단항목(v2.0) | D28: 환경 | E28: 기후변화대응 | F28: 온실가스 배출량 감축 선언 | G28:  국가온실가스감축목표(NDC)에 따른 국내 2030년 온실가스 감축 목표(2018년 수준 대비 40% 감축)를 고려하여, 조직이 온실가스 배출량 감축 목표를 설정하고 있는지 여부 확인 | H28: ‘조직별 홈페이지’ 上 지속가능경영보고서, TCFD 보고서, CDP 보고서, Net-zero선언문, 기타 기후관련 이니셔티브 가입 선언 등 | I28: 직전 회계연도 기준 | J28: 국내외 사업장 및 기타 연결실체 | K28: (구분1 + 구분2) * 1/2 | L28: 복합가중형 | N28: 복합가중형: 2~3개 세부요소를 균등가중평균(예: 1/2+1/2, 1/3×3) — 세부 배점은 점검기준 상세 참조, 자사취득점수는 수동 산정 | O28: 구분1(1/2) 구분2(1/2) | 조직이 온실가스 배출 감축 선언(Commitment)을 조직이 사업장 내에서 배출하는 온실가스 배출량에 | 요건1 | 하고 이를 공개하는 경우 대해 파악하고 있는 경우 | 조직이 온실가스 배출량 감축을 위한 기준연도와 조직이 공급망에서 배출하는 온실가스 배출량을 | 요건2 | 목표연도, 감축 범위를 설정한 경우 관리하고 있는 경우 | 조직이 온실가스 배출량 감축을 위해 중간목표를 Scope1, 2 영역의 구체적인 온실가스 감축 | 요건3 | 포함한 중장기 로드맵을 가지고 있는 경우 프로그램을 이행하는 경우 | 조직이 온실가스 배출량 감축을 위한 구체적인 감축 Scope3 영역을 포함한 구체적인 온실가스 감축 | 요건4 | 계획을 수립한 경우 프로그램을 이행하는 경우 | 조직의 온실가스 감축 목표를 SBTi 등 과학적 기반으로 탄소제거 인증 프레임워크에 따라 인증된 탄소배출 | 요건5 | 검증받고 있는 경우 상쇄(Carbon offset) 계획을 수립한 경우 | ※ 온실가스 배출 감축선언을 하지 않은 경우, 사업장 내 온실가스 배출량을 관리하지 않는 경우 0점 처리 | P28: 완전대응 | Q28: KSSB 제2호 문단 33~36 — 감축목표·SBTi 정합 | R28: GRI 305-5, SBTi | S28: 1_2_0_업종별 K-ESG 가이드라인(v2.0) 진단항목 | T28: 해당없음(복합가중형) | Y28:  본 항목은 조직이 온실가스 배출량 감축 목표 설정 및 이를 공약하는지 여부와 이를 달성하기 위해 어떤 활동을 하고 있는지를 점검한다.  파리 협약에 따라 조직은 산업화 이전 수준보다 지구 온도 상승을 1.5°C로 제한한다는 목표에 맞게 비즈니스 활동 조정 등 온실가스 배출 감축을 위한 노력을 다해야 한다.  조직의 온실가스 배출 감소 전략은 사업장 내, 혹은 공급망에 이르기까지, Scope1,2 및 Scope3를 관리 할 수 있으며, 탄소 배출량 ‘0’ 또는 1.5°C 조정 경로에서 순배출량 ‘0’에 도달하는 것과 일치하는 수준으로 달성 목표를 설정하여야 한다.  조직의 온실가스 배출량 감축 목표연도는 파리협약에 따른 2050년 혹은 그 이전으로 설정해야 하며,… | AA28: 온실가스 배출량 감축 선언을 대내외에 공식적으로 선언·발표하였습니까? | AB28: 단계(1~5)
A29: 28 | B29: E-11-1 | C29: 기본진단항목(v2.0) | D29: 환경 | E29: 생물다양성 | F29: 자연자본 식별 | G29:  조직이 자체적으로 사업이 환경에 미치는 부정적 영향을 제거하거나 최소화하기 위해 사전에 자연자본을 분석 및 검토하고 있는지 확인  자연자본을 식별하는 활동을 바탕으로 특정 생물종 및 개체수에 미치는 영향을 파악하고 있는지 점검  조직의 평가 및 이행점검 체계 구축 수준에 따라 본 지표의 선택적 적용을 권고 | H29: ‘조직별 홈페이지’ 上 지속가능경영보고서, TNFD 보고서 등 | I29: 직전 회계연도 기준 | J29: N/A | K29: N/A | L29: 단계형 | M29: 5 | N29: 단계형: 1단계=0점 / 2단계=25점 / 3단계=50점 / 4단계=75점 / 5단계=100점 | O29: 1단계 | 조직이 위치한 사업장의 자연자본을 식별하고 있지 않은 경우 | 2단계 | 조직이 위치한 사업장의 자연자본을 식별할 계획을 수립한 경우 | 3단계 | 조직이 위치한 일부 사업장의 자연자본을 식별하고 있는 경우 | 4단계 | 조직이 위치한 전체 사업장의 자연자본을 식별하고 있는 경우 | 5단계 | 대외적으로 식별된 자연자본을 공개하고 있는 경우 | P29: 부분대응 | Q29: KSSB 제1호 문단 IG26~IG27(예시지침, 생물다양성은 별도 기준서 미제정) | R29: TNFD 권고안, GRI 304 | S29: 1_2_0_업종별 K-ESG 가이드라인(v2.0) 진단항목 | X29: =IF(T29="","",MAX(1,SUMPRODUCT(('02_점수산정참고표'!$A$2:$A$314=$B29)*('02_점수산정참고표'!$C$2:$C$314=T29)*'02_점수산정참고표'!$E$2:$E$314))) | Y29:  자연자본은 인류에게 상품 및 서비스를 제공하는 식물, 동물, 대기, 물, 토양, 광물 등의 모든 유형자원을 포괄하는 개념으로 자연환경 요소로 구성된 자본 또는 자산(Stock)을 의미한다. 이는 사회와 기업이 기능하기 위해 자연자본에 어떻게 의존하는지를 경제적 관점으로 바라보는 것을 의미한다.  자연자본의 필수 구성 요소 중 하나인 생물다양성은 유전적, 종적 그리고 생태계 수준에서 살아있는 모든 유기체들의 다양성을 의미한다. 특히, 세계자연기금(WWF)은 2022년 지구생명 보고서(Living Planet Report)에서 전세계 포유류, 조류, 어류 등의 변화를 추적하는 지표인 지구생명지수(LPI)를 통해 지난 50년간 야생동물 개체군 규모가 69% 감소했다고… | AA29: 자연환경 자산, 멸종위기종 노출 리스크 등을 식별/공개합니까? | AB29: 단계(1~5)
A30: 29 | B30: E-11-2 | C30: 기본진단항목(v2.0) | D30: 환경 | E30: 생물다양성 | F30: 생물다양성 보존 전략 | G30:  조직의 사업 운영 전반에서 발생 가능한 생물다양성 관련 리스크를 점검하고, 지역사회의 생물다양성을 보전, 복원, 확대하기 위한 조직의 접근 방식 확인  조직의 생물다양성 분야 단기/중장기 목표 및 생물다양성 보전, 복원, 확대를 위한 계획의 구체성과 내재화 수준 점검 | H30: 생물다양성 보호 접근 방식 | I30: 직전 회계연도 기준 | J30: N/A | K30: N/A | L30: 선택형 | M30: 5 | N30: 선택형: 요건1=0점 / 요건2=25점 / 요건3=50점 / 요건4=75점 / 요건5=100점 | O30: 분류 접근방식 | - 생물다양성 영향이 높은 지역 내 사업장 신축, 증설 제한 또는 보류 | 요건1 회피(Avoid) | - 부정적 영향이 확인된 경우, 이를 상쇄하기까지 제한적 운영 | - 대기, 수질, 토양 오염물질 배출을 제거 및 최소화하도록 설비 투자 | 요건2 저감(Reduce) | - 환경오염물질 저감 기술 개발 | - 사업장 주변 또는 인근 지역의 감소 또는 멸종된 생물종, 개체수 증진 | 요건3 복원(Restore) | - 생물종 및 개체수 유지·복원을 위한 (대체)서식지 조성 노력 | - 사업장 주변 이외 자연·생물 자본 증진 및 생산성 향상에 기여 | 요건4 재생(Regenerate) | - 산림, 해양, 토양 환경 개선을 통한 생물종 및 개체수 증대 유도 | - 생물다양성에 영향이 없도록 사업장 또는 주변 지형 구조적 개선 | 요건5 변경(Transform) | - 부정적 환경영향 개선을 위한 정책 입안 참여 및 산업계 협력 | P30: 부분대응 | Q30: KSSB 생물다양성 별도 기준서 미제정 | R30: TNFD, GRI 304 | S30: 1_2_0_업종별 K-ESG 가이드라인(v2.0) 진단항목 | X30: =IF(T30="","",MAX(1,SUMPRODUCT(('02_점수산정참고표'!$A$2:$A$314=$B30)*('02_점수산정참고표'!$C$2:$C$314=T30)*'02_점수산정참고표'!$E$2:$E$314))) | Y30:  TNFD(Task force on Nature-related Financial Disclosures)는 조직이 생물다양성 감소, 자연파괴, 자연재해 등 자연의 변화로 인해 겪을 수 있는 금융적 리스크를 점검 및 평가하고, 이를 고객, 투자자 등 이해관계자들에게 투명하게 보고하도록 요구하고 있다.  조직은 사업 운영 전반에서 발생할 수 있는 생물다양성 저해 및 손실 리스크를 점검하고, 지역사회의 생물다양성 보전, 복원, 확대를 위해 노력해야 한다.  조직은 사업장 및 인근 지역의 생물다양성 보전, 복원, 확대를 위해 다음과 같은 접근방식을 취할 수 있으며 해당 접근방식에 기초해 생물다양성 분야에서 단기/중장기 목표를 구체적으로 수립해야 한다. ; 1)… | AA30: 회피/저감/복원/재생/변경의 생물다양성 보호 전략을 실천합니까? | AB30: 단계(1~5)
A31: 30 | B31: E-11-3 | C31: 기본진단항목(v2.0) | D31: 환경 | E31: 생물다양성 | F31: 산림보호 활동 | G31:  조직의 사업 운영 전반에서 발생 가능한 산림파괴를 예방하고 지역사회의 산림을 보호하기 위한 조직의 접근 방식 확인  조직이 이행하고 있는 산림보호 단기/중장기 목표와 산림보호 및 복원을 위한 계획에 대한 구체성 및 내재화 수준 점검  조직별 사업 연관성에 따라 본 지표의 선택적 적용을 권고 | H31: 산림보호 활동 관련 자료 | I31: 직전 회계연도 기준 | J31: N/A | K31: N/A | L31: 선택형 | M31: 5 | N31: 선택형: 요건1=0점 / 요건2=25점 / 요건3=50점 / 요건4=75점 / 요건5=100점 | O31: 요건1 | 산림보호 혹은 산림파괴 예방 정책을 수립한 경우 | (사업 운영 전반에서 발생하는 산림파괴 리스크 관리 및 산림파괴 예방 등) | 요건2 | 사업 활동으로 인해 영향을 받는 지역을 조사하고 주요 보호지역을 정의한 경우 | (산림이 제공하는 경관 및 지형학/지질학적 특성, 산림에 서식하는 생물다양성 등) | 요건3 | 산림보호를 위해 전사 차원의 목표를 수립한 경우 | (산림파괴 없는 사업 운영 구조 완성, 탄소상쇄 활동(REDD+ 등)에 대한 성과개선 목표 설정 등) | 요건4 | 산림보호를 위한 단기/중장기 목표 수립 및 연도별 이행 현황을 파악하고 있는 경우 | (중장기 산림 보호-복원-확대 목표 이행 현황 및 목표 대비 이행률 점검 등) | 요건5 | 산림보호를 위해 이해관계자로부터 의견을 수렴하고 관련 성과를 공유하는 경우 | (산림 보호 활동 및 성과 공유, 외부 전문기관 및 비영리기관 등과 협력체계 구축 등) | P31: GAP(대응지표 없음) | Q31: KSSB 생물다양성 별도 기준서 미제정 | R31: GRI 304 | S31: 1_2_0_업종별 K-ESG 가이드라인(v2.0) 진단항목 | X31: =IF(T31="","",MAX(1,SUMPRODUCT(('02_점수산정참고표'!$A$2:$A$314=$B31)*('02_점수산정참고표'!$C$2:$C$314=T31)*'02_점수산정참고표'!$E$2:$E$314))) | Y31:  조직은 산림보호 활동을 통해 사업장 및 인근 지역의 녹지면적을 유지/보호할 뿐만 아니라 지역사회 산림 전용 및 황폐화 방지, 산림 보전, 산림 탄소 흡수량 증진에 기여해야 한다.  조직은 산림보호 및 산림파괴 예방을 위해 아래와 같은 활동을 추진할 수 있다. ; 1) 산림보호 또는 산림파괴 예방정책을 수립해 사업 운영 전반에서 발생 가능한 산림파괴를 예방하고, 공급업체 및 협력사 등 거래관계에 있는 이해관계자에게 해당 정책을 따를 것을 권장한다. 2) 산림이 제공하는 경관 및 지형학/지질학적 특성, 산림에 서식하는 생물다양성의 구성/역할/잠재력, 기타 산림의 역사적/문화적/과학적/교육적 중요성을 종합적으로 고려해 주요 보호지역을 정의한다. 이때, 보호지역은… | AA31: 산림파괴 리스크 관리 및 탄소상쇄(REDD+) 목표/실적이 있습니까? | AB31: 단계(1~5)
A32: 31 | B32: S-1-1 | C32: 기본진단항목(v2.0) | D32: 사회 | E32: 목표 | F32: 목표 수립 및 공시 | G32:  조직이 중요하게 생각하는 사회분야의 이슈에 대하여, 재무적 가치와 사회적 가치의 균형점을 찾는 구체적인 목표를 설정하고, 이를 달성하기 위한 노력을 하는지 확인  ESG(지속가능경영)보고서를 통해 도출된 중요한 사회분야 이슈에 대해서 정성/정량적인 목표를 투자자, 고객 등 이해관계자 에게 공개하고 있는지 점검 | H32: ESG(지속가능경영)보고서 내 핵심토픽 리스트 핵심토픽 단기/중장기 성과목표 공시데이터(정성/정량) 핵심토픽 단기/중장기 이행현황 공시데이터(정성/정량) | I32: 직전 회계연도 | J32: 국내 및 해외 사업장 | K32: N/A | L32: 단계형 | M32: 5 | N32: 단계형: 1단계=0점 / 2단계=25점 / 3단계=50점 / 4단계=75점 / 5단계=100점 | O32: 1단계 | 단기/중장기 성과목표 또는 조직의 사회 분야 추진 방향성을 나타내는 사회분야 경영 미션/비전/지향점이 없는 경우 | 2단계 | 단기/중장기 성과목표는 수립되지 않았으나, 조직의 사회 분야 추진 방향성을 나타내는 사회분야 미션/비전/지향점을 제시하고 | 있는 경우 | 3단계 | 조직의 사회분야 핵심이슈에 대한 단기 목표를 설정하고 있는 경우 | 4단계 | 조직의 사회분야 핵심이슈에 대한 중장기 목표를 설정하고 있으나, 모든 중장기 목표가 정성적 형태로 되어 있는 경우 | 5단계 | 조직의 사회분야 핵심이슈에 대한 중장기 목표를 설정하고 있으며, 중장기 목표에는 정성 外 정량적 목표를 포함하고 있는 경우 | P32: 부분대응 | Q32: KSSB 제1호 문단 51(지표 및 목표) | R32: GRI 3 | S32: 1_2_0_업종별 K-ESG 가이드라인(v2.0) 진단항목 | X32: =IF(T32="","",MAX(1,SUMPRODUCT(('02_점수산정참고표'!$A$2:$A$314=$B32)*('02_점수산정참고표'!$C$2:$C$314=T32)*'02_점수산정참고표'!$E$2:$E$314))) | Y32:  조직은 중대성 평가(Materiality Test)를 통해 조직의 사업운영 및 외부환경에 중요한 영향력을 행사하는 핵심이슈를 도출할 수 있다. 조직은 사업운영에 해당하는 모든 직/간접 사회 분야 규제를 관리해야 함과 동시에 사업성과와 연계된 핵심이슈에 대해서는 목표에 의한 성과관리(MBO)가 필요하다. 조직이 수립할 수 있는 사회 분야 목표와 관련된 핵심이슈는 아래와 같다. 인권 리스크 저감 구성원 다양성 증진 차별 및 괴롭힘 방지 산업재해율 저감 협력사 ESG 지원 동반성장 및 상생협력 지역사회 투자 확대 개인정보 유출 최소화 소비자 정보 제공 제품 품질 및 안전 증진  목표는 조직이 의도적으로 달성하고자 하는 상태를 말하며, 조직의 성과와 관련된 작업행동의… | AA32: 사회 분야 핵심이슈에 대해 중장기 정성/정량 목표를 설정/공시합니까? | AB32: 단계(1~5)
A33: 32 | B33: S-2-1 | C33: 기본진단항목(v2.0) | D33: 사회 | E33: 노동 | F33: 신규 채용 및 고용 유지 | G33:  조직이 신규 채용을 통해 지속적 성장에 필요한 인적자본을 축적함과 동시에, 지역사회의 일자리 창출, 고용안정성 증대에 기여하고 있는지 확인  조직이 창출한 부가가치를 채용에 투자하고 있는지, 조직의 고용 규모가 안정적인지 점검 | H33: ‘전자공시시스템’ 上 사업보고서, ‘조직별 홈페이지’ 上 지속가능경영보고서 | I33: 최근 4개 회계연도 | J33: 국내 및 해외 사업장 | K33: ① 신규 채용 지수 = (당해년도 신규 채용 인원 / 전년도 신규 채용 인원) / (당해년도 부가가치 / 전년도 부가가치) * 부가가치 = 영업손익 + 대손상각비 + 인건비 + 순금융비용 + 조세공과 + 감가상각비 ② 고용 규모 = 당해연도 총 인원 – 전년도 총 인원 * CAGR(연평균 증가율) 산식(4개년) : (최종 값 / 초기 값)∧(1/4) - 1 | L33: 복합가중형 | N33: 복합가중형: 2~3개 세부요소를 균등가중평균(예: 1/2+1/2, 1/3×3) — 세부 배점은 점검기준 상세 참조, 자사취득점수는 수동 산정 | O33: 추세(1/2) | 1단계 | 직전 1개년도 ‘신규 채용 지수’가 최근 3년 지수 평균 값 미만 | 2단계 | 직전 1개년도 ‘신규 채용 지수’가 최근 3년 지수 평균 값 동일 | 3단계 | 직전 1개년도 ‘신규 채용 지수’가 최근 3년 지수 평균 값 초과 | 추세(1/2) | 1단계 | 직전 4개년 연평균(CAGR)적으로 ‘고용 규모’가 감소 | 2단계 | 직전 4개년 연평균(CAGR)적으로 ‘고용 규모’가 유지 | 3단계 | 직전 4개년 연평균(CAGR)적으로 ‘고용 규모’가 증가 | * 3개년 이하 데이터 보유 시 해당 데이터로 추세 산정 | P33: GAP(대응지표 없음) | Q33: KSSB 인적자원 지표 미규정 | R33: GRI 401-1 | S33: 1_2_0_업종별 K-ESG 가이드라인(v2.0) 진단항목 | T33: 해당없음(복합가중형) | Y33:  신규채용은 지역사회의 일자리 창출, 고용안정성 증대 등 사회의 지속가능성 향상을 위해 필요한 요소이지만 조직이 속해있는 산업의 특성, 조직 규모 등 다양한 외부 환경을 고려할 때 무조건적인 신규채용 확대를 바람직하다고 이야기 할 수는 없을 것이다. 따라서 본 항목에서는 조직의 부가가치 창출 현황과 신규채용 인원을 통해 상대적인 신규채용 수준을 확인하고자 설계되었다.  본 항목에서의 신규채용이란 조직이 필요에 따라 구직자의 채용서류 심사 등을 기반으로 새로운 근무 인력을 채용하는 것을 의미한다. 여기서 새로운 인력이란 통계청의 경제활동인구조사 근로형태 중 비정규직 형태(한시적 근로자 또는 기간제 근로자, 단시간 근로자, 파견·용역·호출 등의 형태로 종사하는 근로자… | AA33: 부가가치 창출 대비 신규채용 지수 및 고용 규모(총인원)가 4개년 간 증가 추세입니까? | AB33: 단계(1~5)
A34: 33 | B34: S-2-2 | C34: 기본진단항목(v2.0) | D34: 사회 | E34: 노동 | F34: 정규직 비율 | G34:  정규직 근로자의 비율 확대가 조직과 사회의 지속가능성에 긍정적 영향을 미친다는 가정 하에 조직이 정규직 확대를 통해 지역 사회의 고용안정성 증가와 비정규직 근로자 문제에 기여하고 있는 정도를 확인  조직의 전체 인력 대비 정규직 비율을 점검 | H34: ‘전자공시시스템’ 上 사업보고서, ‘조직별 홈페이지’ 上 지속가능경영보고서 | I34: 최근 4개 회계연도 | J34: 국내 및 해외 사업장 | K34: 정규직 비율 = (해당연도말기준총근로자수– 한시적근로자또는기간제근로자– 단시간근로자– 파견·용역·호출 등의 형태로 종사하는 근로자 ) / 해당연도 말 기준 총 근로자 수 | L34: 단계형 | M34: 5 | N34: 단계형: 1단계=0점 / 2단계=25점 / 3단계=50점 / 4단계=75점 / 5단계=100점 | O34: 1단계 | 최근 4개년 간 정규직 비율 데이터가 관리되지 않는 경우 | 2단계 | 조직의 정규직 비율이 40%인 이하인 경우 | 3단계 | 조직의 정규직 비율이 40% 초과 60% 이하인 경우 | 4단계 | 조직의 정규직 비율이 60% 초과 80% 이하인 경우 | 5단계 | 조직의 정규직 비율이 80%를 초과하는 경우 | * 3개년 이하 데이터 보유 시 해당 데이터로 추세 산정 | P34: GAP(대응지표 없음) | Q34: KSSB 인적자원 지표 미규정 | R34: GRI 2-7 | S34: 1_2_0_업종별 K-ESG 가이드라인(v2.0) 진단항목 | X34: =IF(T34="","",MAX(1,SUMPRODUCT(('02_점수산정참고표'!$A$2:$A$314=$B34)*('02_점수산정참고표'!$C$2:$C$314=T34)*'02_점수산정참고표'!$E$2:$E$314))) | Y34:  본 항목에서 사용하는 정규직의 정의는 통계청 경제활동인구조사 근로형태에 따라 1) 한시적 근로자, 2) 시간제 근로자, 3) 비전형 근로자(파견·용역 등) 등 비정규직을 제외한 기간의 정함이 없는 임금근로자를 통칭한다.  조직은 경영의 유연성을 위해 비정규직 근로자를 채용하여 활용할 수 있으나 비정규직 근로자의 고용불안과 함께 근로조건의 차별과 같은 사회적 문제가 지속해서 발생하며, 비정규직 근로자 문제 해결을 요구하는 사회적 목소리가 커지고 있다. 통계청의 경제활동인구조사 결과 2023년 기준 국내 비정규직 근로자 비율은 37% 지난 5년간 상승하는 추세에 있는 반면 비정규직 근로자의 근속기간은 정규직 근로자에 비해 상대적으로 짧은 것으로 나타나고 있다. 정규직… | AA34: 파견, 일용직 등을 제외한 기간의 정함이 없는 정규직 비율이 충분합니까? | AB34: 단계(1~5)
A35: 34 | B35: S-2-3 | C35: 기본진단항목(v2.0) | D35: 사회 | E35: 노동 | F35: 자발적 이직률 | G35:  조직의 인적자원 관리 수준이 적정한 수준을 유지하며 관리되고 있는지 확인  구성원이 자발적으로 조직을 이동함을 의미하는 자발적 이직의 비율을 점검(산업적 특성 반영) | H35: ‘전자공시시스템’ 上 사업보고서, ‘조직별 홈페이지’ 上 지속가능경영보고서 | I35: 최근 4개 회계연도 | J35: 국내 및 해외 사업장 | K35: 자발적 퇴사(이직)율 = 해당연도 총 자발적 퇴사자(이직자) 수 / 해당연도 말 총 직원 수 | L35: 단계형 | M35: 3 | N35: 단계형: 1단계=0점 / 2단계=50점 / 3단계=100점 | O35: 1단계 | 지난 4개년 자발적 이직률이 증가 추세 | 2단계 | 지난 4개년 자발적 이직률이 변동 없음 | 3단계 | 지난 4개년 자발적 이직률이 감소 추세 | * 자발적 이직률 데이터를 관리하지 않고 있는 경우 0점 적용 | * ‘유지 추세’로 판단할 경우 2단계로 적용하여 평가 | * 3개년 이하 데이터 보유 시 해당 데이터로 추세 산정 | P35: GAP(대응지표 없음) | Q35: KSSB 인적자원 지표 미규정 | R35: GRI 401-1 | S35: 1_2_0_업종별 K-ESG 가이드라인(v2.0) 진단항목 | X35: =IF(T35="","",MAX(1,SUMPRODUCT(('02_점수산정참고표'!$A$2:$A$314=$B35)*('02_점수산정참고표'!$C$2:$C$314=T35)*'02_점수산정참고표'!$E$2:$E$314))) | Y35:  이직(퇴사)은 조직의 인적자원에 대한 변화를 초래함으로써 생산성에 영향을 미칠 수 있다. 또한, 이직은 조직의 인건비 지출 감소나 이직으로 인한 채용 등 비용과도 직접적인 관련을 가진다. 이직률은 근로자가 느끼는 불확실성과 불만족의 정도나 기업 구조의 근본적인 변화를 나타내는 지표로써 활용될 수 있다.  근로자의 이직(퇴사)은 자발적 또는 비자발적 경우로 구분할 수 있으며, 비자발적인 경우는 고용계약 종료, 구조조정이나 합병 및 해고 등에 따른 면직, 정년퇴직, 사망 등 근로자의 의사와 무관하게 진행되는 이직(퇴사)을 통칭한다.  본 항목은 조직의 직전 1개년도 ‘동종산업 평균퇴사(이직)율’을 활용하여 4개년 간의 이직률 추세를 함께 점검함으로써 조직의 상대적인… | AA35: 인적자원 관리 수준을 대변하는 자발적 이직률이 최근 4개년 간 감소 추세입니까? | AB35: 단계(1~5)
A36: 35 | B36: S-2-4 | C36: 기본진단항목(v2.0) | D36: 사회 | E36: 노동 | F36: 교육훈련비 | G36:  조직이 미래 경쟁력 및 지속가능성 확보를 위해 구성원의 교육 및 훈련에 얼마나 투자하고 있는지 확인  상대적 비교가능성이 높은 ‘원단위’ 개념을 적용하여 인적자본 관리 기본 진단항목인 구성원 수 기반의 1인당 교육훈련비를 점검. 최근 5개 회계연도의 1인당 교육훈련비 추세를 함께 고려 | H36: ‘전자공시시스템’ 上 사업보고서, ‘조직별 홈페이지’ 上 지속가능경영보고서 | I36: 최근 4개 회계연도 | J36: 국내 사업장 | K36: 1인당 교육훈련비 = 직전 1개년도 교육훈련 지출 비용 / 해당연도 말 총 구성원 수 | L36: 단계형 | M36: 3 | N36: 단계형: 1단계=0점 / 2단계=50점 / 3단계=100점 | O36: 1단계 | 지난 4개년 1인당 교육훈련비 감소 추세 | 2단계 | 지난 4개년 1인당 교육훈련비 변동 없음 | 3단계 | 지난 4개년 1인당 교육훈련비 증가 추세 | * 최근 4개년 간 교육훈련비가 없거나, 1인당 교육훈련비 데이터가 관리되지 않는 경우 0점 적용 | * ‘유지 추세’로 판단할 경우 2단계로 적용하여 평가 | * 3개년 이하 데이터 보유 시 해당 데이터로 추세 산정 | P36: GAP(대응지표 없음) | Q36: KSSB 인적자원 지표 미규정 | R36: GRI 404-1 | S36: 1_2_0_업종별 K-ESG 가이드라인(v2.0) 진단항목 | X36: =IF(T36="","",MAX(1,SUMPRODUCT(('02_점수산정참고표'!$A$2:$A$314=$B36)*('02_점수산정참고표'!$C$2:$C$314=T36)*'02_점수산정참고표'!$E$2:$E$314))) | Y36:  조직은 교육 및 훈련을 통해 업무 수행에 필요한 기술, 지식 등 구성원의 역량을 강화할 수 있으며, 이러한 교육훈련의 성과는 조직의 몰입도에 긍정적인 영향을 미치고 생산성 향상에 기여함으로써 미래 시장 경쟁력을 높이게 한다. 조직은 단기적인 이익창출과 교육훈련을 통한 장기적 성과 회수 사이의 괴리로 인해 구성원의 교육훈련에 소극적이고 수동적인 자세를 보일 수 있지만 장기적 관점의 경영성과 창출과 지속가능성 확보에 더욱 초점을 맞추는 것이 바람직하다.  교육훈련비는 조직의 미래 경쟁력, 지속가능경영 역량을 인적자원 측면에서 확인할 수 있는 항목으로, 조직의 총 구성원 수 대비 교육훈련 지출 비용을 비교하는 방식이 일반적이다. 다만, 조직의 규모, R&D 투자 필요성… | AA36: 1인당 평균 교육훈련 비용이 최근 4개년 간 증가 추세입니까? | AB36: 단계(1~5)
A37: 36 | B37: S-2-5 | C37: 기본진단항목(v2.0) | D37: 사회 | E37: 노동 | F37: 복리후생비 | G37:  조직이 임직원의 업무환경 및 근무조건 개선을 통해 직원 만족도를 높이고 있는지를 점검하는 항목으로 법률상 강제성이 있는 법정 복리후생비를 제외한 조직별 복리후생비를 확인  상대적 비교가능성이 높은 ‘원단위’ 개념을 적용하여 인적자본 관리 기본 진단항목인 구성원 수 기반의 1인당 복리후생비를 점검 (최근 4개 회계연도의 1인당 복리후생비 추세 고려) | H37: ‘전자공시시스템’ 上 사업보고서, ‘조직별 홈페이지’ 上 지속가능경영보고서 | I37: 최근 4개 회계연도 | J37: 국내 사업장 | K37: 1인당 복리후생비 = 직전 1개년도 복리후생비 / 직전 1개년도 말 총 구성원 수 | L37: 단계형 | M37: 3 | N37: 단계형: 1단계=0점 / 2단계=50점 / 3단계=100점 | O37: 1단계 | 지난 4개년 1인당 복리후생비 감소 추세 | 2단계 | 지난 4개년 1인당 복리후생비 변동 없음 | 3단계 | 지난 4개년 1인당 복리후생비 증가 추세 | * 최근 4개년 간 1인당 복리후생비 정보 없는 경우 0점 적용 | * ‘유지 추세’로 판단할 경우 2단계로 적용하여 평가 | * 3개년 이하 데이터 보유 시 해당 데이터로 추세 산정 | P37: GAP(대응지표 없음) | Q37: KSSB 인적자원 지표 미규정 | R37: GRI 401-2 | S37: 1_2_0_업종별 K-ESG 가이드라인(v2.0) 진단항목 | X37: =IF(T37="","",MAX(1,SUMPRODUCT(('02_점수산정참고표'!$A$2:$A$314=$B37)*('02_점수산정참고표'!$C$2:$C$314=T37)*'02_점수산정참고표'!$E$2:$E$314))) | Y37:  복리후생은 조직이 구성원에게 제공하는 대표적인 비임금성 보상으로 기업복지, 근로복지 등 다양한 용어로 사용되고 있다. 최근에는 소위 ‘워라밸’(Work and Life Balance)로 불리는 일과 삶의 균형, 일과 가정의 양립 등이 중요한 사회적 이슈로 떠오르고, 복리후생이 구직자가 조직을 선택하는 중요한 기준의 하나로 자리 잡는 등 노동과 복리후생에 대한 사회의 시각이 빠르게 변화하고 있다. 이러한 복리후생은 구성원의 만족도, 핵심 인재의 확보와 유지 및 조직의 몰입도와 성과 향상 등에 영향을 미침에 따라 조직들은 효과적인 복리후생 프로그램을 운영하기 위한 노력을 기울일 필요가 있다.  복리후생은 법률로 명시되어 강제성이 부여된 법정 복리후생과 그 외의… | AA37: 법정 외 1인당 복리후생비 지출이 최근 4개년 간 증가 추세입니까? | AB37: 단계(1~5)
A38: 37 | B38: S-2-6 | C38: 기본진단항목(v2.0) | D38: 사회 | E38: 노동 | F38: 결사의 자유 보장 | G38:  조직의 직원이 유엔 세계인권선언 제20조에서 제시하는 결사의 자유를 보장받을 수 있는지, 근로자 이해대변 및 협력적 노사관계 형성·유지를 위한 협의기구가 있는지 확인 - (결사의 자유 보장) 근로자가 주체가 되어 자주적으로 단결하여 근로조건의 유지·개선 기타 근로자의 경제적·사회적 지위의 향상을 도모함을 목적으로 조직하는 노동조합의 설립 및 정당한 노동조합 활동을 보장하고 있는지를 점검 - (노사협력) 아울러 ｢근로자참여 및 협력증진에 관한 법률｣에 따른 노사 협의기구인 노사협의회의 설치 및 실질적인 운영을 통한 노사 파트너십 수준을 점검 | H38: '전자공시시스템' 上 사업보고서, '조직별 홈페이지' 上 지속가능경영보고서 | I38: 최근 3개 회계연도(단, 노동조합 가입·설립 또는 노사협의회 설치 시점이 3개 회계연도 이내인 경우에는 그 기간) | J38: 국내 사업장 | K38: N/A | L38: 단계형 | M38: 5 | N38: 단계형: 1단계=0점 / 2단계=25점 / 3단계=50점 / 4단계=75점 / 5단계=100점 | O38: ※ 노동조합 가입·설립 정보가 없는 경우에는 노사협의회 설치·운영 부분을 대체지표로 사용 | 1단계 | 노동조합 가입‧설립, 노사협의회 설치 관련 정보가 모두 없음 | (노조 가입‧신설 관련 부당노동행위로 노동위 판정 또는 법원 판결이 유죄로 확정된 경우) | 2단계 | 노동조합 가입‧설립 또는 상시근로자 30인 이상인 경우 노사협의회 설치(위원 선임, 협의회규정 제정 등) | 3단계 | 2단계 + 과거 또는 현재 적법한 교섭당사자로서의 노동조합과 단체교섭 진행 + 3개월마다 노사협의회 정기회의 개최 | (회의록 작성·비치) | 4단계 | 3단계 + 노동조합과 단체협약(임금협약 포함) 체결 | + 노사협의회 정기회의 외 추가 임시회의(노사 실무협의 포함) 개최 | 5단계 | 4단계 + 체결된 단체협약의 성실한 이행(단체협약 위반 시 불이행으로 간주) + 노사협의회 의결(합의) 여부 | P38: GAP(대응지표 없음) | Q38: KSSB 인적자원 지표 미규정 | R38: GRI 407 | S38: 1_2_0_업종별 K-ESG 가이드라인(v2.0) 진단항목 | X38: =IF(T38="","",MAX(1,SUMPRODUCT(('02_점수산정참고표'!$A$2:$A$314=$B38)*('02_점수산정참고표'!$C$2:$C$314=T38)*'02_점수산정참고표'!$E$2:$E$314))) | Y38:  근로자는 자유로이 노동조합을 조직하거나 이에 가입할 수 있고 가입 형태에 따라 오픈숍(Open Shop)과 유니온숍(Union Shop)의 경우가 있으며, 해당 지표에서는 근로자가 노동조합을 조직하거나 두 가지 가입 형태에 따른 노동조합 가입을 모두 인정하고 있다. 다만, 근로자가 자발적으로 노동조합을 조직하지 않거나 이에 가입하지 않은 경우에는 ‘노사협의회 설치·운영’을 대체지표로 사용 가능하다.  노동조합의 대표자는 그 노동조합 또는 조합원을 위하여 사용자나 사용자단체와 교섭하고 단체협약을 체결할 권한을 가지며, 사용자는 노동조합의 대표자 또는 노동조합으로부터 위임을 받은 자와의 단체협약 체결 기타의 단체교섭을 정당한 이유 없이 거부하거나 해체하지 못한다. … | AA38: 노동조합 설립·가입, 단체협약 이행, 분기별 노사협의회가 실질 운영됩니까? | AB38: 단계(1~5)
A39: 38 | B39: S-3-1 | C39: 기본진단항목(v2.0) | D39: 사회 | E39: 다양성 및 양성평등 | F39: 여성 구성원 비율 | G39:  조직의 중장기적 성장 및 새로운 사업기회 발굴에 필요한 창조적이고 혁신적인 조직문화를 위해 모든 직급의 구성원 다양성이 관리되고 있는지 확인  국내 인구구조적 특성을 고려하여, 다수의 다양성 기준 중 성별에 따른 다양성 현황을 점검하고자 함. 이를 위해, 조직의 남성 구성원 대비 여성 구성원(또는 여성 구성원 대비 남성 구성원)이 차지하는 비율을 직급별로 점검 | H39: ‘전자공시시스템’ 上 사업보고서, ‘조직별 홈페이지’ 上 지속가능경영보고서 | I39: 직전 회계연도 | J39: 국내 및 해외 사업장 | K39: 여성 구성원 비율 = 직전 회계연도 말 여성 구성원 수 (전체, 미등기임원) / 직전 회계연도 말 총 구성원 수 (전체, 미등기임원) | L39: 단계형 | M39: 5 | N39: 단계형: 1단계=0점 / 2단계=25점 / 3단계=50점 / 4단계=75점 / 5단계=100점 | O39: 1단계 | 조직의 전체 구성원 중 여성이 차지하는 비율과, 미등기임원 중 여성이 차지하는 비율의 차이가 80%를 초과하는 경우 | 2단계 | 조직의 전체 구성원 중 여성이 차지하는 비율과, 미등기임원 중 여성이 차지하는 비율의 차이가 60% 초과 ~ 80% 이하인 경우 | 3단계 | 조직의 전체 구성원 중 여성이 차지하는 비율과, 미등기임원 중 여성이 차지하는 비율의 차이가 40% 초과 ~ 60% 이하인 경우 | 4단계 | 조직의 전체 구성원 중 여성이 차지하는 비율과, 미등기임원 중 여성이 차지하는 비율의 차이가 20% 초과 ~ 40% 이하인 경우 | 5단계 | 조직의 전체 구성원 중 여성이 차지하는 비율과, 미등기임원 중 여성이 차지하는 비율의 차이가 20% 이하인 경우 | * 단, 결과값이 ‘-’ 일 경우, 본 지표에서 고려한 조직형태와 다른 경우이므로 적용하지 않음 | P39: GAP(대응지표 없음) | Q39: KSSB 다양성 지표 미규정 | R39: GRI 405-1 | S39: 1_2_0_업종별 K-ESG 가이드라인(v2.0) 진단항목 | X39: =IF(T39="","",MAX(1,SUMPRODUCT(('02_점수산정참고표'!$A$2:$A$314=$B39)*('02_점수산정참고표'!$C$2:$C$314=T39)*'02_점수산정참고표'!$E$2:$E$314))) | Y39:  조직의 전체 구성원 중 여성 비율과, 미등기임원 중 여성 비율의 차이를 측정하는 이유는 조직이 여성의 안정적 근무를 위한 근로환경을 제공하고 있는지, 여성 리더를 적극적으로 발굴 및 육성하고 있는지 확인하기 위함이다. - 여성 구성원 비율 차이 산식(%) : 100 - {(직전 회계연도 말 여성 미등기임원 수/직전 회계연도 말 총 미등기임원 수)/ (직전 회계연도 말 총 여성 구성원 수/직전 회계연도 말 총 구성원 수)}  조직은 직급별, 직무별, 근속연수별, 지역별 여성 구성원 비율을 기준으로도 ‘여성 구성원 비율’ 성과를 점검할 수 있다. - 직급별 : ‘사원’, ‘대리’, ‘과장’, ‘차장’, ‘부장’ 등 직급체계를 기준으로 여성 구성원 비율을 확인하는 방식… | AA39: 전체 여성 비율과 미등기임원 여성 비율 간의 격차가 균형 관리됩니까? | AB39: 단계(1~5)
A40: 39 | B40: S-3-2 | C40: 기본진단항목(v2.0) | D40: 사회 | E40: 다양성 및 양성평등 | F40: 여성 급여 비율 (평균 급여액 대비) | G40:  조직이 다양성 측면에서 소수계층, 사회적 취약계층, 기타 단순한 신체적 차이를 사유로 임금 지급에 차별을 두는 인사제도, 고용관행이 있는지 확인  국내 인구구조적 특성을 고려하여, 차별이 발생하는 다양한 사례 중 성별에 따른 급여 차이가 발생하는지 점검. 조직의 남/여 구성원 중 평균 급여액 미만의 급여를 받는 집단을 기준으로 급여 차이를 확인하는 항목으로써, 1인 평균 급여액 대비 ‘여성 1인 평균 급여액’(또는, 남성 1인 평균 급여액) 비율을 점검 | H40: ‘전자공시시스템’ 上 사업보고서, ‘조직별 홈페이지’ 上 지속가능경영보고서 | I40: 직전 회계연도 | J40: 국내 및 해외 사업장 | K40: 남성대비 여성임금 비율 = 직전 회계연도 여성(또는 남성) 1인 평균 급여액 / 직전 회계연도 조직의 1인 평균 급여액 | L40: 단계형 | M40: 5 | N40: 단계형: 1단계=0점 / 2단계=25점 / 3단계=50점 / 4단계=75점 / 5단계=100점 | O40: 1단계 | 조직의 1인 평균 급여액 대비 ‘여성(또는 남성) 1인 평균 급여액’ 비율이 60% 이하인 경우 | 2단계 | 조직의 1인 평균 급여액 대비 ‘여성(또는 남성) 1인 평균 급여액’ 비율이 60% 초과 ~ 70% 이하인 경우 | 3단계 | 조직의 1인 평균 급여액 대비 ‘여성(또는 남성) 1인 평균 급여액’ 비율이 70% 초과 ~ 80% 이하인 경우 | 4단계 | 조직의 1인 평균 급여액 대비 ‘여성(또는 남성) 1인 평균 급여액’ 비율이 80% 초과 ~ 90% 이하인 경우 | 5단계 | 조직의 1인 평균 급여액 대비 ‘여성(또는 남성) 1인 평균 급여액’ 비율이 90%를 초과하는 경우 | P40: GAP(대응지표 없음) | Q40: KSSB 다양성 지표 미규정 | R40: GRI 405-2 | S40: 1_2_0_업종별 K-ESG 가이드라인(v2.0) 진단항목 | X40: =IF(T40="","",MAX(1,SUMPRODUCT(('02_점수산정참고표'!$A$2:$A$314=$B40)*('02_점수산정참고표'!$C$2:$C$314=T40)*'02_점수산정참고표'!$E$2:$E$314))) | Y40:  여성(또는 남성) 급여 비율로 성과를 점검하는 이유는 조직이 성별 다양성 증진 활동의 결과물을 간접적으로 확인하기 위함이다. 조직의 성별 다양성 증진 활동이 효과적으로 실행되었다면, 상위 직급에 여성의 분포가 높아졌거나, 여성의 근속연수가 증가하였을 것이며, 이는 여성의 평균 급여액이라는 데이터에 반영되기 때문이다. 전체 구성원의 평균 급여액 대비 여성의 평균 급여액이 10% 이내, 또는 동일한 경우, 해당 조직의 다양성 관리는 효과적으로 이루어졌다고 볼 수 있다.  본 ‘여성 급여 비율’ 항목 정의서의 ‘1인 평균 급여액’이란 한국채택국제회계기준(IFRS) 제1019호에서 규정하는 ‘종업원 급여(단기종업원급여, 퇴직급여, 기타장기종업원급여, 해고급여)’를 회계연도… | AA40: 남성 평균 급여 대비 여성 평균 급여의 격차가 점차 해소되고 있습니까? | AB40: 단계(1~5)
...

Sheet 02_점수산정참고표
A1: 분류코드 | B1: 진단항목명 | C1: 단계번호 | D1: 단계라벨 | E1: 배점 | F1: 단계별 판단기준(K-ESG v2.0 원문)
A2: P-1-1 | B2: ESG 정보공시 방식 | C2: 1 | D2: 1단계 | E2: 0 | F2: 조직이 어떠한 방식으로든 ESG 정보를 공시하지 않는 경우
A3: P-1-1 | B3: ESG 정보공시 방식 | C3: 2 | D3: 2단계 | E3: 25 | F3: 조직의 홈페이지, 지속가능경영보고서, 사업보고서, 기타 간행물 등에 ESG 정보를 분산하여 공시하고 있는 경우
A4: P-1-1 | B4: ESG 정보공시 방식 | C4: 3 | D4: 3단계 | E4: 50 | F4: 조직의 홈페이지, 지속가능경영보고서, 사업보고서, 기타 간행물 등에 ESG 정보를 통합하여 공시하고 있는 경우
A5: P-1-1 | B5: ESG 정보공시 방식 | C5: 4 | D5: 4단계 | E5: 75 | F5: ESG 정보를 통합한 조직의 홈페이지, 지속가능경영보고서, 사업보고서, 기타 간행물 등을 지정된 장소에 비치하거나, 특정 URL에 담고 있는 경우
A6: P-1-1 | B6: ESG 정보공시 방식 | C6: 5 | D6: 5단계 | E6: 100 | F6: ESG 정보를 통합한 조직의 홈페이지, 지속가능경영보고서, 사업보고서, 기타 간행물 등의 발행여부를 ‘전자공시시스템-자율공시’ 사항으로 알리는 경우
A7: P-1-2 | B7: ESG 정보공시 주기 | C7: 1 | D7: 1단계 | E7: 0 | F7: ESG 정보공시 주기를 특정할 수 없거나, 명시하고 있지 않는 경우
A8: P-1-2 | B8: ESG 정보공시 주기 | C8: 2 | D8: 2단계 | E8: 50 | F8: 2년 단위로 보고서 발간 및 ESG 정보를 공시하는 경우
A9: P-1-2 | B9: ESG 정보공시 주기 | C9: 3 | D9: 3단계 | E9: 100 | F9: 1년 단위로 보고서 발간 및 ESG 정보를 공시하는 경우
A10: P-1-3 | B10: ESG 정보공시 범위 | C10: 1 | D10: 1단계 | E10: 0 | F10: ESG 정보공시 범위를 특정할 수 없거나, 명시하고 있지 않는 경우
A11: P-1-3 | B11: ESG 정보공시 범위 | C11: 2 | D11: 2단계 | E11: 25 | F11: 조직이 법적으로 직접 소유하고 있는 사업장(ex. 별도재무제표 기준)의 일부 또는 모든 ESG 정보를 공시하고 있는 경우
A12: P-1-3 | B12: ESG 정보공시 범위 | C12: 3 | D12: 3단계 | E12: 50 | F12: 조직의 영향력과 통제력 범위에 있는 곳(자회사, 종속법인, 연결실체 등)의 일부 ESG 정보를 공시하고 있는 경우
A13: P-1-3 | B13: ESG 정보공시 범위 | C13: 4 | D13: 4단계 | E13: 75 | F13: 조직의 영향력과 통제력 범위에 있는 곳(자회사, 종속법인, 연결실체 등)의 일부 ESG 정보를 공시하고 있는 경우. 단, 조직의 영향력과 통제력 범위로 ESG 정보공시 범위를 확대한다는 계획을 제시하고 있는 경우
... A314: S-6-3 | B314: 협력사 ESG 협약사항 | C314: 5 | D314: 요건5 | E314: 100 | F314: 협력사의 ESG 추진에 필요한 설비/장치 도입 지원 협약 체결

Sheet 03_지배구조세부점검(KRX)
A1: 순번 | B1: 핵심원칙(대분류) | C1: 세부원칙 | D1: 지표코드 | E1: 지표명 | F1: 데이터유형 | G1: 크롤링소스(정량 수집처) | H1: 연계 K-ESG 분류코드 | I1: 비고/근거 | J1: [입력]자사 현황값
