Workbook

Sheet 01_ESG통합진단마스터
A1: [분리본: G(지배구조)+P(정보공시)+반도체특화] 원본 「ESG_핵심지표_채점기준표_전체」 01시트를 분류코드 기준으로 재분류한 파일입니다.
A2: No | B2: 분류코드 | C2: 적용구분 | D2: 영역 | E2: 범주 | F2: 진단항목명 | G2: 항목설명 | H2: 데이터원천(수집처) | I2: 데이터기간 | J2: 데이터범위 | K2: 데이터산식(정량화공식) | L2: 채점유형 | M2: 최대단계수 | N2: 배점구조 요약 | O2: 점검기준 상세(K-ESG v2.0 원문) | P2: KSSB 대응현황 | Q2: KSSB 참고근거 | R2: 기타 참고기준(GRI/SASB/TCFD/KCGS 등) | S2: 원본 출처파일 | T2: [입력]충족단계/요건수 | U2: [입력]위반유형1 | V2: [입력]위반유형2 | W2: [입력]위반유형3 | X2: 자사취득점수(0~100) | Y2: 개선 가이드 | Z2: 비고 | AA2: 실사 진단 질문 | AB2: 답변형식
A3: 1 | B3: P-1-1 | C3: 기본진단항목(v2.0) | D3: 정보공시 | E3: 정보공시 형식 | F3: ESG 정보공시 방식 | G3:  조직이 ESG 정보공시 동향에 맞추어 정보 수요자의 접근성을 고려한 ESG 정보공시 방식을 정립하고 있는지 점검  ESG 정보를 종합한 온/오프라인 채널 운영 및 ESG 정보공시 외부 확산/전파 등 정보 접근성 향상 측면의 노력을 확인 | H3: 홈페이지, 지속가능경영보고서, 사업보고서, 기타간행물, 전자공시시스템 上 ‘자율공시’ | I3: 직전 회계연도 | J3: N/A | K3: N/A | L3: 단계형 | M3: 5 | N3: 단계형: 1단계=0점 / 2단계=25점 / 3단계=50점 / 4단계=75점 / 5단계=100점 | O3: 1단계 | 조직이 어떠한 방식으로든 ESG 정보를 공시하지 않는 경우 | 2단계 | 조직의 홈페이지, 지속가능경영보고서, 사업보고서, 기타 간행물 등에 ESG 정보를 분산하여 공시하고 있는 경우 | 3단계 | 조직의 홈페이지, 지속가능경영보고서, 사업보고서, 기타 간행물 등에 ESG 정보를 통합하여 공시하고 있는 경우 | 4단계 | ESG 정보를 통합한 조직의 홈페이지, 지속가능경영보고서, 사업보고서, 기타 간행물 등을 지정된 장소에 비치하거나, | 특정 URL에 담고 있는 경우 | 5단계 | ESG 정보를 통합한 조직의 홈페이지, 지속가능경영보고서, 사업보고서, 기타 간행물 등의 발행여부를 ‘전자공시시스템-자율공시’ | 사항으로 알리는 경우 | P3: 부분대응 | Q3: KSSB 제1호 문단 64~70(보고시기·장소), 21~24(연계된 정보) | R3: GRI 2-3 | S3: 1_2_0_업종별 K-ESG 가이드라인(v2.0) 진단항목 | Y3:  ESG 정보공시란 투자자를 비롯한 다양한 이해관계자의 의사결정 및 가치판단에 영향을 미칠 수 있는 환경, 사회, 지배구조와 관련된 정보를 공개적으로 널리 알리는 행위를 의미한다. 조직은 정기적으로 특정한 정보공시 창구(홈페이지, 사업보고서, 지속가능경영보고서, 기타 간행물 등)에 ESG 관련 정보를 종합적으로 수록하고 있으며, 해당 정보공시 창구를 통해 이해관계자 누구나 ESG 정보를 접근/열람할 수 있고, 정보공시 여부를 대내외에 알리는 행위를 한 경우 ESG 정보공시를 하였다고 정의한다.  ESG 정보란 중대성 평가(Materiality Test) 결과에 따른 핵심이슈, 또는 조직의 사업운영 과정에서 지속적 관리가 필요한 ESG 이슈별로 ‘전략’, ‘조직’,… | AA3: 정보 수요자의 접근성을 고려하여 홈페이지, 지속가능경영보고서 등을 통해 ESG 정보를 통합 공시하고 있습니까? | AB3: 단계(1~5)
A4: 2 | B4: P-1-2 | C4: 기본진단항목(v2.0) | D4: 정보공시 | E4: 정보공시 형식 | F4: ESG 정보공시 주기 | G4:  투자자, 고객 등 정보 수요자의 의사결정 및 가치판단에 필요한 최신 ESG 정보를 적시에 제공하고 있는지 점검  조직의 ESG 데이터 취합/분석/마감 기간을 고려하여 1년 단위로 ESG 정보공시 주기를 설정하고 있는지 확인 | H4: ESG 정보공시 일자, 지속가능경영보고서 발간 주기 | I4: 최근 4개년 회계연도 * 3개년 이하 데이터 보유 시 해당 데이터로 추세 산정 | J4: N/A | K4: N/A | L4: 단계형 | M4: 3 | N4: 단계형: 1단계=0점 / 2단계=50점 / 3단계=100점 | O4: 1단계 | ESG 정보공시 주기를 특정할 수 없거나, 명시하고 있지 않는 경우 | 2단계 | 2년 단위로 보고서 발간 및 ESG 정보를 공시하는 경우 | 3단계 | 1년 단위로 보고서 발간 및 ESG 정보를 공시하는 경우 | P4: 부분대응 | Q4: KSSB 제1호 문단 60~63(보고빈도) | R4: GRI 2-3 | S4: 1_2_0_업종별 K-ESG 가이드라인(v2.0) 진단항목 | Y4:  ESG 정보 수요자가 조직의 ESG 정보를 효과적으로 활용하기 위해서는, 조직이 ESG 정보를 주기적으로 공시하는 것이 중요하다. ESG 정보가 적시성을 확보하기 위해서는 ESG 정보공시 주기를 재무정보 공시주기와 동일하게 하거나, 재무정보 공시 이후 최대한 빠른 시기에 ESG 정보를 공시할 필요가 있다. 또한, ESG 정보 수요자에 상당한 영향력을 미칠 수 있는 정보는 이를 확인한 즉시 대외공시할 것을 권장한다.  조직은 ESG 정보공시 주기를 자율적으로 정할 수 있다. 일부 조직은 주요한 ESG 성과가 창출되는 시점마다 공시하기도 하며, 어떠한 조직은 ESG 정보공시에 따른 업무/비용 부담을 고려하여 격년 주기로 공시하기도 한다. 반면 ESG 정보공시 규제 및… | AA4: 최신 ESG 정보를 적시에 제공하기 위해 1년 단위로 정기 공시합니까? | AB4: 단계(1~5)
A5: 3 | B5: P-1-3 | C5: 기본진단항목(v2.0) | D5: 정보공시 | E5: 정보공시 형식 | F5: ESG 정보공시 범위 | G5:  ESG 정보공시 제도화 움직임에 따라, 조직의 ESG 활동 및 성과를 충분히 대표하고 나타낼 수 있는 정보가 공시되고 있는지 점검  조직의 영향력과 통제력이 미치는 사업장(자회사 포함)의 ESG 정보가 최대한 공시되고 있는지 확인 | H5: 홈페이지, 지속가능경영보고서, 사업보고서, 전자공시시스템 上 ‘자율공시’ | I5: 직전 회계연도 | J5: 사업적 영향력 및 통제력을 행사하는 사업장 및 기타 연결실체 | K5: ESG 정보공시 범위 = ESG 정보공시에 포함된 사업장 등의 (매출액 등) / 전체 조직의 (매출액 등) | L5: 단계형 | M5: 5 | N5: 단계형: 1단계=0점 / 2단계=25점 / 3단계=50점 / 4단계=75점 / 5단계=100점 | O5: 1단계 | ESG 정보공시 범위를 특정할 수 없거나, 명시하고 있지 않는 경우 | 2단계 | 조직이 법적으로 직접 소유하고 있는 사업장(ex. 별도재무제표 기준)의 일부 또는 모든 ESG 정보를 공시하고 있는 경우 | 3단계 | 조직의 영향력과 통제력 범위에 있는 곳(자회사, 종속법인, 연결실체 등)의 일부 ESG 정보를 공시하고 있는 경우 | 4단계 | 조직의 영향력과 통제력 범위에 있는 곳(자회사, 종속법인, 연결실체 등)의 일부 ESG 정보를 공시하고 있는 경우. | 단, 조직의 영향력과 통제력 범위로 ESG 정보공시 범위를 확대한다는 계획을 제시하고 있는 경우 | 5단계 | 조직의 영향력과 통제력 범위에 있는 곳(자회사, 종속법인, 연결실체 등)의 모든 ESG 정보를 공시하고 있는 경우 | P5: 부분대응 | Q5: KSSB 제1호 문단 21~24(연계된 정보) | R5: GRI 2-2 | S5: 1_2_0_업종별 K-ESG 가이드라인(v2.0) 진단항목 | Y5:  조직은 ESG 정보공시 전 어떠한 범위까지 성과관리를 할 것인지, 또는 성과관리가 가능한지 등 최대 범위를 설정해야 한다. ESG 개념을 조직의 재무적 정보를 기반으로 투자의사결정을 하는 자본시장에서 등장하였기 때문에, 장기적으로 ESG 성과관리 및 정보공시 최대범위는 ‘(연결)재무제표’에 포함되는 ‘재무정보’ 범위와 동일시하려는 논의가 진행될 것으로 예상된다. 따라서 조직은 아래의 ‘영향력’과 ‘통제력’이 행사되는 범위에서 발생하는 환경, 사회, 지배구조 관련 정보를 공시할 필요가 있다. (예를 들어, US GAAP, IFRS 회계지침에는 20% 이상 지분을 보유한 조직을 상당한 영향력이 행사되는 조직으로 간주한다.) 1) ESG 정보를 공시하는 조직이 직접적으로… | AA5: 조직 통제력이 미치는 종속/연결실체 등 최대 범위를 공시합니까? | AB5: 단계(1~5)
A6: 4 | B6: P-2-1 | C6: 기본진단항목(v2.0) | D6: 정보공시 | E6: 정보공시 내용 | F6: ESG 핵심이슈 및 KPI | G6:  조직의 사업성과 및 환경/사회에 상당한 영향력을 미치는 핵심이슈를 명확히 정의하고, 이를 관리하기 위한 시스템 및 절차를 갖추고 있는지 확인  조직이 인식하고 관리하고 있는 핵심 ESG 이슈에 대한 조직의 정보공시 수준을 점검 | H6: 홈페이지, 지속가능경영보고서, 사업보고서, 전자공시시스템 上 ‘자율공시’ | I6: 직전 회계연도 | J6: N/A | K6: N/A | L6: 단계형 | M6: 5 | N6: 단계형: 1단계=0점 / 2단계=25점 / 3단계=50점 / 4단계=75점 / 5단계=100점 | O6: 1단계 | 중대성 평가 결과 또는 ESG 핵심이슈를 공시하고 있지 않은 경우 | 2단계 | 중대성 평가 결과와 핵심이슈를 명확히 정의하고 있는 경우 | 3단계 | 2단계 + 핵심이슈에 대해 조직이 관리하고 있는 성과지표를 설명하고 있는 경우 | (예를 들어, 기후변화가 핵심이슈일 경우, 온실가스 배출량 데이터 제시) | 4단계 | 3단계 + 핵심이슈가 사업적/사회적 관점에서 중요한 사유를 설명하고 있는 경우 | (예를 들어, 사업적/사회적 관점의 기회 요인과 리스크 요인 등) | 5단계 | 4단계 + 핵심이슈를 관리하기 위한 시스템 및 절차를 설명하고 있는 경우 | (조직, 전략 및 계획, 고충처리체계, 활동 및 교육 등) | P6: 부분대응 | Q6: KSSB 제1호 문단 17~19(중요성 판단, 이중중대성 개념 미흡) | R6: GRI 3(중대성평가) | S6: 1_2_0_업종별 K-ESG 가이드라인(v2.0) 진단항목 | Y6:  조직의 중요한 경제적, 환경적, 사회적 영향을 반영하는 측면 또는 이해관계자들의 평가와 의사결정에 실질적으로 영향을 미치는 측면을 모두 고려하여 보고서에서 다룰 가치가 있다고 판단되는 주제를 선정하는 과정을 거쳐야 한다. 이러한 이슈의 중대성을 판별하기 위한 방법으로는 일반적으로 ‘중대성 평가(Materiality Assessment)’ 또는 ‘이중 중대성 평가(Double Materiality Assessment)’가 있으며, 중대 측면을 정의하는 데 있어 조직이 참작해야 할 요인들은 다음과 같다. - 지속가능성에 영향, 위험, 기회 요소가 될 수 있는 항목(ex. 지구 온난화, 에이즈, 빈곤 등) 중 합리적 평가가 가능하고, 전문가나 해당 분야에 자격을 갖춘 전문… | AA6: 이중 중대성 평가 기반 핵심이슈, 위기/기회, KPI를 공시합니까? | AB6: 단계(1~5)
A7: 5 | B7: P-3-1 | C7: 기본진단항목(v2.0) | D7: 정보공시 | E7: 정보공시 검증 | F7: ESG 정보공시 검증 | G7:  조직의 ESG 정보를 직접적으로 또는 가공하여 활용하는 이해관계자가 증가함에 따라, 조직이 대외공시하는 ESG 정보가 타당성/신뢰성/투명성을 확보하고 있는지 확인  조직이 대외공시하는 정보에 관해 제3자 기관으로부터 검증을 받는 경우, 해당 검증의견이 갖추어야 할 형식적 요건을 점검 | H7: ESG 정보 검증의견서, 지속가능경영보고서 검증의견서 | I7: 직전 회계연도 | J7: N/A | K7: N/A | L7: 선택형 | M7: 5 | N7: 선택형: 요건1=0점 / 요건2=25점 / 요건3=50점 / 요건4=75점 / 요건5=100점 | O7: 요건1 | 검증의견서에 검증기관(또는 검증인)이 명시되어 있는 경우 | (또는, 검증기관이 License Number를 보유하고 있는 경우) | 요건2 | 검증의견서에 검증기관과의 독립성 성명이 포함되어 있는 경우 | (즉, 검증기관과 검증받는 조직간 이해관계 상충이 없음을 선언한 경우) | 요건3 | 검증의견서에 검증표준(방법론)이 제시되어 있는 경우 | (AA1000AS, ISAE3000, 또는 제3자 검증기관이 개발한 자체 검증표준 등) | 요건4 | 검증의견서에 ESG 정보 검증수준을 공개하고 있는 경우 | (Type1/Type2, Moderate/High, 제한적/합리적 등) | 요건5 | 검증의견서에 제3자 검증기관이 검증한 정보공시 지표가 적시되어 있는 경우 | (즉, 조직의 모든 ESG 정보 중 어떠한 정보를 검증하였는지 명시하는 경우) | P7: 완전대응 | Q7: KSSB 제1호 문단 50(3)(외부검증) | R7: GRI 2-5, AA1000AS, ISAE3000 | S7: 1_2_0_업종별 K-ESG 가이드라인(v2.0) 진단항목 | Y7:  조직은 지속가능경영보고서 발간 등 ESG 정보공시 지표 및 기준을 자율적으로 선택할 수 있으며, ESG 정보가 갖추어야 할 신뢰성을 강제할 수 있는 법적/제도적 장치도 마련되어 있지 않은 상황이다. 따라서 ESG 정보 검증은 이러한 문제점을 개선하기 위한 조직의 의지이자 자율적 활동으로 조직이 공시하는 ESG 정보의 신뢰성을 확보하는 수단으로 인정받고 있다.  ESG 정보 검증의 타당성과 신뢰성을 확인하기 위한 기준은 ‘검증기관의 적격성’, ‘검증기관과의 독립성’, ‘검증방법론의 합리성’, ‘검증수준의 명확성’, ‘검증지표의 구체성’으로 구분할 수 있다.  글로벌 시장에서 통용되는 ESG 검증표준에는 1) 지속가능경영 관련 국제표준 제정기관인… | AA7: 적격/독립된 제3자 검증기관으로부터 인증을 획득했습니까? | AB7: 단계(1~5)
A8: 53 | B8: G-1-1 | C8: 기본진단항목(v2.0) | D8: 지배구조 | E8: 이사회 구성 | F8: 이사회 내 ESG 안건 상정 | G8:  조직의 최고의사결정기구인 이사회 또는 산하 위원회가 ESG 관련 안건을 보고받고 있으며, 특히 중대한 ESG 안건에 대해서는 심의/의결하고 있는지 확인  이사회 또는 산하 위원회를 통해 조직의 ESG 경영이 효율적으로 관리 및 감독되고 있는지 점검하기 위해 1) 활동내역, 2) 운영 규정의 2가지를 점검  조직은 ESG 안건을 다루기 위해 이사회 산하에 ‘지속가능경영위원회(ESG위원회)’를 설립할 수 있으나, 이사회, 또는 기존의 산하 위원회(사회책임위원회, 투명경영위원회, 거버넌스위원회, 경영위원회, 감사위원회 등)를 통해서도 ESG 안건을 다룰 수 있음 | H8: 이사회 또는 산하 위원회 개최 내역, 이사회 또는 산하 위원회 운영규정 | I8: 직전 회계연도 | J8: N/A | K8: N/A | L8: 복합가중형 | N8: 복합가중형: 2~3개 세부요소를 균등가중평균(예: 1/2+1/2, 1/3×3) — 세부 배점은 점검기준 상세 참조, 자사취득점수는 수동 산정 | O8: 영역1 (1/2) | 1단계 | 이사회 또는 산하 위원회에서 ESG 관련 안건을 다루고 있지 않는 경우 | 2단계 | 최근 1년간 ESG 관련 안건이 모두 '보고' 사항인 경우 | 3단계 | 최근 1년간 ESG 관련 안건 중 '심의/의결' 사항이 있는 경우 | 영역2 (1/2) | 1단계 | 이사회 또는 산하 위원회 운영규정에 ESG 관련 사항을 명시하지 않는 경우 | 2단계 | 이사회 또는 산하 위원회 운영규정에 ‘ESG’라는 단어만 기재하고 있는 경우 | 3단계 | 이사회 또는 산하 위원회 운영규정에 ESG 이외에, 조직과 관련된 중요 ESG 이슈 또는 안건을 명시하고 있는 경우 | P8: 완전대응 | Q8: KSSB 제1호 문단 27(1) — 이사회 ESG 안건 감독 | R8: GRI 2-9, KCGS | S8: 1_2_0_업종별 K-ESG 가이드라인(v2.0) 진단항목 | T8: 해당없음(복합가중형) | Y8:  ESG가 사업운영 및 중장기 발전을 위한 중요한 요인으로 등장함에 따라, 조직의 최고의사결정기구인 이사회에서 ESG 안건을 검토/심의/의결하도록 요구받고 있다. 조직은 이사회에서 ESG와 관련한 중요 안건을 보고받거나, 심의/의결할 수도 있으며, 이사회 산하 위원회를 설치하여 ESG 관련 안건을 다루도록 함으로써 이사회 역할 수행의 전문성과 효율성을 제고할 수 있다.  조직은 ESG 안건을 다루기 위해 이사회 산하에 ‘ESG위원회’를 신설할 수 있으나, 이사회, 또는 기존에 설치한 위원회(사회책임위원회, 투명경영위원회, 거번너스위원회, 경영위원회, 감사위원회 등)를 통해서도 ESG 안건을 다룰 수 있다. 즉, ‘ESG위원회’ 설치 여부가 중요한 것이 아니라, 어떠한… | AA8: 이사회 및 ESG위원회 운영 규정에 역할을 명시하고 정기 심의합니까? | AB8: 단계(1~5)
A9: 54 | B9: G-1-2 | C9: 기본진단항목(v2.0) | D9: 지배구조 | E9: 이사회 구성 | F9: 사외이사 비율 | G9:  조직이 사외이사 제도를 통해 경영진 및 지배주주에 대한 견제, 기업경영 투명성의 제고, 소수주주의 권리보호 등의 목적을 달성하고 있는지 확인  경영진의 의사결정 행위를 견제할 수 있으며, 독립적인 시각에서 기업 발전에 관한 제언을 할 수 있는 사외이사 비율이 충분한지 점검 | H9: 이사회 구성현황, 전자공시시스템 [사업보고서-이사회에 관한 사항] | I9: 지난 1개 회계연도 기준 | J9: N/A | K9: N/A | L9: 단계형 | M9: 5 | N9: 단계형: 1단계=0점 / 2단계=25점 / 3단계=50점 / 4단계=75점 / 5단계=100점 | O9: 1단계 | 총원의 과반수로 구성되었으나, 사외이사가 3인인 경우 | 2단계 | 3인 이상, 이사 총원의 과반수를 차지하고 있으나, 전체 이사 중 60% 미만인 경우 | 3단계 | 3인 이상, 이사 총원의 과반수를 차지, 전체 이사 중 60% 이상 ~ 70% 미만인 경우 | 4단계 | 3인 이상, 이사 총원의 과반수를 차지, 전체 이사 중 70% 이상 ~ 80% 미만인 경우 | 5단계 | 3인 이상, 이사 총원의 과반수를 차지, 전체 이사 중 80% 이상인 경우 | P9: 부분대응 | Q9: KSSB 제1호 문단 27(1) 취지상 이사회 역량 요구와 연관 | R9: 지배구조보고서 가이드라인, GRI 2-9 | S9: 1_2_0_업종별 K-ESG 가이드라인(v2.0) 진단항목 | Y9:  이사회가 조직의 경영활동에 대한 감독과 견제의 기능을 효과적으로 수행하며, 경영진이 합리적이고 객관적인 의사결정을 내릴 수 있도록 제언하기 위해서는 사외이사의 독립성이 확보되어야 한다. 사외이사의 독립성 요건(또는 사외이사 결격사유)은 ｢상법｣ 제382조 및 제542조, 금융회사의 지배구조에 관한 법률｣ 제12조를 통해 확인할 수 있다.  사외이사가 경영진의 의사결정에 중요한 영향력을 행사하거나, 이사회 의결사항에 상당한 의사결정권한을 갖추기 위해서는 충분한 수의 사외이사가 확보되어야 한다. 따라서 사외이사 비율은 이사회가 경영진 등을 충분히 견제할 수 있는 수준에서 결정되어야 한다. ｢상법｣ 및 ｢금융회사의 지배구조에 관한 법률｣에서 제시하는 사외이사 비율… | AA9: 경영진 견제를 위해 사외이사의 비율을 과반수 이상 확보하고 있습니까? | AB9: 단계(1~5)
A10: 55 | B10: G-1-3 | C10: 기본진단항목(v2.0) | D10: 지배구조 | E10: 이사회 구성 | F10: 대표이사와 이사회 의장 분리 | G10:  경영진의 경영활동을 감독하고 견제하는 이사회의 역할을 제대로 수행하기 위한 독립성 확보 여부를 확인  이사회의 의장과 경영진의 대표인 대표이사와의 분리 여부 및 선임사외이사 임명 등을 점검 | H10: 이사회 구성 현황, 전자공시시스템[사업보고서-이사회에 관한 사항] | I10: 지난 1개 회계연도 기준 | J10: N/A | K10: N/A | L10: 단계형 | M10: 5 | N10: 단계형: 1단계=0점 / 2단계=25점 / 3단계=50점 / 4단계=75점 / 5단계=100점 | O10: 1단계 | 현재 대표이사와 이사회 의장이 동일한 경우 | 2단계 | 과거 대표이사 또는 이사회 의장을 역임했던 자가 현재 이사회 의장인 경우 | 3단계 | 현재 이사회 의장이 과거 또는 현재의 대표이사나 이사회 의장을 역임하지 않았으나, 모회사 또는 자회사의 임원 등 독립성이 | 결여된 자가 이사회 의장인 경우 | 4단계 | 과거 또는 현재 대표이사이거나, 이사회 의장을 역임하였거나, 독립성이 결여된 자가 현재 이사회 의장인 경우. | 단, 이사회 의장과 이해관계 상충하는 안건 등에 있어, 이사회 의장 역할을 대신하는 ‘선임사외이사’를 임명하고 있는 경우 | 5단계 | 과거 또는 현재 대표이사이거나, 이사회 의장을 역임한 적이 없으며, 회사로부터 독립성이 확보된 이사가 현재 이사회의 | 의장인 경우 | P10: GAP(대응지표 없음) | Q10: KSSB 별도 규정 없음 | R10: 지배구조보고서 가이드라인 | S10: 1_2_0_업종별 K-ESG 가이드라인(v2.0) 진단항목 | Y10:  경영진을 대표하는 대표이사와 이사회를 대표하는 이사회 의장이 동일하다면 경영진의 경영활동을 감독하고 견제하는 이사회의 역할을 제대로 수행할 수 없다. 다만, 대표이사와 이사회 의장이 분리되지 않은 경우에도 독립성을 갖춘 선임사외이사를 두어 이사회의 기능과 역할을 주도적으로 수행하도록 할 수 있다. 선임사외이사는 이사회(대표이사 또는 특수관계인이 이사회 의장으로 선임된)에서 대표이사의 이해와 관계된 의사결정 사안에 대해 이사회 의장을 대리하며, 사외이사들의 의견을 대표로 사내이사 및 경영진에게 전달하는 역할을 수행한다.  국내외 법/규제, ESG 평가기관 등은 대표이사의 이사회 의장 분리 및 선임사외이사 임명 관련 사항을 아래와 같이 명시하고 있으므로, 해당 지표… | AA10: 대표이사와 이사회 의장 분리에 대한 현황을 관리·공시하고 있습니까? | AB10: 단계(1~5)
A11: 56 | B11: G-1-4 | C11: 기본진단항목(v2.0) | D11: 지배구조 | E11: 이사회 구성 | F11: 이사회 성별 다양성 | G11:  이사회가 다양한 이해관계자들의 요구사항을 두루 고려하여 폭넓은 시각과 경험을 바탕으로 중요한 의사결정에 임할 수 있도록 이사회 구성원이 다양한 배경을 가지고 있는지 확인  다양성과 포용성의 대표적인 분류인 남성 대비 여성 비율(혹은 여성 대비 남성 비율)을 점검 | H11: 이사회 구성 현황, 전자공시시스템[사업보고서-이사회에 관한 사항] | I11: 지난 1개 회계연도 기준 | J11: N/A | K11: 이사회 여성 비율 = (여성 이사 수 / 전체 이사회 구성원 수) | L11: 단계형 | M11: 5 | N11: 단계형: 1단계=0점 / 2단계=25점 / 3단계=50점 / 4단계=75점 / 5단계=100점 | O11: 1단계 | 이사회 내 여성 이사가 선임되어 있지 않는 경우 | 2단계 | 이사회 내 여성 이사가 1명만 선임되어 있는 경우 | 3단계 | 이사회 내 여성 이사가 2명 이상이며, 그 비율이 10% 이상 ~ 20% 미만인 경우 | 4단계 | 이사회 내 여성 이사가 2명 이상이며, 그 비율이 20% 이상 ~ 30% 미만인 경우 | 5단계 | 이사회 내 여성 이사가 2명 이상이며, 그 비율이 30% 이상인 경우 | * 이사회 내 다수 성(性)이 여성일 경우에는 반대로 적용 | P11: 부분대응 | Q11: KSSB 제1호 문단 27(1) 이사회 역량·다양성 취지 준용 | R11: GRI 405-1 | S11: 1_2_0_업종별 K-ESG 가이드라인(v2.0) 진단항목 | Y11:  조직이 대내외 환경 변화에 유연하게 대처하고 장기적인 지속가능성을 확보하기 위해서는 다양한 시각과 관점에서 당면한 문제를 바라보고 해결할 수 있는 다양한 배경과 경험을 가진 이사를 선임해야 할 필요가 있다. 본 지표는 이러한 다양성을 확인할 수 있는 대표적 기준 중 하나인 성(性) 비율을 통해 이사회 내 성별 다양성을 점검하도록 요구하고 있다.  이사회를 구성하는 이사가 특정 성(性)에 치우치지 않는다는 것은 성별에서 기인하는 특정한 관점, 이해관계 등에서 벗어난 다양한 의견이 이사회의 의사결정에 반영될 수 있다는 것을 의미한다. 특히, 국내의 경우 독립적이고 다양한 전문성을 가지는 사외이사를 선임하는 등의 노력은 지속되고 있으나 이사회의 성별 다양성은 부족한… | AA11: 여성 이사를 1명 이상 혹은 30% 이상 일정 비율 확보했습니까? | AB11: 단계(1~5)
A12: 57 | B12: G-1-5 | C12: 기본진단항목(v2.0) | D12: 지배구조 | E12: 이사회 구성 | F12: 사외이사 전문성 | G12:  사내이사와 사외이사의 정보 비대칭이 존재하는 상황에서 사외이사가 조직의 중장기 발전에 관한 충분한 의견을 제공하거나, 경영진의 의사결정을 견제할 수 있는 전문성을 갖추고 있는지 확인  사외이사가 조직의 사업 방향에 대해 전문적인 의견을 제시할 수 있는지 점검 (사외이사가 동종산업의 업무경력을 보유하고 있는지 확인) | H12: 사외이사 경력사항 | I12: 직전 회계연도 | J12: N/A | K12: N/A | L12: 단계형 | M12: 3 | N12: 단계형: 1단계=0점 / 2단계=50점 / 3단계=100점 | O12: 1단계 | 동종산업 경력을 보유한 사외이사가 없는 경우 | 2단계 | 동종산업 경력을 보유한 사외이사가 1명 이상인 경우 | 3단계 | 동종산업 경력을 보유한 사외이사가 50% 이상인 경우 | P12: 완전대응 | Q12: KSSB 제1호 문단 27(1)ㄏ — 이사회 전문성 판단·개발계획 | R12: 지배구조보고서 가이드라인, KCGS | S12: 1_2_0_업종별 K-ESG 가이드라인(v2.0) 진단항목 | Y12:  전문성 있는 사외이사란 사내이사(경영진 등)의 경영의사결정에 대한 제언과 감독 기능을 충실히 이행할 수 있도록 해당 산업 전문지식과 경력을 보유하고 있는 자를 말하다. 이때, 해당 산업 전문지식과 경력이란 한국표준산업분류의 대분류(2자리 코드) 기준 동종산업에서 실무자 또는 경영진으로써 재직하였거나, 관련 연구기관 및 서비스기관에서 종사한 경험이 있는 것을 의미하며, 대학을 포함한 고등교육기관 및 학술기관 경력은 제외한다.  글로벌 ESG 평가기관은 ‘산업 전문성을 갖춘 사외이사 비율’을 평가지표로 운용하고 있으며, 조직은 사외이사 선임 시 평가기관 등이 제시하는 ‘산업 전문성’ 요건을 참고할 수 있다. - (S&P Global) 국제산업분류표준(GICS)… | AA12: 동종 산업(반도체/전자) 실무 경험을 보유한 사외이사가 포함되어 있습니까? | AB12: 단계(1~3)
A13: 58 | B13: G-2-1 | C13: 기본진단항목(v2.0) | D13: 지배구조 | E13: 이사회 활동 | F13: 전체 이사 출석률 | G13:  조직의 최고의사결정기구인 이사회가 검토/심의/의결 기능을 효과적으로 수행하기 위해서는 이사회 구성원의 적극적인 참여가 중요함. 이사회 구성원이 이사회에 참여하여 조직의 성장 및 발전에 관한 제언, 주요안건에 대한 의사결정 행위를 하고 있는지 확인  이사회 구성원별 출석률을 평균하여, 전체 이사 출석률이 일정 수준 이상인지 점검 | H13: 이사회 구성 현황, 이사회 회의록 등 | I13: 직전 회계연도 | J13: N/A | K13: 이사회 구성원 평균 출석률 = ∑(출석한 전체 이사 인원 수 / 전체 이사 정원) / 이사회 개최 횟수 | L13: 단계형 | M13: 5 | N13: 단계형: 1단계=0점 / 2단계=25점 / 3단계=50점 / 4단계=75점 / 5단계=100점 | O13: 1단계 | 이사회 구성원 평균 출석률이 75% 미만인 경우 | 2단계 | 이사회 구성원 평균 출석률이 75% 이상 85% 미만인 경우 | 3단계 | 이사회 구성원 평균 출석률이 85% 이상 90% 미만인 경우 | 4단계 | 이사회 구성원 평균 출석률이 90% 이상 95% 미만인 경우 | 5단계 | 이사회 구성원 평균 출석률이 95% 이상인 경우 | P13: 부분대응 | Q13: KSSB 제1호 문단 27(1)ㄒ — 보고주기 준용 | R13: GRI 2-9 | S13: 1_2_0_업종별 K-ESG 가이드라인(v2.0) 진단항목 | Y13:  ｢상법｣에서는 이사의 이사회 출석의무를 규정하고 있지 않으나, 이사 출석률은 이사가 수행해야 할 역할을 충실히 하고 있는지를 대변하는 중요한 지표가 된다.  특히 ｢상법｣ 제393조 제4항은 “이사는 3월에 1회 이상 업무의 진행사항을 이사회에 보고하여야 한다”라고 규정하고 있으며, 이를 해석하면 업무 진행사항을 보고하는 ‘사내이사’와 보고받는 ‘사외이사’가 1년 동안 최소 4회는 이사회에 참여하여야 한다는 것이다.  이사회 참여는 법/규제를 벗어나지 않는 범위에서 선관주의에 따른 이사회 구성원의 자율사항이다. 따라서 개별 이사에 대해 이사회 참여를 강제할 수 없으나, 이사회 구성원의 참여가 저조하거나 소극적인 경우, 이를 강제하기 위한 방식에는 다음과 같은… | AA13: 이사회 전체 이사 평균 출석률이 75% 이상 유지됩니까? | AB13: 단계(1~5)
A14: 59 | B14: G-2-2 | C14: 기본진단항목(v2.0) | D14: 지배구조 | E14: 이사회 활동 | F14: 사내이사 출석률 | G14:  조직의 최고의사결정기구인 이사회가 검토/심의/의결 기능을 효과적으로 수행하기 위해서는 이사회 구성원의 적극적인 참여가 중요함. 특히, 조직의 사업운영을 총괄하는 사내이사가 적극적으로 이사회에 참여하고 있는지 확인  이사회 구성원 중 전체 사내이사 출석률이 일정 수준 이상인지 점검 | H14: 이사회 구성 현황, 이사회 회의록 등 | I14: 직전 회계연도 | J14: N/A | K14: 사내이사 평균 출석률 = ∑(출석한 사내 이사 인원 수 / 전체 이사 정원) / 이사회 개최 횟수 | L14: 단계형 | M14: 5 | N14: 단계형: 1단계=0점 / 2단계=25점 / 3단계=50점 / 4단계=75점 / 5단계=100점 | O14: 1단계 | 사내이사 평균 출석률이 75% 미만인 경우 | 2단계 | 사내이사 평균 출석률이 75% 이상 85% 미만인 경우 | 3단계 | 사내이사 평균 출석률이 85% 이상 90% 미만인 경우 | 4단계 | 사내이사 평균 출석률이 90% 이상 95% 미만인 경우 | 5단계 | 사내이사 평균 출석률이 95% 이상인 경우 | P14: GAP(대응지표 없음) | Q14: KSSB 별도 규정 없음 | R14: 지배구조보고서 가이드라인 | S14: 1_2_0_업종별 K-ESG 가이드라인(v2.0) 진단항목 | Y14:  ｢상법｣에서는 이사의 이사회 출석의무를 규정하고 있지 않으나, 이사 출석률은 이사가 수행해야 할 역할을 충실히 하고 있는지를 대변하는 중요한 지표가 된다.  특히 ｢상법｣ 제393조 제4항은 “이사는 3월에 1회 이상 업무의 진행사항을 이사회에 보고하여야 한다”라고 규정하고 있으며, 이를 해석하면 업무 진행사항을 보고하는 ‘사내이사’와 보고받는 ‘사외이사’가 1년 동안 최소 4회는 이사회에 참여하여야 한다는 것이다.  이사회 참여는 법/규제를 벗어나지 않는 범위에서 선관주의에 따른 이사회 구성원의 자율사항이다. 따라서 사내이사에 대해 이사회 참여를 강제할 수 없으나, 사내이사의 참여가 저조하거나 소극적인 경우 이를 강제하기 위한 방식에는 다음과 같은 것들이 있다.… | AA14: 경영진 책임 강화를 위해 사내이사 이사회 평균 출석률이 높게 유지됩니까? | AB14: 단계(1~5)
A15: 60 | B15: G-2-3 | C15: 기본진단항목(v2.0) | D15: 지배구조 | E15: 이사회 활동 | F15: 이사회 산하 위원회 | G15:  이사회가 효율적으로 운영될 수 있도록 이사회 권한 및 역할의 일부를 산하 위원회에 위임하고 있는지, 각 소위원회는 위임받은 권한 및 역할에 대해 전문적인 시각으로 검토하는지를 확인  조직마다 이사회 산하 위원회 수와 종류는 다양하며, 각 조직의 경영방식 및 사업환경에 따라 위원회 수를 달리할 수 있음. 따라서 이사회 산하 위원회 수가 많고 적음을 떠나, 위원회가 체계적이고 효과적으로 운영되고 있는지 점검 | H15: 이사회 산하 위원회 운영규정, 구성현황, 활동내역 | I15: 직전 회계연도 | J15: N/A | K15: N/A | L15: 선택형 | M15: 5 | N15: 선택형: 요건1=0점 / 요건2=25점 / 요건3=50점 / 요건4=75점 / 요건5=100점 | O15: 요건1 | 이사회 산하 모든 위원회 설치는 정관에 근거하고 있으며, 모든 위원회에 대해 ‘운영규정’을 제정하고 있는 경우 | 요건2 | 특정 이사(사내이사, 사외이사, 기타비상임이사)가 이사회 산하 모든 위원회의 구성원으로 선임되어 있지 않은 경우 | 요건3 | 이사회 산하 모든 위원회가 구성원의 과반수 이상을 사외이사로 선임하고 있는 경우 | 요건4 | 직전 회계연도 중 이사회 산하 위원회 개최 횟수가 평균적으로 3회 이상인 경우 | 요건5 | 직전 회계연도 중 이사회 산하 모든 위원회가 심의/의결 안건을 다룬 경우 | P15: 부분대응 | Q15: KSSB 제1호 문단 27(1)① 위임기구 지정 준용 | R15: 지배구조보고서 가이드라인 | S15: 1_2_0_업종별 K-ESG 가이드라인(v2.0) 진단항목 | Y15:  조직의 모든 중요 안건을 이사회에서 검토하고 의사결정을 내리는 것은 비효율적이다. 따라서 전문성을 요구하는 특정 사안이나, 안건 심의에 있어 독립성이 필요한 사안에 대해서는 이사회 산하 위원회를 통해 검토하게 함으로써, 이사회 운영의 효율성을 제고할 수 있다.  ｢상법｣ 제393조의2에서는 이사회가 위원회에 위임할 수 있는 사항을 폭넓게 인정하고 있다. 법에서 제한하고 있는 사항 이외에는 위임이 가능하다. 즉 이사회는 주주총회의 승인을 요하는 사항의 제안, 대표이사의 선임 및 해임, 위원회의 설치와 그 위원의 선임 및 해임, 정관에서 정하는 사항을 제외하고는 그 권한을 위원회에 위임할 수 있다. - ｢상법｣에서는 이사회 내 위원회를 설치할 경우, 해당 위원회에는… | AA15: 감사위, 사추위, 보상위, ESG위 등 전문성 있는 산하 위원회를 설치했습니까? | AB15: 단계(1~5)
A16: 61 | B16: G-2-4 | C16: 기본진단항목(v2.0) | D16: 지배구조 | E16: 이사회 활동 | F16: 이사회 안건 처리 | G16:  이사회 구성원이 상정된 안건에 대해 독립적/전문적/다양한 시각으로 수정 및 보완 의견을 제시하고 있거나, 특히 조직에 리스크가 될 수 있는 안건에 대해서는 적극적인 반대 의견을 제시하는지 확인  이사회 심의/의결 안건 중 원안대로 가결되지 않은 안건이나 원안에 반대한 이사, 그리고 가결되지 않거나 안건에 반대한 사유를 점검 | H16: 이사회 구성 현황, 이사회 회의록 등 | I16: 지난 1개 회계연도 기준 | J16: N/A | K16: 수정, 보완 및 반대 의견이 나타난 안건 수 / 전체 이사회 상정 안건 수 | L16: 단계형 | M16: 3 | N16: 단계형: 1단계=0점 / 2단계=50점 / 3단계=100점 | O16: 1단계 | 안건에 대한 수정, 보완, 반대하는 의견이 한 건도 없는 경우 | 2단계 | 안건에 대한 수정, 보완, 반대하는 의견이 한 건 이상 존재하는 경우 | 3단계 | 안건에 대한 수정, 보완, 반대하는 의견이 5% 이상 존재하는 경우 | P16: GAP(대응지표 없음) | Q16: KSSB 별도 규정 없음 | R16: 지배구조보고서 가이드라인 | S16: 1_2_0_업종별 K-ESG 가이드라인(v2.0) 진단항목 | Y16:  본 항목은 ‘이사회 구성원이 자유로운 의견을 개진하고 있는지’를 확인하기 위해 설계한 항목으로써, 전체 이사회 안건 처리 중 수정/부결 비율을 측정하는 방법 外 1) 이사회 의사진행에 관한 경과와 결과를 기재하고 있는 의사록 上 논의사항을 확인하는 방법, 2) 이사회 구성원의 안건 검토를 위한 개별 자료제공 요청사항을 확인하는 방법 등으로 ‘이사회 구성원의 자유로운 의견 개진 현황’을 확인할 수 있다.  이사회가 합리적인 의사결정과 경영감독을 수행하기 위해서는 각 이사들이 충분하고 올바른 정보를 가지고 있어야 한다. 이러한 정보는 경영진들 및 실무진의 보고, 개인적인 조사, 실적조사 등 다양한 방식으로 수집될 수 있으며, 이사회 구성원들은 이러한 자료를 사전에… | AA16: 안건 사전 검토를 위해 개최 최소 3~7일 전 배포 기간을 엄수합니까? | AB16: 단계(1~5)
A17: 62 | B17: G-3-1 | C17: 기본진단항목(v2.0) | D17: 지배구조 | E17: 주주권리 | F17: 주주총회 소집 공고 | G17:  주주가 주주총회 참석 전 충분하고 합리적인 판단을 내릴 수 있도록, 주주에게 주주총회 개최 일자, 장소, 안건, 기타 재무사항 등의 정보를 담은 주주총회 소집 공고를 다양한 채널로 전달하는지 확인  조직이 주주총회 소집을 공고하는 방법을 점검 | H17: 주주총회 소집 통지서 外 다음의 방식에 따른 공고 1) 조직의 사업장 게시판, 2) 조직의 온라인 홈페이지, 3) 명의개서대행사, 4) 일간지(신문), 5) 전자공시시스템, 6) 기타 | I17: 직전 회계연도 | J17: N/A | K17: N/A | L17: 단계형 | M17: 5 | N17: 단계형: 1단계=0점 / 2단계=25점 / 3단계=50점 / 4단계=75점 / 5단계=100점 | O17: 1단계 | 주주총회 소집 공고를 서면으로만 통지하거나, 주주의 동의를 받아 전자문서로만 하는 경우 | 2단계 | 서면 또는 전자문서로 통지하는 방식 外 1개의 추가 방식을 이용하는 경우 | 3단계 | 서면 또는 전자문서로 통지하는 방식 外 2개의 추가 방식을 이용하는 경우 | 4단계 | 서면 또는 전자문서로 통지하는 방식 外 3개의 추가 방식을 이용하는 경우 | 5단계 | 서면 또는 전자문서로 통지하는 방식 外 4개 이상의 추가 방식을 이용하는 경우 | P17: GAP(대응지표 없음) | Q17: KSSB 주주총회 절차 별도 규정 없음 | R17: 지배구조보고서 가이드라인 | S17: 1_2_0_업종별 K-ESG 가이드라인(v2.0) 진단항목 | Y17:  기업은 주주총회의 개최 일시, 장소 및 의안에 관한 정보를 사전에 주주에게 제공해야 한다. 주주에게 제공되는 정보는 주주가 의안을 사전에 검토하여 객관적이고 합리적인 판단을 내릴 수 있도록 충분해야 하며, 주주총회의 개최 일시와 장소는 최대한 많은 주주가 참여할 수 있도록 충분한 기간 전에 서면 또는 주주의 동의하에 전자문서로 통지하여야 한다.  ｢상법｣ 제363조에서는 주주총회 소집 통지와 관련하여 아래의 사항들을 명시하고 있다. 1) 주주총회를 소집할 때에는 주주총회일의 2주 전에 각 주주에게 서면으로 통지를 발송하거나 각 주주의 동의를 받아 전자문서로 통지를 발송하여야 한다. 다만, 그 통지가 주주명부상 주주의 주소에 계속 3년간 도달하지 아니한 경우에는… | AA17: 주총 소집 공고를 법정기일보다 빠른 3주/4주 전에 이행합니까? | AB17: 단계(1~5)
A18: 63 | B18: G-3-2 | C18: 기본진단항목(v2.0) | D18: 지배구조 | E18: 주주권리 | F18: 주주총회 집중일 이외 개최 | G18:  주주가 주주총회의 안건을 검토하고 분석하기 위한 충분한 시간과 여건이 확보될 수 있도록 주주총회가 개최되고 있는지 확인  조직이 주주총회 개최일을 지정하는데 있어, 주주를 포함한 주주총회 관련 내/외부 이해관계자의 의견수렴 과정을 진행하고 있는지를 점검 | H18: 주주총회 개최일, 주주총회 개최 계획 | I18: 직전 회계연도 | J18: N/A | K18: N/A | L18: 선택형 | M18: 5 | N18: 선택형: 요건1=0점 / 요건2=25점 / 요건3=50점 / 요건4=75점 / 요건5=100점 | O18: 요건1 | 주주총회 개최일을 지정하는데 있어, 재무결산 및 감사보고서 발행일을 고려함 | 요건2 | 주주총회 개최일을 지정하는데 있어, 조직의 연간 업무계획 및 경영진 등의 업무일정을 고려함 | 요건3 | 주주총회 개최일을 지정하는데 있어, 연기금, 기관투자자, 의결권자문사 등의 주요 시장 참여자 의견을 수렴함 | 요건4 | 주주총회 개최일을 지정하는데 있어, 소액주주 및 기타 이해관계자 등의 의견을 수렴함 | 요건5 | 주주총회 개최일을 지정하는데 있어, 주주총회 예상 집중일을 고려함 | P18: GAP(대응지표 없음) | Q18: KSSB 별도 규정 없음 | R18: 지배구조보고서 가이드라인 | S18: 1_2_0_업종별 K-ESG 가이드라인(v2.0) 진단항목 | Y18:  기업은 주주총회의 개최 일시, 장소 및 의안에 관한 정보를 사전에 주주에게 제공해야 한다. 주주에게 제공되는 정보는 주주가 의안을 사전에 검토하여 객관적이고 합리적인 판단을 내릴 수 있도록 충분해야 하며, 주주총회의 개최 일시와 장소는 최대한 많은 주주가 참여할 수 있도록 충분한 기간 전에 서면 또는 주주의 동의하에 전자문서로 통지하여야 한다.  ｢상법｣ 제363조에서는 주주총회를 소집하기 위해 아래의 사항을 통지할 것을 명시하고 있다. 1) 주주총회를 소집할 때에는 주주총회일의 2주 전에 각 주주에게 서면으로 통지를 발송하거나 각 주주의 동의를 받아 전자문서로 통지를 발송하여야 한다. 다만, 그 통지가 주주명부상 주주의 주소에 3년간 지속적으로 도달하지 아니한… | AA18: 지배구조 보고서 내 '주주총회 집중일 이외 개최' 지표를 준수하고 있습니까? | AB18: 단계(1~5)
A19: 64 | B19: G-3-3 | C19: 기본진단항목(v2.0) | D19: 지배구조 | E19: 주주권리 | F19: 집중/전자/서면 투표제 | G19:  조직의 모든 주주가 의결권을 용이하게 행사할 수 있으며, 소수주주에게 이해관계를 대변할 수 있는 이사 선임 기회를 제공하고 있는지 확인  국내 ｢상법｣ 上 조직의 자율적 의사결정에 따라 선택할 수 있는 소수주주 보호장치인 ‘서면투표제’, ‘전자투표제’, ‘집중투표제’ 도입 여부를 점검 | H19: 조직의 정관, 이사회 결의사항 | I19: 직전 회계연도 | J19: N/A | K19: N/A | L19: 복합가중형 | N19: 복합가중형: 2~3개 세부요소를 균등가중평균(예: 1/2+1/2, 1/3×3) — 세부 배점은 점검기준 상세 참조, 자사취득점수는 수동 산정 | O19: 집중투표제 도입 서면투표제 도입 전자투표제 도입 | (1/5) (2/5) (2/5) | 1단계 정관에서 집중투표제를 배제 정관에서 서면투표제를 배제 정관에서 전자투표제를 배제하고 | 하고 있다. 하고 있다. 있다. | 2단계 정관에서 집중투표제를 명시 정관에서 서면투표제를 명시 정관에서 전자투표제를 명시하거나, | 하고 있다. 하고 있다. 이사회 결의로 도입하고 있다. | P19: GAP(대응지표 없음) | Q19: KSSB 별도 규정 없음 | R19: 지배구조보고서 가이드라인 | S19: 1_2_0_업종별 K-ESG 가이드라인(v2.0) 진단항목 | T19: 해당없음(복합가중형) | Y19:  조직은 주주가 보유하고 있는 기본적인 권리 행사, 재산 보호, 이해관계 대변 등을 용이하게 할 수 있도록 직접적 또는 간접적인 방법을 의결권을 행사할 수 있는 기회를 보장해야 한다. 주주의 의결권 행사 용이성을 높일 수 있는 장치로는 ‘서면투표제’와 ‘전자투표제’가 있다. 주주가 직접 출석하지 않더라도 의결권을 행사할 수 있는 장치를 마련한다면, 조직의 중요한 의사결정에 주주의 의사를 결집하여 반영할 수 있고, 조직에 대한 견제/감독도 수월해지게 된다. 또한, 조직은 주주총회에 소요되는 경비를 절감할 수 있으며, 더 나아가 조직이 필요로 하는 안건에 대해 의결권을 확보하는 데에 도움이 될 수 있다. - 국제기업지배구조네트워크인 ICGN이 2014년 발표한 ｢적극적… | AA19: 집중/전자/서면 투표제에 대한 현황을 관리·공시하고 있습니까? | AB19: 단계(1~5)
A20: 65 | B20: G-3-4 | C20: 기본진단항목(v2.0) | D20: 지배구조 | E20: 주주권리 | F20: 배당정책 및 이행 | G20:  조직이 주주가치 증진 및 투자의사결정에 필요한 배당 관련 정보를 적시에 충분하게 안내하고, 적절하게 배당을 실시했는지 확인  주주에게 배당정책 및 배당계획을 충실히 통지함과 동시에, 배당정책 및 배당계획에 따라 실제 배당을 진행하였는지 점검 | H20: 배정정책, 현금현물배당결정 | I20: 직전 회계연도 | J20: N/A | K20: N/A | L20: 단계형 | M20: 3 | N20: 단계형: 1단계=0점 / 2단계=50점 / 3단계=100점 | O20: 1단계 | 주주에게 배당정책 및 배당계획을 통지하지 아니한 경우 | 2단계 | 주주에게 배당정책 및 배당계획을 연 1회 이상 통지한 경우 | 3단계 | 주주에게 배당정책 및 배당계획을 연 1회 인상 통지하였으며, 배당정책 및 배당계획대로 배당을 집행한 경우 | P20: GAP(대응지표 없음) | Q20: KSSB 별도 규정 없음 | R20: 지배구조보고서 가이드라인, 한국거래소 지침 | S20: 1_2_0_업종별 K-ESG 가이드라인(v2.0) 진단항목 | Y20:  배당정책이란 조직의 향후 배당목표에 대해 주주에게 제공하는 설명으로서, 배당수준의 유지, 확대, 축소에 관한 방향성, 배당목표 결정 시 사용된 재무지표와 이를 산출한 방법, 기타 자사주 매입 및 소각 계획 등을 포함해야 한다. 또한, 조직의 당해연도 배당계획에는 아래의 정보들이 포함되어야 한다. - 배당규모 : 주당배당금, 배당수익률 - 배당성향 : 배당수준 유지, 확대, 축소 - 배당형태 : 현금배당, 주식배당, 기타 현물배당 - 배당시기 : 분기배당, 중간배당, 결산배당  조직의 단순한 배당성향 및 배당수익률 증가는 주주가치 증진과 직접 연계되어 있지 않다. 해당 항목은 주주가치 증진을 위해 배당성향 및 배당수익률 증가를 요구하는 것이 아니라, 주주가… | AA20: 중장기 배당 정책 수립/공시 및 선 배당액 확정 밸류업 정책을 이행합니까? | AB20: 단계(1~5)
A21: 66 | B21: G-4-1 | C21: 기본진단항목(v2.0) | D21: 지배구조 | E21: 윤리경영 | F21: 윤리규범 위반사항 공시 | G21:  조직이 구성원의 윤리규범 위반 행위(부당한 이익이나 뇌물의 수수, 불공정 경쟁 및 거래, 제품/서비스 책임 소홀, 구성원 상호 간 모독 및 비하, 기타 사회적 책임 등)를 관리·감독함과 동시에, 구성원의 윤리규범 위반행위가 재발하지 않도록 내부개선이 이루어지고 있는지 확인  이해관계자와의 신뢰성 및 투명성 관점을 고려하여, 조직이 윤리규범 위반 행위와 개선활동을 대외공시하고 있는지 점검 | H21: 윤리규범 위반 내역 및 조치경과 | I21: 직전 회계연도 | J21: N/A | K21: N/A | L21: 선택형 | M21: 5 | N21: 선택형: 요건1=0점 / 요건2=25점 / 요건3=50점 / 요건4=75점 / 요건5=100점 | O21: 요건1 | 윤리규범 위반 건수를 공시하고 있는 경우 | 요건2 | 윤리규범 위반한 구성원 수를 공시하고 있는 경우 | 요건3 | 윤리규범 위반 건과 관련한 처벌내역(사법상, 행정상)을 공시하고 있는 경우 | 요건4 | 윤리규범 위반 건과 관련된 구성원 처분내역(인사상)을 공시하고 있는 경우 | 요건5 | 윤리규범 위반 사건 재발방지를 위한 개선활동 및 계획을 공시하고 있는 경우 | * 선택 항목의 합산값으로 평가 | P21: 부분대응 | Q21: KSSB 제1호 위험관리 원칙 준용 | R21: GRI 205, 2-26 | S21: 1_2_0_업종별 K-ESG 가이드라인(v2.0) 진단항목 | Y21:  윤리규범이란 윤리경영을 실천하기 위한 올바른 의사결정과 윤리적 판단 기준을 구성원에게 제공하는 것으로서, 조직에 속한 구성원 및 해당 조직과 거래관계에 있는 자들이 업무수행 과정에서 준수해야 하는 행동방식이 담겨 있는 문서를 지칭한다. 조직마다 윤리규범을 일컫는 용어는 다양하며, 윤리헌장, 윤리강령, 행동강령, 행동규범, 청렴규범 등의 용어가 존재한다.  윤리규범 위반이란 조직이 제정한 윤리규범에서 다루는 행동방식을 위반한 행위를 하는 경우 및 이에 준하는 사회통념적 윤리기준을 위반한 행위를 통칭한다. 이러한 윤리규범 위반 행위에 포함되는 사례는 다음과 같다. 이해관계 상충 행위 금품 및 향응 수수 직무권한 및 지위 남용 공정거래 미준수 행위 부정경쟁 행위… | AA21: 최근 4개년 간 횡령, 배임, 뇌물 등 부패 위반 제재 내역이 있습니까? | AB21: 단계(1~5)
A22: 67 | B22: G-5-1 | C22: 기본진단항목(v2.0) | D22: 지배구조 | E22: 감사기구 | F22: 내부감사부서 설치 | G22:  조직의 재무, 회계, 감사 관련 부정사안, 기타 내부통제 관련 현안 등을 상시적으로 점검하고, 중요한 의사결정사항 및 관련 정보를 감사위원회에 보고하는 거버넌스 체계가 구축되어 있는지 확인  조직이 내부감사부서를 두고 있는지, 내부감사부서의 책임과 역할을 명확히 규정하고 있는지 점검 | H22: 내부감사부서 등 조직도 및 업무분장 | I22: 직전 회계연도 | J22: N/A | K22: N/A | L22: 단계형 | M22: 5 | N22: 단계형: 1단계=0점 / 2단계=25점 / 3단계=50점 / 4단계=75점 / 5단계=100점 | O22: 1단계 | 내부감사부서를 두고 있지 않거나, 감사 관련 업무를 수행하는 부서 또는 업무분장을 두고 있지 않은 경우 | 2단계 | 내부감사부서를 두고 있지 않으나, 감사 관련 업무를 수행하는 기타 부서 및 업무분장이 있는 경우 | 3단계 | 내부감사부서를 두고 있으나, 내부감사부서의 업무분장 등에 감사위원회 업무지원과 관련한 내용을 명시하지 않은 경우 | 4단계 | 내부감사부서를 두고 있으며, 내부감사부서의 업무분장 등에 감사위원회 업무지원과 관련한 내용을 명시한 경우 | 5단계 | 감사위원회 지원 역할만을 수행하는 별도 전담부서 또는 업무분장이 규정되어 있는 경우 | P22: 부분대응 | Q22: KSSB 제1호 문단 27(1) 내부통제 취지 준용 | R22: 외감법, KCGS | S22: 1_2_0_업종별 K-ESG 가이드라인(v2.0) 진단항목 | Y22:  감사위원회의 회계감사 및 내부통제 업무를 보조하거나, 지원할 수 있는 내부감사부서 설치가 필요하다. 감사위원회는 조직의 회계, 재무, 감사에 관한 감독 등 내부통제제도에 관한 사항을 심의하는 역할에 집중하고 있어, 일상적인 감사 관련 업무를 수행하는데 한계가 있기 때문이다. 특히, 감사위원회가 전원 사외이사로만 구성되어 있을 경우, 조직의 회계, 재무, 감사에 관한 정보 접근성에 제약이 발생하기 때문에, 이를 보완할 수 있는 조직으로서 내부감사부서 설치는 필요하다.  국내 ｢상법｣에서는 상장회사 등에 내부감사부서 설치를 강제하는 규정이 없으나, ｢금융회사의 지배구조에 관한 법률｣ 제20조 및 ｢공공기관 운영에 관한 법률｣ 제32조에는 ‘감사위원회 또는 감사’의… | AA22: 감사위 직속 독립 내부감사 부서 및 인사권이 보장되어 있습니까? | AB22: 단계(1~5)
A23: 68 | B23: G-5-2 | C23: 기본진단항목(v2.0) | D23: 지배구조 | E23: 감사기구 | F23: 감사기구 전문성 (감사기구 내 회계/재무 전문가) | G23:  조직의 감사위원회(또는 감사)가 거시경제 흐름 및 업종동향에 대한 직관, 상법 등 관련 법률 소양, 회계/재무/감사에 관한 전문적 지식을 보유하고 있는지 확인  국내 법률상 규정되어 있는 감사위원회 전문성 조건을 상회하여, 회계 및 재무 전문가를 감사위원으로 선임하고 있는지 점검 | H23: 감사위원회(또는 감사) 구성 | I23: 직전 회계연도 | J23: N/A | K23: N/A | L23: 단계형 | M23: 3 | N23: 단계형: 1단계=0점 / 2단계=50점 / 3단계=100점 | O23: 1단계 | 감사위원회 내 회계 및 재무 분야 전문성을 보유한 감사위원이 1명 선임되어 있는 경우 | 2단계 | 감사위원회 내 회계 및 재무 전문가가 1명 이상 선임되어 있으나, 전체 감사위원 중 50% 이하인 경우 | 3단계 | 감사위원회 내 회계 및 재무 전문가가 1명 이상 선임되어 있으며, 전체 감사위원 중 50% 초과한 경우 | P23: 부분대응 | Q23: KSSB 제1호 문단 27(1)ㄏ 전문성 취지 준용 | R23: KCGS | S23: 1_2_0_업종별 K-ESG 가이드라인(v2.0) 진단항목 | Y23:  감사위원회의 기본적 업무는 회계감사이며, 감사위원회가 효과적으로 기능하기 위해서는 감사위원이 조직과 이해관계 상충이 없다는 ‘독립성’ 요건을 충족하는 것 이외에 회계, 재무, 감사 분야의 ‘전문성’이 확보되어야 한다. 특히, 감사위원회의 핵심 역할은 재무제표 작성 및 회계감사를 감독하는 업무이므로, 회계 및 감사 업무의 전문성은 꼭 필요하다.  국내 상장회사 및 금융회사의 감사위원회 내 회계 및 재무 분야 전문성을 보유한 감사위원을 선임해야 한다는 규정은 ｢상법｣ 제542조의11 및 ｢금융회사의 지배구조에 관한 법률｣ 제19조에 명시되어 있다. - ｢상법｣ 제542조의11 : 자산규모 2조 원 이상 상장회사 및 자산규모 1천억 원 이상 상장회사 중 감사위원회를… | AA23: 감사위원회 내 재무/회계 전문가(공인회계사 등)를 확보하고 있습니까? | AB23: 단계(1~5)
A24: 69 | B24: G-6-1 | C24: 기본진단항목(v2.0) | D24: 지배구조 | E24: 지배구조 법/규제 위반 | F24: 지배구조 법/규제 위반 | G24:  조직이 주주권리 보호, 이사회 및 경영진 등 최고 거버넌스 운영, 상호출자 등 소유구조, 특수관계인 거래 등과 관련한 법/규제를 명확하게 인식하고, 지배구조 리스크 해결을 위한 제도 및 활동을 도입하고 있는지 확인  지배구조 관련 법/규제 위반 건 중 조직의 재무구조 및 명성 관리에 상당한 영향력을 미치는 사법상 형벌, 행정상 처분(금전적, 비금전적)에 대해 가중치를 달리 적용해 점검 | H24: ‘전자공시시스템’ 上 사업보고서, ‘조직별 홈페이지’ 上 지속가능경영보고서 | I24: 최근 4개 회계연도 | J24: N/A | K24: ∑(지배구조 법/규제 위반 건 * 처벌수위별 감점 기준) | L24: 감점형 | M24: 3 | N24: 감점형: 기준 100점에서 위반유형별(-50/-30/-10점) 차감(중복 적용 가능), 최저 0점 | O24: 유형 1 | 지난 4개년 간 지배구조 법/규제 위반내역 중 처분이 확정된 건수에 대해, 처벌수위가 사법상 형벌, 벌금, 과료인 경우, 또는 지배 | 구조 법/규제 위반으로 인해 국가나 지방자치단체를 당사자로 하는 계약에서 입찰참가자격을 제한당한 경우 | 유형 2 | 지난 4개년 간 지배구조 법/규제 위반내역 중 처분이 확정된 건수에 대해, 지배구조 법/규제 위반의 처벌수위가 행정상 처분 중 | 금전적 처분에 해당하는 과태료, 과징금, 이행강제금 등인 경우 | 유형 3 | 지난 4개년 간 지배구조 법/규제 위반내역 중 처분이 확정된 건수에 대해, 지배구조 법/규제 위반의 처벌수위가 행정상 처분 중 | 비금전적 처분에 해당하는 시정명령, 시정권고, 경고 등인 경우 | * 감점 사항이 없을 경우, 본 항목의 점수는 100점으로 산정. 최저점은 0점으로 제한 | P24: 부분대응 | Q24: KSSB 제1호 위험관리 원칙 준용 | R24: GRI 2-27 | S24: 1_2_0_업종별 K-ESG 가이드라인(v2.0) 진단항목 | T24: 해당없음(감점형) | U24: 0 | V24: 0 | W24: 0 | X24: 100 | Y24:  지배구조 법/규제 위반은 ｢상법｣, ｢자본시장과 금융투자업에 관한 법률｣, ｢금융회사의 지배구조에 관한 법률｣ 및 이에 준하는 기타 법률 등에서 규정한 ‘주주권리 보호’, ‘상호출자 등 소유구조’, ‘계열회사 등 특수관계인과의 거래’, ‘이사회 구성 및 운영’, ‘감사기구 구성 및 운영’, ‘경영정보 공시’ 요건을 위반한 경우로 볼 수 있으며, 이에 대한 예시는 아래와 같다. - 주주권리 보호 : 집중투표제, 전자투표제, 주주제안, 주주대표소송 등 - 상호출자 등 소유구조 : 5% 이상 지분율 공시, 상호출자제한기업집단 간 주식 취득 및 소유 등 - 특수관계인과의 거래 : 계열회사 출자총액/지급보증/담보제공 등 - 이사회 구성 및 운영 : 사외이사 선임, 여성(남성)… | AA24: 최근 3개년 간 지배구조 법/규제 위반 관련 사례가 있었습니까? (있다면 유형·건수 기재) | AB24: 단계(1~5)
A25: 84 | B25: G-경영진-추가1 | C25: 추가진단항목(v2.0) | D25: 지배구조 | E25: 경영진 | F25: 경영진 성과평가 및 보상 | G25:  경영진의 성과를 체계적으로 평가하고 이를 근거로 보상을 지급함으로써, 경영진의 의사결정행위를 직/간접적으로 감독 및 통제하고 있는지 확인  경영진의 성과평가 지표(KPIs)는 조직의 장기적 가치 향상과 연계되어 있으며, 성과평가 행위가 구체적, 연속적, 실효적으로 이루어지고 있는지 점검 | H25: ‘전자공시시스템’ 上 사업보고서, ‘조직별 홈페이지’ 上 지속가능경영보고서 | I25: 최근 1개 회계연도 | J25: N/A | K25: N/A | L25: 선택형 | M25: 5 | N25: 선택형: 요건1=0점 / 요건2=25점 / 요건3=50점 / 요건4=75점 / 요건5=100점 | O25: 요건1 | 조직의 재무적 성과와 연계하여 정량적 ‘성과평가 지표’가 설정되어 있는 경우 | (매출액, 영업이익, 현금흐름, EBIT, 시가총액, 주주수익률 등) | 요건2 | 조직의 비재무적 성과와 연계하여 정량적 ‘성과평가 지표’가 설정되어 있는 경우 | (온실가스 배출량, 친환경 제품 비율, 산업재해율, 인권 리스크 개선율 등) | 요건3 | 조직의 재무적/비재무적 성과와 연계하여 3년 이상의 중장기 ‘성과평가 지표’가 설정되어 있는 경우 | 요건4 | 성과평가 결과에 따라 보상(성과급)을 지급하고 있으며, 성과보상 지급을 1년 이상 초과하여 이연지급하고 있는 경우 | 요건5 | 성과평가 종료 후, 지급(예정) 보상을 회수할 수 있는 요건을 두고 있는 경우 | (경영진 행위가 불법적이거나, 조직에 심각한 피해를 초래한 사유 등) | P25: 부분대응 | Q25: KSSB 제2호 문단 29(7) 경영진 보상-기후지표 연계 취지 준용(ESG 전반 KPI 연계는 KSSB가 더 포괄적) | R25: GRI 2-19, KCGS | S25: K-ESG 가이드라인 v2.0 (추가 진단항목, 3장) | Y25: 요건1 조직의 재무적 성과와 연계하여 정량적 ‘성과평가 지표’가 설정되어 있는 경우 (매출액, 영업이익, 현금흐름, EBIT, 시가총액, 주주수익률 등) 요건2 조직의 비재무적 성과와 연계하여 정량적 ‘성과평가 지표’가 설정되어 있는 경우 (온실가스 배출량, 친환경 제품 비율, 산업재해율, 인권 리스크 개선율 등) 요건3 조직의 재무적/비재무적 성과와 연계하여 3년 이상의 중장기 ‘성과평가 지표’가 설정되어 있는 경우 요건4 성과평가 결과에 따라 보상(성과급)을 지급하고 있으며, 성과보상 지급을 1년 이상 초과하여… | AA25: 경영진 성과평가 및 보상을 수립하여 운영하고 있습니까? | AB25: 선택형(요건 충족 수)
A26: 85 | B26: G-윤리경영-추가1 | C26: 추가진단항목(v2.0) | D26: 지배구조 | E26: 윤리경영 | F26: 윤리경영/반부패 관련 법규/행동강령 등 준수 | G26:  조직이 윤리경영 및 부패방지 관련 법규, 행동강령 및 실천규범 등을 준수하고 있는지 확인 | H26: 회사(계열사 제외), 임직원(계열사 제외)의 법규 위반 사항 중 사회 관련 법규 위반 사실 (사업보고서, 지속가능성보고서, 법규위반 정보 관련 웹사이트) | I26: 최근 회계연도 기준 | J26: 국내, 해외 지점 포함 | K26: N/A | L26: 감점형 | M26: 4 | N26: 감점형: 유형1=-50점 / 유형2=-30점 / 유형3=-10점 (기준 100점에서 위반유형별 차감, 최저 0점, 중복 합산 가능) | O26: 유형1(1단계): 처벌 및 조치내용 중 「과징금·벌금·징역·금고·구류」가 포함된 처벌이 있는 경우 | 유형2(2단계): 처벌 및 조치내용 중 「과태료·범칙금·이행강제금」이 포함된 처벌이 있는 경우 | 유형3(3단계): 상기 조치 이외의 처벌(금전적 처벌 없이 시정명령·영업정지 등 제재만 있는 경우) | 처벌·조치내역이 없는 경우 감점 없음(=100점), 사회 분야 총 평가 최저점은 0점으로 하한 설정. 전년도 회사(계열사 제외)·임직원(계열사 제외)의 윤리경영/반부패 관련 법규·행동강령 위반 사실을 기준으로 평가하며, 항소 중인 건은 전년도 현재 판결 기준으로 평가(금융지주회사는 계열사 및 자회사 포함) | P26: 부분대응 | Q26: KSSB 제1호 위험관리 원칙 준용 | R26: GRI 205 | S26: K-ESG 가이드라인 v2.0 (추가 진단항목, 3장) | T26: 해당없음(감점형) | U26: 0 | V26: 0 | W26: 0 | X26: 100 | Y26: 윤리경영/반부패 관련 법규 및 행동강령 위반 이력이 없도록 사전 예방 체계(내부신고 채널, 정기 준법교육, 반부패 정책)를 구축·운영하고, 처벌·조치내역 발생 시에도 재발방지 개선활동을 공시해 위반 유형별 감점을 최소화해야 함. 동일 위반유형이 반복되지 않도록 내부통제 프로세스를 개선하는 것이 핵심 개선 방향. | AA26: 윤리경영/반부패 관련 법규/행동강령 등 준수를 수립하여 운영하고 있습니까? | AB26: OX(위반유형별 감점)
A27: 86 | B27: 반도체-E-1 | C27: 업종특화(반도체 v1.0) | D27: 환경 | E27: 온실가스 및 에너지 | F27: 에너지 효율적 제품 | G27: 조직이 개발·생산하는 제품 중 에너지 효율적 제품의 비중을 점검하고, 사용단계 에너지 절감 노력을 확인 | H27: '조직별 홈페이지' 上 지속가능경영보고서 | I27: 최근 4개 회계연도 | J27: 국내외 사업장 및 기타 연결실체 | K27: (에너지 효율적 제품의 수 / 조직이 생산하고 있는 전체 제품의 수) X 100 | L27: 단계형 | M27: 3 | N27: 단계형: 1단계=0점 / 2단계=50점 / 3단계=100점 | O27: 1단계: 지난 4개년간 에너지 효율적 제품의 비중 감소 추세 | 2단계: 지난 4개년간 에너지 효율적 제품의 비중 변동 없음 | 3단계: 지난 4개년간 에너지 효율적 제품의 비중 증가 추세 | P27: GAP(대응지표 없음) | Q27: KSSB 업종기반지표(반도체 S2 부속지침)로 별도 개발 예정 | R27: SASB Semiconductors | S27: 2_업종별 K-ESG 가이드라인(반도체) 진단항목 | Y27: Energy Star, EU Energy Label, 국내 에너지소비효율등급표시제도 등 공인 인증 또는 자체평가로 입증 가능한 에너지 효율 제품 비중을 측정. 설비(장비) 생산기업은 판매 장비의 에너지효율 비중으로 대체 측정 가능. | AA27: 사용 단계 전력 소모를 절감한 에너지 효율 반도체/장비 비중이 증가 추세입니까? | AB27: 단계(1~3)/감점형
A28: 87 | B28: 반도체-E-2 | C28: 업종특화(반도체 v1.0) | D28: 환경 | E28: 용수 | F28: 초순수 사용량 | G28: 반도체 생산에 필요한 초순수(Ultra-pure Water) 사용량을 효과적으로 측정·모니터링·관리하고 있는지 점검 | H28: '조직별 홈페이지' 上 지속가능경영보고서 | I28: 최근 4개 회계연도 | J28: 국내외 사업장 및 기타 연결실체 | K28: 원단위 초순수 사용량 = 전체 초순수 사용량 / 원단위 활용 분모(매출액·생산량 등) | L28: 단계형 | M28: 3 | N28: 단계형: 1단계=0점 / 2단계=50점 / 3단계=100점 | O28: 1단계: 지난 4개년간 원단위 초순수 사용량 증가 추세 | 2단계: 지난 4개년간 원단위 초순수 사용량 변동 없음 | 3단계: 지난 4개년간 원단위 초순수 사용량 감소 추세 (미산정 시 0점) | P28: GAP(대응지표 없음) | Q28: KSSB 업종기반지표로 별도 개발 예정 | R28: GRI 303, SASB Semiconductors | S28: 2_업종별 K-ESG 가이드라인(반도체) 진단항목 | Y28: 초순수는 반도체 웨이퍼·마스크 세정에 필수적인 자원으로, 물부족·기후변화에 따른 공급비용 증가 리스크 관리 지표. 연평균성장률(CAGR)로 4개년 추세 판정. | AA28: 웨이퍼 세정에 필수적인 초순수(UPW) 원단위 사용량이 감소 추세입니까? | AB28: 단계(1~3)/감점형
A29: 88 | B29: 반도체-E-3 | C29: 업종특화(반도체 v1.0) | D29: 환경 | E29: 용수 | F29: 물 부족 지역에서의 용수 사용량 | G29: 조직의 사업장 중 물부족지역(Water-stressed areas)에 노출된 사업장의 원단위 용수 사용량을 점검 | H29: '조직별 홈페이지' 上 지속가능경영보고서 | I29: 최근 4개 회계연도 | J29: 국내외 사업장 및 기타 연결실체 | K29: 물부족지역 사업장 원단위 용수사용량 = 물부족지역 사업장 용수사용량 / 원단위 활용 분모 | L29: 단계형 | M29: 3 | N29: 단계형: 1단계=0점 / 2단계=50점 / 3단계=100점 | O29: 1단계: 지난 4개년간 물부족지역 사업장 원단위 용수사용량 증가 추세 | 2단계: 변동 없음 | 3단계: 감소 추세 (미식별·미측정 시 0점) | P29: GAP(대응지표 없음) | Q29: KSSB 업종기반지표로 별도 개발 예정 | R29: CDP Water Security, SASB Semiconductors | S29: 2_업종별 K-ESG 가이드라인(반도체) 진단항목 | Y29: 물부족지역 식별은 세계자원연구소(WRI Aqueduct), 세계자연기금(WWF Water Risk Filter) 등에서 확인 가능. | AA29: 수자원 취수 원단위 총 용수 사용량이 감소 추세입니까? | AB29: 단계(1~3)/감점형
A30: 89 | B30: 반도체-E-4 | C30: 업종특화(반도체 v1.0) | D30: 환경 | E30: 오염물질 | F30: 과불화탄소 배출량 | G30: 반도체 식각·챔버세정 공정에서 발생하는 과불화탄소(PFCs, GWP 7,000) 배출을 관리하는지 확인 | H30: '조직별 홈페이지' 上 지속가능경영보고서, TCFD 보고서, CDP 보고서 등 | I30: 최근 4개 회계연도 | J30: 국내외 사업장 및 기타 연결실체 | K30: 원단위 대비 PFC 배출량 = 총 PFC 배출량(tCO2eq) / 원단위 활용 분모 | L30: 단계형 | M30: 3 | N30: 단계형: 1단계=0점 / 2단계=50점 / 3단계=100점 | O30: 1단계: 지난 4개년간 원단위 PFC 배출량 증가 추세 | 2단계: 변동 없음 | 3단계: 감소 추세 (미관리 시 0점) | P30: GAP(대응지표 없음) | Q30: KSSB 업종기반지표로 별도 개발 예정(GHG Scope1 총량에는 포함) | R30: SASB Semiconductors | S30: 2_업종별 K-ESG 가이드라인(반도체) 진단항목 | Y30: EU 불화온실가스 저감 규정(Regulation (EU) No 517/2014), 교토의정서 7대 온실가스에 해당. | AA30: 과불화탄소 배출량에 대한 현황을 관리·공시하고 있습니까? | AB30: 단계(1~3)/감점형
A31: 90 | B31: 반도체-E-5 | C31: 업종특화(반도체 v1.0) | D31: 환경 | E31: 오염물질 | F31: 휘발성 유기화합물 배출량 | G31: 제품 생산과정에서 발생하는 휘발성유기화합물(VOC) 배출을 관리하는지 확인 | H31: '조직별 홈페이지' 上 지속가능경영보고서, TCFD·CDP 보고서 등 | I31: 최근 4개 회계연도 | J31: 국내외 사업장 및 기타 연결실체 | K31: 원단위 대비 VOC 배출량 = 총 VOC 배출량(Metric ton) / 원단위 활용 분모 | L31: 단계형 | M31: 3 | N31: 단계형: 1단계=0점 / 2단계=50점 / 3단계=100점 | O31: 1단계: 지난 4개년간 원단위 VOC 배출량 증가 추세 | 2단계: 변동 없음 | 3단계: 감소 추세 (미관리 시 0점) | P31: GAP(대응지표 없음) | Q31: KSSB 업종기반지표로 별도 개발 예정 | R31: SASB Semiconductors | S31: 2_업종별 K-ESG 가이드라인(반도체) 진단항목 | Y31: 국내 대기환경보전법 휘발성유기화합물 지정고시(37개 물질), 미국 EPA 40 CFR Part 51.100, RBA 행동규범 배출관리 요구사항 참고. | AA31: 휘발성 유기화합물 배출량에 대한 현황을 관리·공시하고 있습니까? | AB31: 단계(1~3)/감점형
A32: 91 | B32: 반도체-G-1 | C32: 업종특화(반도체 v1.0) | D32: 지배구조 | E32: 윤리경영 | F32: 반경쟁행위 위반사항 공시 | G32: 조직이 반경쟁행위(가격담합·시장지배력남용 등) 관련 법/규제를 준수하는지, 위반시 처벌수위별 감점으로 점검 | H32: '전자공시시스템' 上 사업보고서, '조직별 홈페이지' 上 지속가능경영보고서 | I32: 최근 4개 회계연도 | J32: 국내외 사업장 및 기타 연결실체 | K32: ∑(반경쟁행위 위반 건 × 처벌수위별 감점기준) | L32: 감점형 | M32: 3 | N32: 감점형: 유형1=-50점 / 유형2=-30점 / 유형3=-10점 (감점형: 100점 기준 위반유형별 차감, 최저 0점) | O32: 유형1: 확정판결 中 사법상 형벌·벌금·과료 또는 입찰참가자격 제한 | 유형2: 확정판결 中 금전적 행정처분(과태료·과징금·이행강제금) | 유형3: 확정판결 中 비금전적 행정처분(시정명령·시정권고·경고) — 감점 없을 시 100점, 최저점 0점 하한 | P32: GAP(대응지표 없음) | Q32: KSSB 규정 없음 | R32: SASB Semiconductors, 공정거래법 | S32: 2_업종별 K-ESG 가이드라인(반도체) 진단항목 | T32: 해당없음(감점형) | U32: 0 | V32: 0 | W32: 0 | X32: 100 | Y32: 반도체 산업표준 제정 과정의 상호라이선스·특허풀 활용 등으로 가격담합 등 반독점 리스크가 상대적으로 높은 업종 특성 반영. | AA32: 반경쟁행위 위반사항 공시를 충실히 이행하고 있습니까? | AB32: 단계(1~3)/감점형

Sheet 02_점수산정참고표
A1: [분리본: G(지배구조)+P(정보공시)+반도체특화] 원본 02시트를 분류코드 기준으로 재분류한 파일입니다.
A2: 분류코드 | B2: 진단항목명 | C2: 단계번호 | D2: 단계라벨 | E2: 배점 | F2: 단계별 판단기준(K-ESG v2.0 원문)
A3: P-1-1 | B3: ESG 정보공시 방식 | C3: 1 | D3: 1단계 | E3: 0 | F3: 조직이 어떠한 방식으로든 ESG 정보를 공시하지 않는 경우
A4: P-1-1 | B4: ESG 정보공시 방식 | C4: 2 | D4: 2단계 | E4: 25 | F4: 조직의 홈페이지, 지속가능경영보고서, 사업보고서, 기타 간행물 등에 ESG 정보를 분산하여 공시하고 있는 경우
A5: P-1-1 | B5: ESG 정보공시 방식 | C5: 3 | D5: 3단계 | E5: 50 | F5: 조직의 홈페이지, 지속가능경영보고서, 사업보고서, 기타 간행물 등에 ESG 정보를 통합하여 공시하고 있는 경우
A6: P-1-1 | B6: ESG 정보공시 방식 | C6: 4 | D6: 4단계 | E6: 75 | F6: ESG 정보를 통합한 조직의 홈페이지, 지속가능경영보고서, 사업보고서, 기타 간행물 등을 지정된 장소에 비치하거나, 특정 URL에 담고 있는 경우
A7: P-1-1 | B7: ESG 정보공시 방식 | C7: 5 | D7: 5단계 | E7: 100 | F7: ESG 정보를 통합한 조직의 홈페이지, 지속가능경영보고서, 사업보고서, 기타 간행물 등의 발행여부를 ‘전자공시시스템-자율공시’ 사항으로 알리는 경우
A8: P-1-2 | B8: ESG 정보공시 주기 | C8: 1 | D8: 1단계 | E8: 0 | F8: ESG 정보공시 주기를 특정할 수 없거나, 명시하고 있지 않는 경우
A9: P-1-2 | B9: ESG 정보공시 주기 | C9: 2 | D9: 2단계 | E9: 50 | F9: 2년 단위로 보고서 발간 및 ESG 정보를 공시하는 경우
A10: P-1-2 | B10: ESG 정보공시 주기 | C10: 3 | D10: 3단계 | E10: 100 | F10: 1년 단위로 보고서 발간 및 ESG 정보를 공시하는 경우
A11: P-1-3 | B11: ESG 정보공시 범위 | C11: 1 | D11: 1단계 | E11: 0 | F11: ESG 정보공시 범위를 특정할 수 없거나, 명시하고 있지 않는 경우
A12: P-1-3 | B12: ESG 정보공시 범위 | C12: 2 | D12: 2단계 | E12: 25 | F12: 조직이 법적으로 직접 소유하고 있는 사업장(ex. 별도재무제표 기준)의 일부 또는 모든 ESG 정보를 공시하고 있는 경우
A13: P-1-3 | B13: ESG 정보공시 범위 | C13: 3 | D13: 3단계 | E13: 50 | F13: 조직의 영향력과 통제력 범위에 있는 곳(자회사, 종속법인, 연결실체 등)의 일부 ESG 정보를 공시하고 있는 경우
A14: P-1-3 | B14: ESG 정보공시 범위 | C14: 4 | D14: 4단계 | E14: 75 | F14: 조직의 영향력과 통제력 범위에 있는 곳(자회사, 종속법인, 연결실체 등)의 일부 ESG 정보를 공시하고 있는 경우. 단, 조직의 영향력과 통제력 범위로 ESG 정보공시 범위를 확대한다는 계획을 제시하고 있는 경우
... A107: 반도체-E-5 | B107: 휘발성 유기화합물 배출량 | C107: 3 | D107: 3단계 | E107: 100 | F107: 감소 추세 (미관리 시 0점)

Sheet 03_지배구조세부점검(KRX)
A1: [분리본] 03시트는 지배구조(G) 항목만 있어 G 파일에만 포함됩니다.
A2: 순번 | B2: 핵심원칙(대분류) | C2: 세부원칙 | D2: 지표코드 | E2: 지표명 | F2: 데이터유형 | G2: 크롤링소스(정량 수집처) | H2: 연계 K-ESG 분류코드 | I2: 비고/근거 | J2: [입력]자사 현황값
A3: 1 | B3: 지배구조 핵심지표(15개) | C3: - | D3: H01 | E3: 주주총회 4주 전 소집공고 실시 | F3: OX | G3: 기업지배구조보고서 | H3: G-3-1 | I3: 준수율 산정 15개 항목 중 하나
A4: 2 | B4: 지배구조 핵심지표(15개) | C4: - | D4: H02 | E4: 전자투표 실시 | F4: OX | G4: 기업지배구조보고서 | H4: G-3-3
A5: 3 | B5: 지배구조 핵심지표(15개) | C5: - | D5: H03 | E5: 주주총회 집중일 이외 개최 | F5: OX | G5: 기업지배구조보고서 | H5: G-3-2
A6: 4 | B6: 지배구조 핵심지표(15개) | C6: - | D6: H04 | E6: 현금배당 관련 예측가능성 제공 | F6: OX | G6: 기업지배구조보고서 | H6: G-3-4 | I6: 배당액 확정일이 배당기준일보다 선행
A7: 5 | B7: 지배구조 핵심지표(15개) | C7: - | D7: H05 | E7: 배당정책·배당실시계획 연1회 이상 주주 통지 | F7: OX | G7: 기업지배구조보고서 | H7: G-3-4
A8: 6 | B8: 지배구조 핵심지표(15개) | C8: - | D8: H06 | E8: 최고경영자 승계정책 마련 및 운영 | F8: OX | G8: 기업지배구조보고서 | H8: G-경영진-추가1
A9: 7 | B9: 지배구조 핵심지표(15개) | C9: - | D9: H07 | E9: 위험관리 등 내부통제정책 마련 및 운영 | F9: OX | G9: 기업지배구조보고서 | H9: G-4-1 | I9: 리스크관리·준법경영·내부회계관리·공시정보관리 모두 충족해야 준수
A10: 8 | B10: 지배구조 핵심지표(15개) | C10: - | D10: H08 | E10: 사외이사가 이사회 의장인지 여부 | F10: OX | G10: 기업지배구조보고서 | H10: G-1-3
A11: 9 | B11: 지배구조 핵심지표(15개) | C11: - | D11: H09 | E11: 집중투표제 채택 | F11: OX | G11: 기업지배구조보고서 | H11: G-3-3 | I11: 정관상 배제하지 않는 경우 해당
A12: 10 | B12: 지배구조 핵심지표(15개) | C12: - | D12: H10 | E12: 기업가치 훼손·주주권익 침해 책임자 임원선임 방지 정책 수립 | F12: OX | G12: 기업지배구조보고서 | H12: G-4-1
A13: 11 | B13: 지배구조 핵심지표(15개) | C13: - | D13: H11 | E13: 이사회 구성원 모두 단일 성별이 아님 | F13: OX | G13: 기업지배구조보고서 | H13: G-1-4 | I13: 성별 다양성
A14: 12 | B14: 지배구조 핵심지표(15개) | C14: - | D14: H12 | E14: 독립적인 내부감사부서(지원조직) 설치 | F14: OX | G14: 기업지배구조보고서 | H14: G-5-1
A15: 13 | B15: 지배구조 핵심지표(15개) | C15: - | D15: H13 | E15: 내부감사기구에 회계·재무 전문가 존재 | F15: OX | G15: 기업지배구조보고서 | H15: G-5-2
A16: 14 | B16: 지배구조 핵심지표(15개) | C16: - | D16: H14 | E16: 내부감사기구-외부감사인 분기 1회 이상 경영진 없이 회의 | F16: OX | G16: 기업지배구조보고서 | H16: G-5-1
A17: 15 | B17: 지배구조 핵심지표(15개) | C17: - | D17: H15 | E17: 경영 중요정보에 내부감사기구 접근 가능한 절차 마련 | F17: OX | G17: 기업지배구조보고서 | H17: G-5-1
A18: 16 | B18: 핵심원칙1_주주의권리 | C18: 1-①_주주총회정보제공 | D18: 101 | E18: 소집공고일~주주총회일 간격(일) | F18: 숫자 | G18: 기업지배구조보고서 | H18: G-3-1, G-3-3 | I18: 4주 초과 여부 판단 근거
A19: 17 | B19: 핵심원칙1_주주의권리 | C19: 1-①_주주총회정보제공 | D19: 102 | E19: 외국인 주주 이해가능 소집통지 실시여부 | F19: OX | G19: 기업지배구조보고서 | H19: G-3-1, G-3-3
A20: 18 | B20: 핵심원칙1_주주의권리 | C20: 1-②_의결권행사 | D20: 103 | E20: 정기주총 집중일 회피 여부 | F20: OX | G20: 기업지배구조보고서 | H20: G-3-1, G-3-3 | I20: 최근 3개년
A21: 19 | B21: 핵심원칙1_주주의권리 | C21: 1-②_의결권행사 | D21: 104 | E21: 서면투표 실시여부 | F21: OX | G21: 기업지배구조보고서 | H21: G-3-1, G-3-3
A22: 20 | B22: 핵심원칙1_주주의권리 | C22: 1-②_의결권행사 | D22: 105 | E22: 전자투표 실시여부 | F22: OX | G22: 기업지배구조보고서 | H22: G-3-1, G-3-3
A23: 21 | B23: 핵심원칙1_주주의권리 | C23: 1-②_의결권행사 | D23: 106 | E23: 의결권 대리행사 권유 여부 | F23: OX | G23: 기업지배구조보고서 | H23: G-3-1, G-3-3
A24: 22 | B24: 핵심원칙1_주주의권리 | C24: 1-②_의결권행사 | D24: 107 | E24: 안건별 찬성/반대(기권) 비율(%) | F24: 숫자 | G24: 기업지배구조보고서 | H24: G-3-1, G-3-3
A25: 23 | B25: 핵심원칙1_주주의권리 | C25: 1-③_주주제안권 | D25: 108 | E25: 주주제안 절차 홈페이지 등 안내 시행여부 | F25: OX | G25: 기업지배구조보고서 | H25: G-3(주주권리 보강)
A26: 24 | B26: 핵심원칙1_주주의권리 | C26: 1-③_주주제안권 | D26: 109 | E26: 주주제안 처리절차·기준 규정 시행여부 | F26: OX | G26: 기업지배구조보고서 | H26: G-3(주주권리 보강)
A27: 25 | B27: 핵심원칙1_주주의권리 | C27: 1-③_주주제안권 | D27: 110 | E27: 공시대상기간 내 주주제안 건수 및 이행상황 | F27: 숫자/텍스트 | G27: 기업지배구조보고서 | H27: G-3(주주권리 보강)
A28: 26 | B28: 핵심원칙1_주주의권리 | C28: 1-③_주주제안권 | D28: 111 | E28: 공개서한 접수 여부 및 처리현황 | F28: OX/텍스트 | G28: 기업지배구조보고서 | H28: G-3(주주권리 보강)
A29: 27 | B29: 핵심원칙1_주주의권리 | C29: 1-④_주주환원정책 | D29: 112 | E29: 주주환원정책(배당 포함) 수립여부 | F29: OX | G29: 기업지배구조보고서 | H29: G-3-4
A30: 28 | B30: 핵심원칙1_주주의권리 | C30: 1-④_주주환원정책 | D30: 113 | E30: 주주환원정책 연1회 통지 여부 | F30: OX | G30: 기업지배구조보고서 | H30: G-3-4
A31: 29 | B31: 핵심원칙1_주주의권리 | C31: 1-④_주주환원정책 | D31: 114 | E31: 주주환원정책 영문자료 제공 여부 | F31: OX | G31: 기업지배구조보고서 | H31: G-3-4
A32: 30 | B32: 핵심원칙1_주주의권리 | C32: 1-④_주주환원정책 | D32: 115 | E32: 현금배당 관련 예측가능성 제공(배당기준일 이전 배당결정) | F32: OX | G32: 기업지배구조보고서 | H32: G-3-4 | I32: 표 1-4-1
A33: 31 | B33: 핵심원칙1_주주의권리 | C33: 1-④_주주환원정책 | D33: 116 | E33: 상장회사협의회 표준정관 개정 반영 여부 | F33: OX | G33: 기업지배구조보고서 | H33: G-3-4
A34: 32 | B34: 핵심원칙1_주주의권리 | C34: 1-⑤_배당등주주권리 | D34: 117 | E34: 최근 3개년 주당 배당금 | F34: 숫자 | G34: 기업지배구조보고서/지속가능경영보고서 | H34: G-3-4 | I34: 표 1-5-1-1
A35: 33 | B35: 핵심원칙1_주주의권리 | C35: 1-⑤_배당등주주권리 | D35: 118 | E35: 최근 3개년 시가배당률(%) | F35: 숫자 | G35: 기업지배구조보고서/지속가능경영보고서 | H35: G-3-4
A36: 34 | B36: 핵심원칙1_주주의권리 | C36: 1-⑤_배당등주주권리 | D36: 119 | E36: 최근 3개년 현금배당성향(연결/개별, %) | F36: 숫자 | G36: 기업지배구조보고서/지속가능경영보고서 | H36: G-3-4 | I36: 표 1-5-1-2
A37: 35 | B37: 핵심원칙1_주주의권리 | C37: 1-⑤_배당등주주권리 | D37: 120 | E37: 차등배당·분기배당·중간배당 실시여부 | F37: OX | G37: 기업지배구조보고서 | H37: G-3-4
A38: 36 | B38: 핵심원칙1_주주의권리 | C38: 1-⑤_배당등주주권리 | D38: 121 | E38: 자사주 매입·소각 등 배당외 주주환원 실시내역 | F38: 텍스트 | G38: 기업지배구조보고서/지속가능경영보고서 | H38: G-3-4
A39: 37 | B39: 핵심원칙2_주주의공평한대우 | C39: 2-①_의결권및정보제공 | D39: 201 | E39: 발행가능주식총수 대비 발행주식수(%) | F39: 숫자 | G39: 기업지배구조보고서 | H39: G-3(주주권리 보강)
A40: 38 | B40: 핵심원칙2_주주의공평한대우 | C40: 2-①_의결권및정보제공 | D40: 202 | E40: 종류주식별 의결권 부여 내용 | F40: 텍스트 | G40: 기업지배구조보고서 | H40: G-3(주주권리 보강)
...

Sheet 04_KSSB갭분석
B2: KSSB 대비 GAP 분석 (분리본: G(지배구조)+P(정보공시)+반도체특화)
B3: KSSB(한국지속가능성기준위원회) 지속가능성 공시기준서 제1호(일반요구사항)·제2호(기후) 대비 K-ESG 가이드라인 v2.0의 대응 현황
B4: ※ 「ESG_핵심지표_채점기준표_전체」 01시트를 G(지배구조)+P(정보공시)+반도체특화 기준으로 재분류한 파일입니다. 아래 표는 01시트 입력값에 실시간 연동되는 수식입니다 (반도체특화문항은 영역과 무관하게 G 파일에 포함).
B6: 영역 | C6: 완전대응 | D6: 부분대응 | E6: GAP(대응지표 없음) | F6: 항목수 합계 | G6: 완전대응율
B7: 정보공시(P) | C7: =COUNTIFS('01_ESG통합진단마스터'!$D$3:$D$32,"정보공시",'01_ESG통합진단마스터'!$P$3:$P$32,"완전대응") | D7: =COUNTIFS('01_ESG통합진단마스터'!$D$3:$D$32,"정보공시",'01_ESG통합진단마스터'!$P$3:$P$32,"부분대응") | E7: =COUNTIFS('01_ESG통합진단마스터'!$D$3:$D$32,"정보공시",'01_ESG통합진단마스터'!$P$3:$P$32,"GAP(대응지표 없음)") | F7: =C7+D7+E7 | G7: =IFERROR(C7/F7,0)
B8: 지배구조(G) | C8: =COUNTIFS('01_ESG통합진단마스터'!$D$3:$D$32,"지배구조",'01_ESG통합진단마스터'!$C$3:$C$32,"<>업종특화(반도체 v1.0)",'01_ESG통합진단마스터'!$P$3:$P$32,"완전대응") | D8: =COUNTIFS('01_ESG통합진단마스터'!$D$3:$D$32,"지배구조",'01_ESG통합진단마스터'!$C$3:$C$32,"<>업종특화(반도체 v1.0)",'01_ESG통합진단마스터'!$P$3:$P$32,"부분대응") | E8: =COUNTIFS('01_ESG통합진단마스터'!$D$3:$D$32,"지배구조",'01_ESG통합진단마스터'!$C$3:$C$32,"<>업종특화(반도체 v1.0)",'01_ESG통합진단마스터'!$P$3:$P$32,"GAP(대응지표 없음)") | F8: =C8+D8+E8 | G8: =IFERROR(C8/F8,0)
B9: 업종특화(반도체) | C9: =COUNTIFS('01_ESG통합진단마스터'!$C$3:$C$32,"업종특화(반도체 v1.0)",'01_ESG통합진단마스터'!$P$3:$P$32,"완전대응") | D9: =COUNTIFS('01_ESG통합진단마스터'!$C$3:$C$32,"업종특화(반도체 v1.0)",'01_ESG통합진단마스터'!$P$3:$P$32,"부분대응") | E9: =COUNTIFS('01_ESG통합진단마스터'!$C$3:$C$32,"업종특화(반도체 v1.0)",'01_ESG통합진단마스터'!$P$3:$P$32,"GAP(대응지표 없음)") | F9: =C9+D9+E9 | G9: =IFERROR(C9/F9,0)
B10: 전체(G(지배구조)+P(정보공시)+반도체특화) | C10: =SUM(C7:C9) | D10: =SUM(D7:D9) | E10: =SUM(E7:E9) | F10: =SUM(F7:F9) | G10: =IFERROR(C10/F10,0)

Sheet 05_요약대시보드
B2: ESG 통합진단 요약 대시보드 (분리본: G(지배구조)+P(정보공시)+반도체특화)
B3: 01_ESG통합진단마스터 시트의 입력값에 실시간 연동되는 수식입니다 (해당 시트에 점수를 입력하면 아래 표가 자동 갱신됩니다)
B5: 1. 진단 완료 현황
B6: 전체 진단항목 수 | C6: =COUNTA('01_ESG통합진단마스터'!$B$3:$B$32)
B7: 점수 입력 완료 항목 수 | C7: =COUNT('01_ESG통합진단마스터'!$X$3:$X$32)
B8: 입력 완료율 | C8: =IFERROR(C7/C6,0)
B10: 2. 영역별 평균 점수 (G(지배구조)+P(정보공시)+반도체특화 기준, 동일가중 단순평균 — 각 항목 100점 기준)
B11: 영역 | C11: 항목 수 | D11: 점수입력 완료수 | E11: 평균점수(100점 환산) | F11: 완전대응(KSSB) | G11: GAP(KSSB)
B12: 정보공시(P) | C12: =COUNTIFS('01_ESG통합진단마스터'!$D$3:$D$32,"정보공시") | D12: =SUMPRODUCT(('01_ESG통합진단마스터'!$D$3:$D$32="정보공시")*ISNUMBER('01_ESG통합진단마스터'!$X$3:$X$32)) | E12: =IFERROR(AVERAGEIFS('01_ESG통합진단마스터'!$X$3:$X$32,'01_ESG통합진단마스터'!$D$3:$D$32,"정보공시"),"미입력") | F12: =COUNTIFS('01_ESG통합진단마스터'!$D$3:$D$32,"정보공시",'01_ESG통합진단마스터'!$P$3:$P$32,"완전대응") | G12: =COUNTIFS('01_ESG통합진단마스터'!$D$3:$D$32,"정보공시",'01_ESG통합진단마스터'!$P$3:$P$32,"GAP(대응지표 없음)")
B13: 지배구조(G) | C13: =COUNTIFS('01_ESG통합진단마스터'!$D$3:$D$32,"지배구조",'01_ESG통합진단마스터'!$C$3:$C$32,"<>업종특화(반도체 v1.0)") | D13: =SUMPRODUCT(('01_ESG통합진단마스터'!$D$3:$D$32="지배구조")*('01_ESG통합진단마스터'!$C$3:$C$32<>"업종특화(반도체 v1.0)")*ISNUMBER('01_ESG통합진단마스터'!$X$3:$X$32)) | E13: =IFERROR(AVERAGEIFS('01_ESG통합진단마스터'!$X$3:$X$32,'01_ESG통합진단마스터'!$D$3:$D$32,"지배구조",'01_ESG통합진단마스터'!$C$3:$C$32,"<>업종특화(반도체 v1.0)"),"미입력") | F13: =COUNTIFS('01_ESG통합진단마스터'!$D$3:$D$32,"지배구조",'01_ESG통합진단마스터'!$C$3:$C$32,"<>업종특화(반도체 v1.0)",'01_ESG통합진단마스터'!$P$3:$P$32,"완전대응") | G13: =COUNTIFS('01_ESG통합진단마스터'!$D$3:$D$32,"지배구조",'01_ESG통합진단마스터'!$C$3:$C$32,"<>업종특화(반도체 v1.0)",'01_ESG통합진단마스터'!$P$3:$P$32,"GAP(대응지표 없음)")
B14: 업종특화(반도체) | C14: =COUNTIFS('01_ESG통합진단마스터'!$C$3:$C$32,"업종특화(반도체 v1.0)") | D14: =SUMPRODUCT(('01_ESG통합진단마스터'!$C$3:$C$32="업종특화(반도체 v1.0)")*ISNUMBER('01_ESG통합진단마스터'!$X$3:$X$32)) | E14: =IFERROR(AVERAGEIFS('01_ESG통합진단마스터'!$X$3:$X$32,'01_ESG통합진단마스터'!$C$3:$C$32,"업종특화(반도체 v1.0)"),"미입력") | F14: =COUNTIFS('01_ESG통합진단마스터'!$C$3:$C$32,"업종특화(반도체 v1.0)",'01_ESG통합진단마스터'!$P$3:$P$32,"완전대응") | G14: =COUNTIFS('01_ESG통합진단마스터'!$C$3:$C$32,"업종특화(반도체 v1.0)",'01_ESG통합진단마스터'!$P$3:$P$32,"GAP(대응지표 없음)")
B15: 전체(종합) | C15: =SUM(C12:C14) | D15: =SUM(D12:D14) | E15: =IFERROR(AVERAGE('01_ESG통합진단마스터'!$X$3:$X$32),"미입력") | F15: =SUM(F12:F14) | G15: =SUM(G12:G14)
B18: 3. 적용구분별 항목 수 (기본/추가/업종특화)
B19: 적용구분 | C19: 항목 수 | D19: 점수입력 완료수 | E19: 평균점수
B20: 기본진단항목(v2.0) | C20: =COUNTIF('01_ESG통합진단마스터'!$C$3:$C$32,"기본진단항목(v2.0)") | D20: =SUMPRODUCT(('01_ESG통합진단마스터'!$C$3:$C$32="기본진단항목(v2.0)")*ISNUMBER('01_ESG통합진단마스터'!$X$3:$X$32)) | E20: =IFERROR(AVERAGEIFS('01_ESG통합진단마스터'!$X$3:$X$32,'01_ESG통합진단마스터'!$C$3:$C$32,"기본진단항목(v2.0)"),"미입력")
B21: 추가진단항목(v2.0) | C21: =COUNTIF('01_ESG통합진단마스터'!$C$3:$C$32,"추가진단항목(v2.0)") | D21: =SUMPRODUCT(('01_ESG통합진단마스터'!$C$3:$C$32="추가진단항목(v2.0)")*ISNUMBER('01_ESG통합진단마스터'!$X$3:$X$32)) | E21: =IFERROR(AVERAGEIFS('01_ESG통합진단마스터'!$X$3:$X$32,'01_ESG통합진단마스터'!$C$3:$C$32,"추가진단항목(v2.0)"),"미입력")
B22: 업종특화(반도체 v1.0) | C22: =COUNTIF('01_ESG통합진단마스터'!$C$3:$C$32,"업종특화(반도체 v1.0)") | D22: =SUMPRODUCT(('01_ESG통합진단마스터'!$C$3:$C$32="업종특화(반도체 v1.0)")*ISNUMBER('01_ESG통합진단마스터'!$X$3:$X$32)) | E22: =IFERROR(AVERAGEIFS('01_ESG통합진단마스터'!$X$3:$X$32,'01_ESG통합진단마스터'!$C$3:$C$32,"업종특화(반도체 v1.0)"),"미입력")
B25: 4. 참고
B26: 평균점수는 각 영역 내 모든 항목에 동일 가중치(1/N)를 부여한 단순평균이며, 점수 미입력 항목은 제외하고 계산합니다.
B27: 본 파일은 「ESG_핵심지표_채점기준표_전체」에서 G(지배구조)+P(정보공시)+반도체특화 기준으로 분리된 작업본입니다. 03_지배구조세부점검(KRX) 시트는 G 파일에만 포함됩니다.
